Workbook

Sheet Sales Summary
B1: Sales | Weekly Summary | E1: 0.98675 | F1: 0.23330847 | G1: 9.0898469 | H1: 2.37953 | I1: 0.042992657 | J1: 23.38 | K1: 38.96 | L1: 38.985363 | M1: 38.750271 | N1: 0.39989733 | O1: 2945 | P1: 0 | Q1: 1 | R1: 687 | S1: 0 | T1: #DIV/0! | U1: 16062.06 | V1: 26765.97 | W1: 0 | X1: #DIV/0! | Y1: 7594 | Z1: 0 | AA1: #DIV/0! | AB1: 294294.53 | AC1: 0 | AD1: #DIV/0! | AE1: 0.32241687 | AF1: 420 | AG1: 23289 | AH1: -39 | AI1: -0.061355792 | AJ1: -0.72458238 | AK1: -269 | AL1: -0.034161135 | AM1: -634.92 | AN1: 7133.44 | AO1: 149627.77 | AQ1: 15688 | AR1: 78 | AS1: 102 | AT1: 1201 | AU1: 40 | AV1: 1167
B2: Prime Item Nbr | C2: Prime Item Desc | D2: Vendor Stk Nbr | E2: Curr Repl Instock % | F2: LW U/S/W | G2: LW $/S/W | H2: YTD $/P/W | I2: Wkly Sell Thru % | J2: Unit Cost | K2: Unit Retail | L2: Avg Retail | M2: YTD AUR | N2: MU % | O2: Curr Traited Store/Item Comb | P2: Traited Store LY | Q2: LW Store Count Chg % | R2: LW POS Qty | S2: LY LW POS Qty | T2: LW Sales Qty Chng | U2: LW POS Cost | V2: LW POS Sales | W2: LY LW POS Sales | X2: LW Sales Chng | Y2: YTD POS Qty | Z2: LY YTD POS Qty | AA2: YTD Sales Qty Chng | AB2: YTD POS Sales | AC2: LY YTD POS Sales | AD2: YTD Sales Chng | AE2: YTD Sell Thru % | AF2: LW Gross Ship Qty | AG2: YTD Gross Ship Qty | AH2: LW Total Customer Item Return | AI2: LW Total Return Rate | AJ2: YTD Def Rate (sales) | AK2: YTD Total Customer Item Return | AL2: YTD Total Return Rate | AM2: LW SI Total MUMD $ | AN2: YTD SI Total MUMD $ | AO2: 52/53 WK FC Units | AP2: Frcst WOS | AQ2: Curr Str On Hand Qty | AR2: Curr Str In Transit Qty | AS2: Curr Str In Whse Qty | AT2: Curr Str On Order Qty | AU2: Curr Whse On Hand Qty | AV2: Curr Whse SS Order Qty | AW2: UPC | AX2: Effective Date
B3: 677410826 | C3: AQUASONIC WFLS PREC | D3: =VLOOKUP($B3,'Luminate Item Data'!A:C,3,FALSE) -> AS-PREC-FLOS-BK | E3: =VLOOKUP($B3,'Luminate Item Data'!$A:$AS,45,FALSE) -> 0.9884 | F3: =IFERROR(($R3/$O3),"-") -> 0.3267663 | G3: =IFERROR(($V3/$O3),"-") -> 12.718933 | H3: =IFERROR(($AB3/$O3)/42,"-") -> 3.0827818 | I3: =IFERROR($R3/($AQ3+$R3),0) -> 0.062120625 | J3: =_xlfn.IFNA(VLOOKUP(B3,'Luminate Item Data'!A:G,7,0),0) -> 23.38 | K3: =VLOOKUP($B3,'Luminate Item Data'!A:H,8,FALSE) -> 38.96 | L3: =IFERROR(Table4[[#This Row],[ LW POS Sales]]/Table4[[#This Row],[ LW POS Qty]],"-") -> 38.923638 | M3: =IFERROR(Table4[[#This Row],[ YTD POS Sales]]/Table4[[#This Row],[ YTD POS Qty]],"0") -> 38.76142 | N3: =(K3-J3)/K3 -> 0.39989733 | O3: =VLOOKUP($B3,'Luminate Item Data'!A:AR,44,FALSE) -> 1472 | P3: =_xlfn.IFNA(VLOOKUP(Table4[[#This Row],[Prime Item Nbr]],'Luminate Item Data'!A:AX,50,0),0) -> 0 | Q3: =IFERROR((Table4[[#This Row],[ Curr Traited Store/Item Comb]]-Table4[[#This Row],[Traited Store LY]])/Table4[[#This Row],[Traited Store LY]],1) -> 1 | R3: =_xlfn.IFNA(VLOOKUP($B3,'Luminate Sales Data'!A:C,3,FALSE),0) -> 481 | S3: =_xlfn.IFNA(VLOOKUP($B3,'Luminate Sales Data'!A:D,4,FALSE),0) -> 0 | T3: =IFERROR(($R3-$S3)/$S3,"-") -> - | U3: =$R3*$J3 -> 11245.78 | V3: =_xlfn.IFNA(VLOOKUP($B3,'Luminate Sales Data'!A:E,5,FALSE),0) -> 18722.27 | W3: =_xlfn.IFNA(VLOOKUP($B3,'Luminate Sales Data'!A:F,6,FALSE),0) -> 0 | X3: =IFERROR(($V3-$W3)/$W3,"-") -> - | Y3: =_xlfn.IFNA(VLOOKUP($B3,'Luminate Sales Data'!A:U,21,FALSE),0) -> 4917 | Z3: =_xlfn.IFNA(VLOOKUP($B3,'Luminate Sales Data'!A:V,22,FALSE),0) -> 0 | AA3: =IFERROR(($Y3-$Z3)/$Z3,"-") -> - | AB3: =_xlfn.IFNA(VLOOKUP($B3,'Luminate Sales Data'!A:W,23,FALSE),0) -> 190589.9 | AC3: =_xlfn.IFNA(VLOOKUP($B3,'Luminate Sales Data'!A:X,24,FALSE),0) -> 0 | AD3: =IFERROR(($AB3-$AC3)/$AC3,"-") -> - | AE3: =IFERROR($Y3/($Y3+$AQ3),0) -> 0.40372773 | AF3: =_xlfn.IFNA(VLOOKUP($B3,'Luminate Sales Data'!A:K,11,FALSE),0) -> 411 | AG3: =_xlfn.IFNA(VLOOKUP($B3,'Luminate Sales Data'!A:AC,29,FALSE),0) -> 12342 | AH3: =_xlfn.IFNA(VLOOKUP($B3,'Luminate Sales Data'!A:Q,17,FALSE),0) -> -24 | AI3: =IFERROR(($AH3/$R3),"-") -> -0.04989605 | AJ3: =IFERROR(VLOOKUP($B3,'Luminate Sales Data'!$A:$AG,31,0)/Table4[[#This Row],[ YTD POS Qty]],0) -> -0.83791336 | AK3: =_xlfn.IFNA(VLOOKUP($B3,'Luminate Sales Data'!A:AI,35,FALSE),0) -> -189 | AL3: =IFERROR($AK3/$Y3,0) -> -0.038438072 | AM3: =_xlfn.IFNA(VLOOKUP($B3,'Luminate Markdown'!A:C,3,FALSE),0) -> -177.84 | AN3: =_xlfn.IFNA(VLOOKUP($B3,'Luminate Markdown'!A:E,5,FALSE),0) -> 5195.1 | AO3: =_xlfn.IFNA(VLOOKUP($B3,'Luminate Forecast'!N:P,3,FALSE),0) -> 74787.17 | AP3: =IFERROR(($AQ3/$R3),"-") -> 15.097713 | AQ3: =VLOOKUP($B3,'Luminate Item Data'!A:AT,46,FALSE) -> 7262 | AR3: =VLOOKUP($B3,'Luminate Item Data'!A:AU,47,FALSE) -> 74 | AS3: =VLOOKUP($B3,'Luminate Item Data'!A:AV,48,FALSE) -> 96 | AT3: =VLOOKUP($B3,'Luminate Item Data'!A:AW,49,FALSE) -> 950 | AU3: =IFERROR(VLOOKUP($B3,'Luminate Warehouse Inv'!B:E,4,FALSE),0) -> 40 | AV3: =IFERROR(VLOOKUP($B3,'Luminate Warehouse Inv'!B:G,6,FALSE),0) -> 921 | AW3: =VLOOKUP($B3,'Luminate Item Data'!$A:$D,4,FALSE) -> 85007565805 | AX3: =VLOOKUP($B3,'Luminate Item Data'!$A:$E,5,FALSE) -> 45796
B4: 677536463 | C4: AS TOOTHBRUSH | D4: =VLOOKUP($B4,'Luminate Item Data'!A:C,3,FALSE) -> AS-PREC-TB-BK | E4: =VLOOKUP($B4,'Luminate Item Data'!$A:$AS,45,FALSE) -> 0.9851 | F4: =IFERROR(($R4/$O4),"-") -> 0.13985064 | G4: =IFERROR(($V4/$O4),"-") -> 5.4607604 | H4: =IFERROR(($AB4/$O4)/42,"-") -> 1.6762782 | I4: =IFERROR($R4/($AQ4+$R4),0) -> 0.02386469 | J4: =_xlfn.IFNA(VLOOKUP(B4,'Luminate Item Data'!A:G,7,0),0) -> 23.38 | K4: =VLOOKUP($B4,'Luminate Item Data'!A:H,8,FALSE) -> 38.96 | L4: =IFERROR(Table4[[#This Row],[ LW POS Sales]]/Table4[[#This Row],[ LW POS Qty]],"-") -> 39.047087 | M4: =IFERROR(Table4[[#This Row],[ YTD POS Sales]]/Table4[[#This Row],[ YTD POS Qty]],"0") -> 38.739122 | N4: =(K4-J4)/K4 -> 0.39989733 | O4: =VLOOKUP($B4,'Luminate Item Data'!A:AR,44,FALSE) -> 1473 | P4: =_xlfn.IFNA(VLOOKUP(Table4[[#This Row],[Prime Item Nbr]],'Luminate Item Data'!A:AX,50,0),0) -> 0 | Q4: =IFERROR((Table4[[#This Row],[ Curr Traited Store/Item Comb]]-Table4[[#This Row],[Traited Store LY]])/Table4[[#This Row],[Traited Store LY]],1) -> 1 | R4: =_xlfn.IFNA(VLOOKUP($B4,'Luminate Sales Data'!A:C,3,FALSE),0) -> 206 | S4: =_xlfn.IFNA(VLOOKUP($B4,'Luminate Sales Data'!A:D,4,FALSE),0) -> 0 | T4: =IFERROR(($R4-$S4)/$S4,"-") -> - | U4: =$R4*$J4 -> 4816.28 | V4: =_xlfn.IFNA(VLOOKUP($B4,'Luminate Sales Data'!A:E,5,FALSE),0) -> 8043.7 | W4: =_xlfn.IFNA(VLOOKUP($B4,'Luminate Sales Data'!A:F,6,FALSE),0) -> 0 | X4: =IFERROR(($V4-$W4)/$W4,"-") -> - | Y4: =_xlfn.IFNA(VLOOKUP($B4,'Luminate Sales Data'!A:U,21,FALSE),0) -> 2677 | Z4: =_xlfn.IFNA(VLOOKUP($B4,'Luminate Sales Data'!A:V,22,FALSE),0) -> 0 | AA4: =IFERROR(($Y4-$Z4)/$Z4,"-") -> - | AB4: =_xlfn.IFNA(VLOOKUP($B4,'Luminate Sales Data'!A:W,23,FALSE),0) -> 103704.63 | AC4: =_xlfn.IFNA(VLOOKUP($B4,'Luminate Sales Data'!A:X,24,FALSE),0) -> 0 | AD4: =IFERROR(($AB4-$AC4)/$AC4,"-") -> - | AE4: =IFERROR($Y4/($Y4+$AQ4),0) -> 0.24110601 | AF4: =_xlfn.IFNA(VLOOKUP($B4,'Luminate Sales Data'!A:K,11,FALSE),0) -> 9 | AG4: =_xlfn.IFNA(VLOOKUP($B4,'Luminate Sales Data'!A:AC,29,FALSE),0) -> 10947 | AH4: =_xlfn.IFNA(VLOOKUP($B4,'Luminate Sales Data'!A:Q,17,FALSE),0) -> -15 | AI4: =IFERROR(($AH4/$R4),"-") -> -0.072815534 | AJ4: =IFERROR(VLOOKUP($B4,'Luminate Sales Data'!$A:$AG,31,0)/Table4[[#This Row],[ YTD POS Qty]],0) -> -0.6112514 | AK4: =_xlfn.IFNA(VLOOKUP($B4,'Luminate Sales Data'!A:AI,35,FALSE),0) -> -80 | AL4: =IFERROR($AK4/$Y4,0) -> -0.029884199 | AM4: =_xlfn.IFNA(VLOOKUP($B4,'Luminate Markdown'!A:C,3,FALSE),0) -> -457.08 | AN4: =_xlfn.IFNA(VLOOKUP($B4,'Luminate Markdown'!A:E,5,FALSE),0) -> 1938.34 | AO4: =_xlfn.IFNA(VLOOKUP($B4,'Luminate Forecast'!N:P,3,FALSE),0) -> 74840.6 | AP4: =IFERROR(($AQ4/$R4),"-") -> 40.902913 | AQ4: =VLOOKUP($B4,'Luminate Item Data'!A:AT,46,FALSE) -> 8426 | AR4: =VLOOKUP($B4,'Luminate Item Data'!A:AU,47,FALSE) -> 4 | AS4: =VLOOKUP($B4,'Luminate Item Data'!A:AV,48,FALSE) -> 6 | AT4: =VLOOKUP($B4,'Luminate Item Data'!A:AW,49,FALSE) -> 251 | AU4: =IFERROR(VLOOKUP($B4,'Luminate Warehouse Inv'!B:E,4,FALSE),0) -> 0 | AV4: =IFERROR(VLOOKUP($B4,'Luminate Warehouse Inv'!B:G,6,FALSE),0) -> 246 | AW4: =VLOOKUP($B4,'Luminate Item Data'!$A:$D,4,FALSE) -> 85007565801 | AX4: =VLOOKUP($B4,'Luminate Item Data'!$A:$E,5,FALSE) -> 45803
B5: Grand Totals | E5: =AVERAGE(E3:E4) -> 0.98675 | F5: =AVERAGE(F3:F4) -> 0.23330847 | G5: =AVERAGE(G3:G4) -> 9.0898469 | H5: =AVERAGE(Table4[YTD $/P/W]) -> 2.37953 | I5: =AVERAGE(Table4[ Wkly Sell Thru %]) -> 0.042992657 | J5: =AVERAGE(Table4[[ Unit Cost]]) -> 23.38 | K5: =AVERAGE(Table4[[ Unit Retail]]) -> 38.96 | L5: =AVERAGE(Table4[[ Avg Retail]]) -> 38.985363 | M5: =AVERAGE(Table4[YTD AUR]) -> 38.750271 | N5: =AVERAGE(Table4[ MU %]) -> 0.39989733 | O5: =SUBTOTAL(9,Table4 [ Curr Traited Store/Item Comb] ) -> 2945 | P5: =SUM(Table4[Traited Store LY]) -> 0 | Q5: =SUBTOTAL(1,Table4[LW Store Count Chg %]) -> 1 | R5: =SUM(Table4[[ LW POS Qty]]) -> 687 | S5: =SUM(Table4[[ LY LW POS Qty]]) -> 0 | T5: =($R5-$S5)/$S5 -> #DIV/0! | U5: =SUM(Table4[LW POS Cost]) -> 16062.06 | V5: =SUM(Table4[[ LW POS Sales]]) -> 26765.97 | W5: =SUM(Table4[[ LY LW POS Sales]]) -> 0 | X5: =($V5-$W5)/$W5 -> #DIV/0! | Y5: =SUM(Table4[[ YTD POS Qty]]) -> 7594 | Z5: =SUM(Table4[[ LY YTD POS Qty]]) -> 0 | AA5: =(Y5-Z5)/Z5 -> #DIV/0! | AB5: =SUM(Table4[[ YTD POS Sales]]) -> 294294.53 | AC5: =SUM(Table4[[ LY YTD POS Sales]]) -> 0 | AD5: =(AB5-AC5)/AC5 -> #DIV/0! | AE5: =AVERAGE(Table4 [ YTD Sell Thru %] ) -> 0.32241687 | AF5: =SUM(Table4[[ LW Gross Ship Qty]]) -> 420 | AG5: =SUM(Table4[[ YTD Gross Ship Qty]]) -> 23289 | AH5: =SUM(Table4[[ LW Total Customer Item Return]]) -> -39 | AI5: =AVERAGE(Table4[[ LW Total Return Rate]]) -> -0.061355792 | AJ5: =AVERAGE(Table4[ YTD Def Rate (sales)]) -> -0.72458238 | AK5: =SUM(Table4[[ YTD Total Customer Item Return]]) -> -269 | AL5: =AVERAGE(Table4[[ YTD Total Return Rate]]) -> -0.034161135 | AM5: =SUM(Table4 [ LW SI Total MUMD $] ) -> -634.92 | AN5: =SUM(Table4 [ YTD SI Total MUMD $] ) -> 7133.44 | AO5: =SUM(Table4 [ 52/53 WK FC Units] ) -> 149627.77 | AQ5: =SUM(Table4[[ Curr Str On Hand Qty]]) -> 15688 | AR5: =SUM(Table4[[ Curr Str In Transit Qty]]) -> 78 | AS5: =SUM(Table4[[ Curr Str In Whse Qty]]) -> 102 | AT5: =SUM(Table4[[ Curr Str On Order Qty]]) -> 1201 | AU5: =SUM(Table4[[ Curr Whse On Hand Qty]]) -> 40 | AV5: =SUM(Table4[[ Curr Whse SS Order Qty]]) -> 1167

Sheet All Item Detail
B1: Replenishment | All Item Detail | H1: 3 | I1: 4 | J1: 5 | K1: 6 | L1: 7 | M1: 8 | N1: 9 | O1: 10 | P1: 11 | Q1: 12 | R1: 13 | S1: 14 | T1: 15 | U1: 16 | V1: 17 | W1: 18 | X1: 19 | Y1: 20 | Z1: 21 | AA1: 22 | AB1: 23 | AC1: 24 | AD1: 25 | AE1: 26 | AF1: 27 | AG1: 28 | AH1: 29 | AI1: 30 | AJ1: 31 | AK1: 32 | AL1: 33 | AM1: 34 | AN1: 35 | AO1: 36 | AP1: 37 | AQ1: 38 | AR1: 39 | AS1: 40 | AT1: 41 | AU1: 42 | AV1: 43 | AW1: 44 | AX1: 45 | AY1: 46 | AZ1: 47 | BA1: 48 | BB1: 49 | BC1: 50 | BD1: 51 | BE1: 52 | BF1: 53 | BG1: 54
G2: WOW Increase/Decrease | H2: =IFERROR((H4-G4)/G4,0) -> 0 | I2: =IFERROR((I4-H4)/H4,0) -> 0 | J2: =IFERROR((J4-I4)/I4,0) -> 0 | K2: =IFERROR((K4-J4)/J4,0) -> 0 | L2: =IFERROR((L4-K4)/K4,0) -> 0 | M2: =IFERROR((M4-L4)/L4,0) -> 0 | N2: =IFERROR((N4-M4)/M4,0) -> 0 | O2: =IFERROR((O4-N4)/N4,0) -> 0 | ... AK2: =IFERROR((AK4-AJ4)/AJ4,0) -> 0 | AL2: =(AL4-AK4)/AK4 -> 43.079055 | AM2: =(AM4-AL4)/AL4 -> 4.0434631 | AN2: =(AN4-AM4)/AM4 -> 1.5100043 | AO2: =(AO4-AN4)/AN4 -> 0.17248174 | AP2: =(AP4-AO4)/AO4 -> 0.25719729 | AQ2: =(AQ4-AP4)/AP4 -> -0.05279311 | AR2: =(AR4-AQ4)/AQ4 -> 0.049126114 | AS2: =(AS4-AR4)/AR4 -> -0.03712836 | ... AW2: =(AW4-AV4)/AV4 -> -0.03689288
G3: Total Sales Units per Week | H3: 0 | I3: 0 | J3: 0 | K3: 0 | L3: 0 | M3: 0 | N3: 0 | O3: 0 | P3: 0 | Q3: 0 | R3: 0 | S3: 0 | T3: 0 | U3: 0 | V3: 0 | W3: 0 | X3: 0 | Y3: 0 | Z3: 0 | AA3: 0 | AB3: 0 | AC3: 0 | AD3: 0 | AE3: 0 | AF3: 0 | AG3: 0 | AH3: 0 | AI3: 0 | AJ3: 0 | AK3: 1 | AL3: 48 | AM3: 226 | AN3: 564 | AO3: 655 | AP3: 824 | AQ3: 782 | AR3: 820 | AS3: 797 | AT3: 733 | AU3: 741 | AV3: 716 | AW3: 687
G4: Total Sales $ | H4: 0 | I4: 0 | J4: 0 | K4: 0 | L4: 0 | M4: 0 | N4: 0 | O4: 0 | P4: 0 | Q4: 0 | R4: 0 | S4: 0 | T4: 0 | U4: 0 | V4: 0 | W4: 0 | X4: 0 | Y4: 0 | Z4: 0 | AA4: 0 | AB4: 0 | AC4: 0 | AD4: 0 | AE4: 0 | AF4: 0 | AG4: 0 | AH4: 0 | AI4: 0 | AJ4: 0 | AK4: 38.96 | AL4: 1717.32 | AM4: 8661.24 | AN4: 21739.75 | AO4: 25489.46 | AP4: 32045.28 | AQ4: 30353.51 | AR4: 31844.66 | AS4: 30662.32 | AT4: 28437.29 | AU4: 28747.5 | AV4: 27791.27 | AW4: 26765.97
G5: Total TSC | H5: 0 | I5: 0 | J5: 0 | K5: 0 | L5: 0 | M5: 0 | N5: 0 | O5: 0 | P5: 0 | Q5: 0 | R5: 0 | S5: 0 | T5: 0 | U5: 0 | V5: 0 | W5: 0 | X5: 0 | Y5: 0 | Z5: 0 | AA5: 0 | AB5: 0 | AC5: 0 | AD5: 0 | AE5: 0 | AF5: 0 | AG5: 0 | AH5: 0 | AI5: 0 | AJ5: 0 | AK5: 0 | AL5: 2879 | AM5: 2881 | AN5: 2881 | AO5: 2883 | AP5: 2885 | AQ5: 2947 | AR5: 2949 | AS5: 2948 | AT5: 2947 | AU5: 2945 | AV5: 2947 | AW5: 2945
B6: Acct Dept Nbr | C6: Vendor Stk Nbr | D6: Prime Item Nbr | E6: Prime Item Desc | F6: Unique | G6: Data Type | H6: 202501 | I6: 202502 | J6: 202503 | K6: 202504 | L6: 202505 | M6: 202506 | N6: 202507 | O6: 202508 | P6: 202509 | Q6: 202510 | R6: 202511 | S6: 202512 | T6: 202513 | U6: 202514 | V6: 202515 | W6: 202516 | X6: 202517 | Y6: 202518 | Z6: 202519 | AA6: 202520 | AB6: 202521 | AC6: 202522 | AD6: 202523 | AE6: 202524 | AF6: 202525 | AG6: 202526 | AH6: 202527 | AI6: 202528 | AJ6: 202529 | AK6: 202530 | AL6: 202531 | AM6: 202532 | AN6: 202533 | AO6: 202534 | AP6: 202535 | AQ6: 202536 | AR6: 202537 | AS6: 202538 | AT6: 202539 | AU6: 202540 | AV6: 202541 | AW6: 202542 | AX6: 202543 | AY6: 202544 | AZ6: 202545 | BA6: 202546 | BB6: 202547 | BC6: 202548 | BD6: 202549 | BE6: 202550 | BF6: 202551 | BG6: 202552
A7: =CONCATENATE(D7,G7) -> 677410826POS Sales $ | B7: 2 | C7: AS-PREC-FLOS-BK | D7: 677410826 | E7: AQUASONIC WFLS PREC | F7: 573415018POS Sales | G7: POS Sales $ | H7: 0 | I7: 0 | J7: 0 | K7: 0 | L7: 0 | M7: 0 | N7: 0 | O7: 0 | P7: 0 | Q7: 0 | R7: 0 | S7: 0 | T7: 0 | U7: 0 | V7: 0 | W7: 0 | X7: 0 | Y7: 0 | Z7: 0 | AA7: 0 | AB7: 0 | AC7: 0 | AD7: 0 | AE7: 0 | AF7: 0 | AG7: 0 | AH7: 0 | AI7: 0 | AJ7: 0 | AK7: 0 | AL7: 1201.8 | AM7: 4479.44 | AN7: 13158.52 | AO7: 16305.82 | AP7: 21142.82 | AQ7: 19385.12 | AR7: 21669.02 | AS7: 19839.36 | AT7: 19075.03 | AU7: 18340.68 | AV7: 17270.02 | AW7: 18722.27 | AX7: 0 | AY7: 0 | AZ7: 0 | BA7: 0 | BB7: 0 | BC7: 0 | BD7: 0 | BE7: 0 | BF7: 0 | BG7: 0
A8: =CONCATENATE(D8,G8) -> 677410826POS Qty | B8: 2 | C8: AS-PREC-FLOS-BK | D8: 677410826 | E8: AQUASONIC WFLS PREC | F8: 573415018POS Qty | G8: POS Qty | H8: 0 | I8: 0 | J8: 0 | K8: 0 | L8: 0 | M8: 0 | N8: 0 | O8: 0 | P8: 0 | Q8: 0 | R8: 0 | S8: 0 | T8: 0 | U8: 0 | V8: 0 | W8: 0 | X8: 0 | Y8: 0 | Z8: 0 | AA8: 0 | AB8: 0 | AC8: 0 | AD8: 0 | AE8: 0 | AF8: 0 | AG8: 0 | AH8: 0 | AI8: 0 | AJ8: 0 | AK8: 0 | AL8: 34 | AM8: 118 | AN8: 341 | AO8: 419 | AP8: 543 | AQ8: 499 | AR8: 557 | AS8: 516 | AT8: 491 | AU8: 473 | AV8: 445 | AW8: 481 | AX8: 0 | AY8: 0 | AZ8: 0 | BA8: 0 | BB8: 0 | BC8: 0 | BD8: 0 | BE8: 0 | BF8: 0 | BG8: 0
A9: =CONCATENATE(D9,G9) -> 677410826POS Qty if Instock | B9: 2 | C9: AS-PREC-FLOS-BK | D9: 677410826 | E9: AQUASONIC WFLS PREC | F9: 573415018POS Qty if Instock | G9: POS Qty if Instock | H9: 0 | I9: 0 | J9: 0 | K9: 0 | L9: 0 | M9: 0 | N9: 0 | O9: 0 | P9: 0 | Q9: 0 | R9: 0 | S9: 0 | T9: 0 | U9: 0 | V9: 0 | W9: 0 | X9: 0 | Y9: 0 | Z9: 0 | AA9: 0 | AB9: 0 | AC9: 0 | AD9: 0 | AE9: 0 | AF9: 0 | AG9: 0 | AH9: 0 | AI9: 0 | AJ9: 0 | AK9: 0 | AL9: 68 | AM9: 236 | AN9: 351.912 | AO9: 429.5169 | AP9: 550.9278 | AQ9: 504.5389 | AR9: 571.0364 | AS9: 525.4944 | AT9: 497.3339 | AU9: 479.1017 | AV9: 450.162 | AW9: 486.5796 | AX9: 0 | AY9: 0 | AZ9: 0 | BA9: 0 | BB9: 0 | BC9: 0 | BD9: 0 | BE9: 0 | BF9: 0 | BG9: 0
A10: =CONCATENATE(D10,G10) -> 677410826Units per Store per Week (w/zeros) | B10: 2 | C10: AS-PREC-FLOS-BK | D10: 677410826 | E10: AQUASONIC WFLS PREC | F10: 573415018USW | G10: Units per Store per Week (w/zeros) | H10: 0 | I10: 0 | J10: 0 | K10: 0 | L10: 0 | M10: 0 | N10: 0 | O10: 0 | P10: 0 | Q10: 0 | R10: 0 | S10: 0 | T10: 0 | U10: 0 | V10: 0 | W10: 0 | X10: 0 | Y10: 0 | Z10: 0 | AA10: 0 | AB10: 0 | AC10: 0 | AD10: 0 | AE10: 0 | AF10: 0 | AG10: 0 | AH10: 0 | AI10: 0 | AJ10: 0 | AK10: 0 | AL10: 0.023627519 | AM10: 0.081944444 | AN10: 0.23680556 | AO10: 0.2907703 | AP10: 0.37656033 | AQ10: 0.33876443 | AR10: 0.37788331 | AS10: 0.3503055 | AT10: 0.33333333 | AU10: 0.32133152 | AV10: 0.30210455 | AW10: 0.3267663 | AX10: 0 | AY10: 0 | AZ10: 0 | BA10: 0 | BB10: 0 | BC10: 0 | BD10: 0 | BE10: 0 | BF10: 0 | BG10: 0
A11: =CONCATENATE(D11,G11) -> 677410826Avg Price | B11: 2 | C11: AS-PREC-FLOS-BK | D11: 677410826 | E11: AQUASONIC WFLS PREC | F11: 573415018Avg Price | G11: Avg Price | H11: 0 | I11: 0 | J11: 0 | K11: 0 | L11: 0 | M11: 0 | N11: 0 | O11: 0 | P11: 0 | Q11: 0 | R11: 0 | S11: 0 | T11: 0 | U11: 0 | V11: 0 | W11: 0 | X11: 0 | Y11: 0 | Z11: 0 | AA11: 0 | AB11: 0 | AC11: 0 | AD11: 0 | AE11: 0 | AF11: 0 | AG11: 0 | AH11: 0 | AI11: 0 | AJ11: 0 | AK11: 0 | AL11: 35.347059 | AM11: 37.961356 | AN11: 38.588035 | AO11: 38.916038 | AP11: 38.937053 | AQ11: 38.847936 | AR11: 38.903088 | AS11: 38.448372 | AT11: 38.849348 | AU11: 38.775222 | AV11: 38.809034 | AW11: 38.923638 | AX11: 0 | AY11: 0 | AZ11: 0 | BA11: 0 | BB11: 0 | BC11: 0 | BD11: 0 | BE11: 0 | BF11: 0 | BG11: 0
A12: =CONCATENATE(D12,G12) -> 677410826Traited Stores | B12: 2 | C12: AS-PREC-FLOS-BK | D12: 677410826 | E12: AQUASONIC WFLS PREC | F12: 573415018Avg Traited Store/Item Comb. | G12: Traited Stores | H12: 0 | I12: 0 | J12: 0 | K12: 0 | L12: 0 | M12: 0 | N12: 0 | O12: 0 | P12: 0 | Q12: 0 | R12: 0 | S12: 0 | T12: 0 | U12: 0 | V12: 0 | W12: 0 | X12: 0 | Y12: 0 | Z12: 0 | AA12: 0 | AB12: 0 | AC12: 0 | AD12: 0 | AE12: 0 | AF12: 0 | AG12: 0 | AH12: 0 | AI12: 0 | AJ12: 0 | AK12: 0 | AL12: 1439 | AM12: 1440 | AN12: 1440 | AO12: 1441 | AP12: 1442 | AQ12: 1473 | AR12: 1474 | AS12: 1473 | AT12: 1473 | AU12: 1472 | AV12: 1473 | AW12: 1472 | AX12: 0 | AY12: 0 | AZ12: 0 | BA12: 0 | BB12: 0 | BC12: 0 | BD12: 0 | BE12: 0 | BF12: 0 | BG12: 0
A13: =CONCATENATE(D13,G13) -> 677410826Instock | B13: 2 | C13: AS-PREC-FLOS-BK | D13: 677410826 | E13: AQUASONIC WFLS PREC | F13: 573415018Avg Instock % | G13: Instock | H13: 0 | I13: 0 | J13: 0 | K13: 0 | L13: 0 | M13: 0 | N13: 0 | O13: 0 | P13: 0 | Q13: 0 | R13: 0 | S13: 0 | T13: 0 | U13: 0 | V13: 0 | W13: 0 | X13: 0 | Y13: 0 | Z13: 0 | AA13: 0 | AB13: 0 | AC13: 0 | AD13: 0 | AE13: 0 | AF13: 0 | AG13: 0 | AH13: 0 | AI13: 0 | AJ13: 0 | AK13: 0 | AL13: 0 | AM13: 0 | AN13: 0.968 | AO13: 0.9749 | AP13: 0.9854 | AQ13: 0.9889 | AR13: 0.9748 | AS13: 0.9816 | AT13: 0.9871 | AU13: 0.9871 | AV13: 0.9884 | AW13: 0.9884 | AX13: 0 | AY13: 0 | AZ13: 0 | BA13: 0 | BB13: 0 | BC13: 0 | BD13: 0 | BE13: 0 | BF13: 0 | BG13: 0
A14: =CONCATENATE(D14,G14) -> 677410826Forecast | B14: 2 | C14: AS-PREC-FLOS-BK | D14: 677410826 | E14: AQUASONIC WFLS PREC | F14: 573415018Forecast | G14: Forecast | H14: 1160.38 | I14: 1331.27 | J14: 1603.65 | K14: 1828.22 | L14: 1830.35 | M14: 1625.91 | N14: 1605.65 | O14: 1579.09 | P14: 1562.92 | Q14: 1492.85 | R14: 1460.18 | S14: 1371.42 | T14: 1411.15 | U14: 1314.38 | V14: 1286.22 | W14: 1277.65 | X14: 1240.12 | Y14: 1338.88 | Z14: 1306.26 | AA14: 1358.61 | AB14: 1358.61 | AC14: 1304.1 | AD14: 1299.89 | AE14: 1300.62 | AF14: 1296.68 | AG14: 1337.52 | AH14: 1330.41 | AI14: 1374.86 | AJ14: 1356.84 | AK14: 1319.98 | AL14: 1245.11 | AM14: 1348.54 | AN14: 1472.72 | AO14: 1395.82 | AP14: 1533.55 | AQ14: 1390.35 | AR14: 1423.78 | AS14: 1433.92 | AT14: 1473.25 | AU14: 1498.24 | AV14: 1504.84 | AW14: 1408.22 | AX14: 1243.53 | AY14: 1543.86 | AZ14: 1700.14 | BA14: 2214.56 | BB14: 2203.16 | BC14: 1531.53 | BD14: 1450.65 | BE14: 1287.48 | BF14: 1043.52 | BG14: 1175.73
A15: =CONCATENATE(D15,G15) -> 677410826Variance | B15: 2 | C15: AS-PREC-FLOS-BK | D15: 677410826 | E15: AQUASONIC WFLS PREC | F15: 573415019Variance | G15: Variance | H15: 0 | I15: 0 | J15: 0 | K15: 0 | L15: 0 | M15: 0 | N15: 0 | O15: 0 | P15: 0 | Q15: 0 | R15: 0 | S15: 0 | T15: 0 | U15: 0 | V15: 0 | W15: 0 | X15: 0 | Y15: 0 | Z15: 0 | AA15: 0 | AB15: 0 | AC15: 0 | AD15: 0 | AE15: 0 | AF15: 0 | AG15: 0 | AH15: 0 | AI15: 0 | AJ15: 0 | AK15: 0 | AL15: 0.027306824 | AM15: 0.087502039 | AN15: 0.23154435 | AO15: 0.30018197 | AP15: 0.3540804 | AQ15: 0.35890243 | AR15: 0.39121213 | AS15: 0.35985271 | AT15: 0.33327677 | AU15: 0.31570376 | AV15: 0.2957125 | AW15: 0.34156595 | AX15: 0 | AY15: 0 | AZ15: 0 | BA15: 0 | BB15: 0 | BC15: 0 | BD15: 0 | BE15: 0 | BF15: 0 | BG15: 0
A16: =CONCATENATE(D16,G16) -> 677536463POS Sales $ | B16: 2 | C16: AS-PREC-TB-BK | D16: 677536463 | E16: AS TOOTHBRUSH | F16: 573415018POS Sales | G16: POS Sales $ | H16: 0 | I16: 0 | J16: 0 | K16: 0 | L16: 0 | M16: 0 | N16: 0 | O16: 0 | P16: 0 | Q16: 0 | R16: 0 | S16: 0 | T16: 0 | U16: 0 | V16: 0 | W16: 0 | X16: 0 | Y16: 0 | Z16: 0 | AA16: 0 | AB16: 0 | AC16: 0 | AD16: 0 | AE16: 0 | AF16: 0 | AG16: 0 | AH16: 0 | AI16: 0 | AJ16: 0 | AK16: 38.96 | AL16: 515.52 | AM16: 4181.8 | AN16: 8581.23 | AO16: 9183.64 | AP16: 10902.46 | AQ16: 10968.39 | AR16: 10175.64 | AS16: 10822.96 | AT16: 9362.26 | AU16: 10406.82 | AV16: 10521.25 | AW16: 8043.7 | AX16: 0 | AY16: 0 | AZ16: 0 | BA16: 0 | BB16: 0 | BC16: 0 | BD16: 0 | BE16: 0 | BF16: 0 | BG16: 0
A17: =CONCATENATE(D17,G17) -> 677536463POS Qty | B17: 2 | C17: AS-PREC-TB-BK | D17: 677536463 | E17: AS TOOTHBRUSH | F17: 573415018POS Qty | G17: POS Qty | H17: 0 | I17: 0 | J17: 0 | K17: 0 | L17: 0 | M17: 0 | N17: 0 | O17: 0 | P17: 0 | Q17: 0 | R17: 0 | S17: 0 | T17: 0 | U17: 0 | V17: 0 | W17: 0 | X17: 0 | Y17: 0 | Z17: 0 | AA17: 0 | AB17: 0 | AC17: 0 | AD17: 0 | AE17: 0 | AF17: 0 | AG17: 0 | AH17: 0 | AI17: 0 | AJ17: 0 | AK17: 1 | AL17: 14 | AM17: 108 | AN17: 223 | AO17: 236 | AP17: 281 | AQ17: 283 | AR17: 263 | AS17: 281 | AT17: 242 | AU17: 268 | AV17: 271 | AW17: 206 | AX17: 0 | AY17: 0 | AZ17: 0 | BA17: 0 | BB17: 0 | BC17: 0 | BD17: 0 | BE17: 0 | BF17: 0 | BG17: 0
A18: =CONCATENATE(D18,G18) -> 677536463POS Qty if Instock | B18: 2 | C18: AS-PREC-TB-BK | D18: 677536463 | E18: AS TOOTHBRUSH | F18: 573415018POS Qty if Instock | G18: POS Qty if Instock | H18: 0 | I18: 0 | J18: 0 | K18: 0 | L18: 0 | M18: 0 | N18: 0 | O18: 0 | P18: 0 | Q18: 0 | R18: 0 | S18: 0 | T18: 0 | U18: 0 | V18: 0 | W18: 0 | X18: 0 | Y18: 0 | Z18: 0 | AA18: 0 | AB18: 0 | AC18: 0 | AD18: 0 | AE18: 0 | AF18: 0 | AG18: 0 | AH18: 0 | AI18: 0 | AJ18: 0 | AK18: 2 | AL18: 28 | AM18: 216 | AN18: 231.5186 | AO18: 242.2304 | AP18: 284.5125 | AQ18: 285.9432 | AR18: 269.6276 | AS18: 285.215 | AT18: 244.4684 | AU18: 270.3852 | AV18: 273.5745 | AW18: 209.0694 | AX18: 0 | AY18: 0 | AZ18: 0 | BA18: 0 | BB18: 0 | BC18: 0 | BD18: 0 | BE18: 0 | BF18: 0 | BG18: 0
... A24: =CONCATENATE(D24,G24) -> 677536463Variance | B24: 2 | C24: AS-PREC-TB-BK | D24: 677536463 | E24: AS TOOTHBRUSH | F24: 573415019Variance | G24: Variance | H24: 0 | I24: 0 | J24: 0 | K24: 0 | L24: 0 | M24: 0 | N24: 0 | O24: 0 | P24: 0 | Q24: 0 | R24: 0 | S24: 0 | T24: 0 | U24: 0 | V24: 0 | W24: 0 | X24: 0 | Y24: 0 | Z24: 0 | AA24: 0 | AB24: 0 | AC24: 0 | AD24: 0 | AE24: 0 | AF24: 0 | AG24: 0 | AH24: 0 | AI24: 0 | AJ24: 0 | AK24: 0.00076684764 | AL24: 0.011521022 | AM24: 0.081494673 | AN24: 0.15283499 | AO24: 0.15314433 | AP24: 0.16734757 | AQ24: 0.18655978 | AR24: 0.17603748 | AS24: 0.19275885 | AT24: 0.15382757 | AU24: 0.17334385 | AV24: 0.1787481 | AW24: 0.14116357 | AX24: 0 | AY24: 0 | AZ24: 0 | BA24: 0 | BB24: 0 | BC24: 0 | BD24: 0 | BE24: 0 | BF24: 0 | BG24: 0

Sheet Scorecard Aquasonic
B1: Last Week | E1: Current Month | H1: Last Month | K1: Year | N1: Q1 | Q1: Q2 | T1: Q3 | W1: Q4
B2: (202542-202542/202443-202443) | E2: (202540-202543/202441-202444) | H2: (202536-202539/202437-202440) | K2: (202501-202543/202402-202444) | N2: (202501-202513/202401-202413) | Q2: (202514-202526/202414-202426) | T2: (202527-202539/202427-202439) | W2: (202540-202552/202440-202452)
B3: TY | C3: LY | D3: Diff | E3: TY | F3: LY | G3: Diff | H3: TY | I3: LY | J3: Diff | K3: TY | L3: LY | M3: Diff | N3: TY | O3: LY | P3: Diff | Q3: TY | R3: LY | S3: Diff | T3: TY | U3: LY | V3: Diff | W3: TY | X3: LY | Y3: Diff
A4: Vendor Scorecard - Vendor 122289 / AQUASONIC LLC
A5: Store Sales
A6: POS Sales in dollars | B6: 26765.97 | C6: 0 | D6: 0 | E6: 83304.74 | F6: 0 | G6: 0 | H6: 121297.78 | I6: 0 | J6: 0 | K6: 294294.53 | L6: 0 | M6: 0 | N6: 0 | O6: 0 | P6: 0 | Q6: 0 | R6: 0 | S6: 0 | T6: 210989.79 | U6: 0 | V6: 0 | W6: 83304.74 | X6: 0 | Y6: 0
A7: Comp Sales in dollars | B7: 26725.05 | C7: 0 | D7: 0 | E7: 83224.86 | F7: 0 | G7: 0 | H7: 120986.1 | I7: 0 | J7: 0 | K7: 293786.09 | L7: 0 | M7: 0 | N7: 0 | O7: 0 | P7: 0 | Q7: 0 | R7: 0 | S7: 0 | T7: 210561.23 | U7: 0 | V7: 0 | W7: 83224.86 | X7: 0 | Y7: 0
A8: POS Sales in Units | B8: 687 | C8: 0 | D8: 0 | E8: 2144 | F8: 0 | G8: 0 | H8: 3132 | I8: 0 | J8: 0 | K8: 7594 | L8: 0 | M8: 0 | N8: 0 | O8: 0 | P8: 0 | Q8: 0 | R8: 0 | S8: 0 | T8: 5450 | U8: 0 | V8: 0 | W8: 2144 | X8: 0 | Y8: 0
A9: AUR (Avg Unit Retail) | B9: 38.96 | C9: 0 | D9: 0 | E9: 38.85 | F9: 0 | G9: 0 | H9: 38.73 | I9: 0 | J9: 0 | K9: 38.75 | L9: 0 | M9: 0 | N9: 0 | O9: 0 | P9: 0 | Q9: 0 | R9: 0 | S9: 0 | T9: 38.71 | U9: 0 | V9: 0 | W9: 38.85 | X9: 0 | Y9: 0
A10: Store Returns in dollars | B10: 116.88 | C10: 0 | D10: 0 | E10: 155.84 | F10: 0 | G10: 0 | H10: 116.88 | I10: 0 | J10: 0 | K10: 272.72 | L10: 0 | M10: 0 | N10: 0 | O10: 0 | P10: 0 | Q10: 0 | R10: 0 | S10: 0 | T10: 116.88 | U10: 0 | V10: 0 | W10: 155.84 | X10: 0 | Y10: 0
A11: Store Returns as % of POS Sales | B11: 0.004366739 | C11: 0 | D11: 0 | E11: 0.001870722 | F11: 0 | G11: 0 | H11: 0.000963579 | I11: 0 | J11: 0 | K11: 0.000926691 | L11: 0 | M11: 0 | N11: 0 | O11: 0 | P11: 0 | Q11: 0 | R11: 0 | S11: 0 | T11: 0.00055396 | U11: 0 | V11: 0 | W11: 0.001870722 | X11: 0 | Y11: 0
A12: Store Inventory
A13: Retail Dollar Inventory | B13: 617490.27 | C13: 0 | D13: 0 | E13: 630968.43 | F13: 0 | G13: 0 | H13: 644640.17 | I13: 0 | J13: 0 | K13: 448597.88 | L13: 0 | M13: 0 | N13: 0 | O13: 0 | P13: 0 | Q13: 0 | R13: 0 | S13: 0 | T13: 403005.25 | U13: 0 | V13: 0 | W13: 630968.43 | X13: 0 | Y13: 0
A14: Cost Dollar Inventory | B14: 384130.84 | C14: 0 | D14: 0 | E14: 392703.17 | F14: 0 | G14: 0 | H14: 394208.2 | I14: 0 | J14: 0 | K14: 273874.22 | L14: 0 | M14: 0 | N14: 0 | O14: 0 | P14: 0 | Q14: 0 | R14: 0 | S14: 0 | T14: 244166.98 | U14: 0 | V14: 0 | W14: 392703.17 | X14: 0 | Y14: 0
A15: Cost On Order | B15: 29121.463 | C15: 0 | D15: 0 | E15: 27068.16 | F15: 0 | G15: 0 | H15: 40008.244 | I15: 0 | J15: 0 | K15: 92440.909 | L15: 0 | M15: 0 | N15: 0 | O15: 0 | P15: 0 | Q15: 0 | R15: 0 | S15: 0 | T15: 108784.1 | U15: 0 | V15: 0 | W15: 27068.16 | X15: 0 | Y15: 0
A16: Repl Instock % | B16: 0.98888403 | C16: 0 | D16: 0 | E16: 0.98896172 | F16: 0 | G16: 0 | H16: 0.98595523 | I16: 0 | J16: 0 | K16: 0.98301463 | L16: 0 | M16: 0 | N16: 0 | O16: 0 | P16: 0 | Q16: 0 | R16: 0 | S16: 0 | T16: 0.98031583 | U16: 0 | V16: 0 | W16: 0.98896172 | X16: 0 | Y16: 0
A17: Unit Turns | B17: 2.2564019 | C17: 0 | D17: 0 | E17: 2.2959894 | F17: 0 | G17: 0 | H17: 2.4611213 | I17: 0 | J17: 0 | K17: 2.2854677 | L17: 0 | M17: 0 | N17: 0 | O17: 0 | P17: 0 | Q17: 0 | R17: 0 | S17: 0 | T17: 2.2813548 | U17: 0 | V17: 0 | W17: 2.2959894 | X17: 0 | Y17: 0
A18: Retail turns | B18: 2.2540119 | C18: 0 | D18: 0 | E18: 2.2884645 | F18: 0 | G18: 0 | H18: 2.4461261 | I18: 0 | J18: 0 | K18: 2.274244 | L18: 0 | M18: 0 | N18: 0 | O18: 0 | P18: 0 | Q18: 0 | R18: 0 | S18: 0 | T18: 2.2686779 | U18: 0 | V18: 0 | W18: 2.2884645 | X18: 0 | Y18: 0
A19: Store Weeks of Supply/ Weeks on Hand | B19: 21.717347 | C19: 0 | D19: 0 | E19: 21.428013 | F19: 0 | G19: 0 | H19: 23.064671 | I19: 0 | J19: 0 | K19: 26.984729 | L19: 0 | M19: 0 | N19: 0 | O19: 0 | P19: 0 | Q19: 0 | R19: 0 | S19: 0 | T19: 30.626275 | U19: 0 | V19: 0 | W19: 21.428013 | X19: 0 | Y19: 0
A20: Ships at Retail | B20: 16363.2 | C20: 0 | D20: 0 | E20: 52964.1 | F20: 0 | G20: 0 | H20: 117358.8 | I20: 0 | J20: 0 | K20: 907709.88 | L20: 0 | M20: 0 | N20: 0 | O20: 0 | P20: 0 | Q20: 0 | R20: 0 | S20: 0 | T20: 854745.78 | U20: 0 | V20: 0 | W20: 52964.1 | X20: 0 | Y20: 0
A21: Ships at cost | B21: 10215.8 | C21: 0 | D21: 0 | E21: 33055.41 | F21: 0 | G21: 0 | H21: 73188.91 | I21: 0 | J21: 0 | K21: 566420.83 | L21: 0 | M21: 0 | N21: 0 | O21: 0 | P21: 0 | Q21: 0 | R21: 0 | S21: 0 | T21: 533365.42 | U21: 0 | V21: 0 | W21: 33055.41 | X21: 0 | Y21: 0
A22: DC Inventory
A23: Ships At Cost WHSE | B23: 14010.24 | C23: 0 | D23: 0 | E23: 44949.52 | F23: 0 | G23: 0 | H23: 145933.36 | I23: 0 | J23: 0 | K23: 645319.94 | L23: 0 | M23: 0 | N23: 0 | O23: 0 | P23: 0 | Q23: 0 | R23: 0 | S23: 0 | T23: 600370.42 | U23: 0 | V23: 0 | W23: 44949.52 | X23: 0 | Y23: 0
A24: Warehouse Weeks of Supply/Weeks on Hand | B24: 0 | C24: 0 | D24: 0 | E24: 0 | F24: 0 | G24: 0 | H24: 0 | I24: 0 | J24: 0 | K24: 0 | L24: 0 | M24: 0 | N24: 0 | O24: 0 | P24: 0 | Q24: 0 | R24: 0 | S24: 0 | T24: 0 | U24: 0 | V24: 0 | W24: 0 | X24: 0 | Y24: 0
A25: Cost On Hand | B25: 0 | C25: 0 | D25: 0 | E25: 0 | F25: 0 | G25: 0 | H25: 0 | I25: 0 | J25: 0 | K25: 0 | L25: 0 | M25: 0 | N25: 0 | O25: 0 | P25: 0 | Q25: 0 | R25: 0 | S25: 0 | T25: 0 | U25: 0 | V25: 0 | W25: 0 | X25: 0 | Y25: 0
A26: Cost On Order | B26: 27334.56 | C26: 0 | D26: 0 | E26: 21783.48 | F26: 0 | G26: 0 | H26: 87574.8 | I26: 0 | J26: 0 | K26: 57380.961 | L26: 0 | M26: 0 | N26: 0 | O26: 0 | P26: 0 | Q26: 0 | R26: 0 | S26: 0 | T26: 116887.15 | U26: 0 | V26: 0 | W26: 21783.48 | X26: 0 | Y26: 0
A27: Warehouse Turns | B27: 0 | C27: 0 | D27: 0 | E27: 0 | F27: 0 | G27: 0 | H27: 0 | I27: 0 | J27: 0 | K27: 0 | L27: 0 | M27: 0 | N27: 0 | O27: 0 | P27: 0 | Q27: 0 | R27: 0 | S27: 0 | T27: 0 | U27: 0 | V27: 0 | W27: 0 | X27: 0 | Y27: 0
A28: Margins and Markdowns
A29: Gross Initial Margin % | B29: 0.37568446 | C29: 0 | D29: 0 | E29: 0.37589027 | F29: 0 | G29: 0 | H29: 0.37636624 | I29: 0 | J29: 0 | K29: 0.37598913 | L29: 0 | M29: 0 | N29: 0 | O29: 0 | P29: 0 | Q29: 0 | R29: 0 | S29: 0 | T29: 0.37599526 | U29: 0 | V29: 0 | W29: 0.37589027 | X29: 0 | Y29: 0
A30: Maintain Margin % | B30: 0.39049396 | C30: 0 | D30: 0 | E30: 0.36747141 | F30: 0 | G30: 0 | H30: 0.3592636 | I30: 0 | J30: 0 | K30: 0.36122094 | L30: 0 | M30: 0 | N30: 0 | O30: 0 | P30: 0 | Q30: 0 | R30: 0 | S30: 0 | T30: 0.35871981 | U30: 0 | V30: 0 | W30: 0.36747141 | X30: 0 | Y30: 0
A31: Net Maintain Margin % | B31: 0.39032389 | C31: 0 | D31: 0 | E31: 0.36739961 | F31: 0 | G31: 0 | H31: 0.3592395 | I31: 0 | J31: 0 | K31: 0.36121358 | L31: 0 | M31: 0 | N31: 0 | O31: 0 | P31: 0 | Q31: 0 | R31: 0 | S31: 0 | T31: 0.35871645 | U31: 0 | V31: 0 | W31: 0.36739961 | X31: 0 | Y31: 0
A32: Net Maintained Margin $ | B32: 10447.398 | C32: 0 | D32: 0 | E32: 30606.129 | F32: 0 | G32: 0 | H32: 43574.954 | I32: 0 | J32: 0 | K32: 106303.18 | L32: 0 | M32: 0 | N32: 0 | O32: 0 | P32: 0 | Q32: 0 | R32: 0 | S32: 0 | T32: 75685.509 | U32: 0 | V32: 0 | W32: 30606.129 | X32: 0 | Y32: 0
A33: GMROII | B33: 1.4148861 | C33: 0 | D33: 0 | E33: 1.351173 | F33: 0 | G33: 0 | H33: 1.4370894 | I33: 0 | J33: 0 | K33: 1.3456002 | L33: 0 | M33: 0 | N33: 0 | O33: 0 | P33: 0 | Q33: 0 | R33: 0 | S33: 0 | T33: 1.3432349 | U33: 0 | V33: 0 | W33: 1.351173 | X33: 0 | Y33: 0
A34: MUMD Dollars | B34: -634.92 | C34: 0 | D34: 0 | E34: 1123.73 | F34: 0 | G34: 0 | H34: 3326.49 | I34: 0 | J34: 0 | K34: 6964.94 | L34: 0 | M34: 0 | N34: 0 | O34: 0 | P34: 0 | Q34: 0 | R34: 0 | S34: 0 | T34: 5841.21 | U34: 0 | V34: 0 | W34: 1123.73 | X34: 0 | Y34: 0
A35: MUMD Percent To Sales | B35: -0.023721165 | C35: 0 | D35: 0 | E35: 0.013489388 | F35: 0 | G35: 0 | H35: 0.027424162 | I35: 0 | J35: 0 | K35: 0.023666563 | L35: 0 | M35: 0 | N35: 0 | O35: 0 | P35: 0 | Q35: 0 | R35: 0 | S35: 0 | T35: 0.027684799 | U35: 0 | V35: 0 | W35: 0.013489388 | X35: 0 | Y35: 0

Sheet All Item Detail Data
B1: Replenishment | All Item Detail | H1: 3 | I1: 4 | J1: 5 | K1: 6 | L1: 7 | M1: 8 | N1: 9 | O1: 10 | P1: 11 | Q1: 12 | R1: 13 | S1: 14 | T1: 15 | U1: 16 | V1: 17 | W1: 18 | X1: 19 | Y1: 20 | Z1: 21 | AA1: 22 | AB1: 23 | AC1: 24 | AD1: 25 | AE1: 26 | AF1: 27 | AG1: 28 | AH1: 29 | AI1: 30 | AJ1: 31 | AK1: 32 | AL1: 33 | AM1: 34 | AN1: 35 | AO1: 36 | AP1: 37 | AQ1: 38 | AR1: 39 | AS1: 40 | AT1: 41 | AU1: 42 | AV1: 43 | AW1: 44 | AX1: 45 | AY1: 46 | AZ1: 47 | BA1: 48 | BB1: 49 | BC1: 50 | BD1: 51 | BE1: 52 | BF1: 53 | BG1: 54
B2: Acct Dept Nbr | C2: Vendor Stk Nbr | D2: Prime Item Nbr | E2: Prime Item Desc | F2: Unique | G2: Data Type | H2: 202501 | I2: 202502 | J2: 202503 | K2: 202504 | L2: 202505 | M2: 202506 | N2: 202507 | O2: 202508 | P2: 202509 | Q2: 202510 | R2: 202511 | S2: 202512 | T2: 202513 | U2: 202514 | V2: 202515 | W2: 202516 | X2: 202517 | Y2: 202518 | Z2: 202519 | AA2: 202520 | AB2: 202521 | AC2: 202522 | AD2: 202523 | AE2: 202524 | AF2: 202525 | AG2: 202526 | AH2: 202527 | AI2: 202528 | AJ2: 202529 | AK2: 202530 | AL2: 202531 | AM2: 202532 | AN2: 202533 | AO2: 202534 | AP2: 202535 | AQ2: 202536 | AR2: 202537 | AS2: 202538 | AT2: 202539 | AU2: 202540 | AV2: 202541 | AW2: 202542 | AX2: 202543 | AY2: 202544 | AZ2: 202545 | BA2: 202546 | BB2: 202547 | BC2: 202548 | BD2: 202549 | BE2: 202550 | BF2: 202551 | BG2: 202552
A3: =CONCATENATE(D3,G3) -> 677410826pos_sales_this_year | B3: 2 | C3: AS-PREC-FLOS-BK | D3: 677410826 | E3: AQUASONIC WFLS PREC | F3: 573415018POS Sales | G3: pos_sales_this_year | H3: =VLOOKUP($A3,'Last Week Data'!$E:$BF,H$1,0) -> 0 | I3: =VLOOKUP($A3,'Last Week Data'!$E:$BF,I$1,0) -> 0 | J3: =VLOOKUP($A3,'Last Week Data'!$E:$BF,J$1,0) -> 0 | K3: =VLOOKUP($A3,'Last Week Data'!$E:$BF,K$1,0) -> 0 | L3: =VLOOKUP($A3,'Last Week Data'!$E:$BF,L$1,0) -> 0 | M3: =VLOOKUP($A3,'Last Week Data'!$E:$BF,M$1,0) -> 0 | N3: =VLOOKUP($A3,'Last Week Data'!$E:$BF,N$1,0) -> 0 | O3: =VLOOKUP($A3,'Last Week Data'!$E:$BF,O$1,0) -> 0 | ... BG3: =VLOOKUP($A3,'Last Week Data'!$E:$BF,BG$1,0) -> 0
A4: =CONCATENATE(D4,G4) -> 677410826pos_quantity_this_year | B4: 2 | C4: AS-PREC-FLOS-BK | D4: 677410826 | E4: AQUASONIC WFLS PREC | F4: 573415018POS Qty | G4: pos_quantity_this_year | H4: =VLOOKUP($A4,'Last Week Data'!$E$3:$BF$17924,H$1,0) -> 0 | I4: =VLOOKUP($A4,'Last Week Data'!$E$3:$BF$17924,I$1,0) -> 0 | J4: =VLOOKUP($A4,'Last Week Data'!$E$3:$BF$17924,J$1,0) -> 0 | K4: =VLOOKUP($A4,'Last Week Data'!$E$3:$BF$17924,K$1,0) -> 0 | L4: =VLOOKUP($A4,'Last Week Data'!$E$3:$BF$17924,L$1,0) -> 0 | M4: =VLOOKUP($A4,'Last Week Data'!$E$3:$BF$17924,M$1,0) -> 0 | N4: =VLOOKUP($A4,'Last Week Data'!$E$3:$BF$17924,N$1,0) -> 0 | O4: =VLOOKUP($A4,'Last Week Data'!$E$3:$BF$17924,O$1,0) -> 0 | ... BG4: =VLOOKUP($A4,'Last Week Data'!$E$3:$BF$17924,BG$1,0) -> 0
A5: =CONCATENATE(D5,G5) -> 677410826POS Qty if Instock | B5: 2 | C5: AS-PREC-FLOS-BK | D5: 677410826 | E5: AQUASONIC WFLS PREC | F5: 573415018POS Qty if Instock | G5: POS Qty if Instock | H5: =((1-H9)*H4)+H4 -> 0 | I5: =((1-I9)*I4)+I4 -> 0 | J5: =((1-J9)*J4)+J4 -> 0 | K5: =((1-K9)*K4)+K4 -> 0 | L5: =((1-L9)*L4)+L4 -> 0 | M5: =((1-M9)*M4)+M4 -> 0 | N5: =((1-N9)*N4)+N4 -> 0 | O5: =((1-O9)*O4)+O4 -> 0 | ... BG5: =((1-BG9)*BG4)+BG4 -> 0
A6: =CONCATENATE(D6,G6) -> 677410826Units per Store per Week (w/zeros) | B6: 2 | C6: AS-PREC-FLOS-BK | D6: 677410826 | E6: AQUASONIC WFLS PREC | F6: 573415018USW | G6: Units per Store per Week (w/zeros) | H6: =IFERROR(H4/H8,0) -> 0 | I6: =IFERROR(I4/I8,0) -> 0 | J6: =IFERROR(J4/J8,0) -> 0 | K6: =IFERROR(K4/K8,0) -> 0 | L6: =IFERROR(L4/L8,0) -> 0 | M6: =IFERROR(M4/M8,0) -> 0 | N6: =IFERROR(N4/N8,0) -> 0 | O6: =IFERROR(O4/O8,0) -> 0 | ... BG6: =IFERROR(BG4/BG8,0) -> 0
A7: =CONCATENATE(D7,G7) -> 677410826Avg Price | B7: 2 | C7: AS-PREC-FLOS-BK | D7: 677410826 | E7: AQUASONIC WFLS PREC | F7: 573415018Avg Price | G7: Avg Price | H7: =IFERROR(H3/H4,0) -> 0 | I7: =IFERROR(I3/I4,0) -> 0 | J7: =IFERROR(J3/J4,0) -> 0 | K7: =IFERROR(K3/K4,0) -> 0 | L7: =IFERROR(L3/L4,0) -> 0 | M7: =IFERROR(M3/M4,0) -> 0 | N7: =IFERROR(N3/N4,0) -> 0 | O7: =IFERROR(O3/O4,0) -> 0 | ... BG7: =IFERROR(BG3/BG4,0) -> 0
A8: =CONCATENATE(D8,G8) -> 677410826traited_store_count_this_year | B8: 2 | C8: AS-PREC-FLOS-BK | D8: 677410826 | E8: AQUASONIC WFLS PREC | F8: 573415018Avg Traited Store/Item Comb. | G8: traited_store_count_this_year | H8: =VLOOKUP($A8,'Last Week Data'!$E$3:$BF$17924,H$1,0) -> 0 | I8: =VLOOKUP($A8,'Last Week Data'!$E$3:$BF$17924,I$1,0) -> 0 | J8: =VLOOKUP($A8,'Last Week Data'!$E$3:$BF$17924,J$1,0) -> 0 | K8: =VLOOKUP($A8,'Last Week Data'!$E$3:$BF$17924,K$1,0) -> 0 | L8: =VLOOKUP($A8,'Last Week Data'!$E$3:$BF$17924,L$1,0) -> 0 | M8: =VLOOKUP($A8,'Last Week Data'!$E$3:$BF$17924,M$1,0) -> 0 | N8: =VLOOKUP($A8,'Last Week Data'!$E$3:$BF$17924,N$1,0) -> 0 | O8: =VLOOKUP($A8,'Last Week Data'!$E$3:$BF$17924,O$1,0) -> 0 | ... BG8: =VLOOKUP($A8,'Last Week Data'!$E$3:$BF$17924,BG$1,0) -> 0
A9: =CONCATENATE(D9,G9) -> 677410826repl_instock_percentage_this_year_eop | B9: 2 | C9: AS-PREC-FLOS-BK | D9: 677410826 | E9: AQUASONIC WFLS PREC | F9: 573415018Avg Instock % | G9: repl_instock_percentage_this_year_eop | H9: =VLOOKUP($A9,'Last Week Data'!$E$3:$BF$17924,H$1,0) -> 0 | I9: =VLOOKUP($A9,'Last Week Data'!$E$3:$BF$17924,I$1,0) -> 0 | J9: =VLOOKUP($A9,'Last Week Data'!$E$3:$BF$17924,J$1,0) -> 0 | K9: =VLOOKUP($A9,'Last Week Data'!$E$3:$BF$17924,K$1,0) -> 0 | L9: =VLOOKUP($A9,'Last Week Data'!$E$3:$BF$17924,L$1,0) -> 0 | M9: =VLOOKUP($A9,'Last Week Data'!$E$3:$BF$17924,M$1,0) -> 0 | N9: =VLOOKUP($A9,'Last Week Data'!$E$3:$BF$17924,N$1,0) -> 0 | O9: =VLOOKUP($A9,'Last Week Data'!$E$3:$BF$17924,O$1,0) -> 0 | ... BG9: =VLOOKUP($A9,'Last Week Data'!$E$3:$BF$17924,BG$1,0) -> 0
A10: =CONCATENATE(D10,G10) -> 677410826Forecast | B10: 2 | C10: AS-PREC-FLOS-BK | D10: 677410826 | E10: AQUASONIC WFLS PREC | F10: 573415018Forecast | G10: Forecast | H10: =_xlfn.IFNA(VLOOKUP($D10,'Luminate Forecast'!$U:$BV,'Luminate Forecast'!V$19,0),0) -> 1160.38 | I10: =_xlfn.IFNA(VLOOKUP($D10,'Luminate Forecast'!$U:$BV,'Luminate Forecast'!W$19,0),0) -> 1331.27 | J10: =_xlfn.IFNA(VLOOKUP($D10,'Luminate Forecast'!$U:$BV,'Luminate Forecast'!X$19,0),0) -> 1603.65 | K10: =_xlfn.IFNA(VLOOKUP($D10,'Luminate Forecast'!$U:$BV,'Luminate Forecast'!Y$19,0),0) -> 1828.22 | L10: =_xlfn.IFNA(VLOOKUP($D10,'Luminate Forecast'!$U:$BV,'Luminate Forecast'!Z$19,0),0) -> 1830.35 | M10: =_xlfn.IFNA(VLOOKUP($D10,'Luminate Forecast'!$U:$BV,'Luminate Forecast'!AA$19,0),0) -> 1625.91 | N10: =_xlfn.IFNA(VLOOKUP($D10,'Luminate Forecast'!$U:$BV,'Luminate Forecast'!AB$19,0),0) -> 1605.65 | O10: =_xlfn.IFNA(VLOOKUP($D10,'Luminate Forecast'!$U:$BV,'Luminate Forecast'!AC$19,0),0) -> 1579.09 | ... BG10: =_xlfn.IFNA(VLOOKUP($D10,'Luminate Forecast'!$U:$BV,'Luminate Forecast'!BU$19,0),0) -> 1175.73
A11: =CONCATENATE(D11,G11) -> 677410826Variance | B11: 2 | C11: AS-PREC-FLOS-BK | D11: 677410826 | E11: AQUASONIC WFLS PREC | F11: 573415019Variance | G11: Variance | H11: =IF(H10>0,H4/H10,0) -> 0 | I11: =IF(I10>0,I4/I10,0) -> 0 | J11: =IF(J10>0,J4/J10,0) -> 0 | K11: =IF(K10>0,K4/K10,0) -> 0 | L11: =IF(L10>0,L4/L10,0) -> 0 | M11: =IF(M10>0,M4/M10,0) -> 0 | N11: =IF(N10>0,N4/N10,0) -> 0 | O11: =IF(O10>0,O4/O10,0) -> 0 | ... BG11: =IF(BG10>0,BG4/BG10,0) -> 0
A12: =CONCATENATE(D12,G12) -> 677536463pos_sales_this_year | B12: 2 | C12: AS-PREC-TB-BK | D12: 677536463 | E12: AS TOOTHBRUSH | F12: 573415018POS Sales | G12: pos_sales_this_year | H12: =VLOOKUP($A12,'Last Week Data'!$E:$BF,H$1,0) -> 0 | I12: =VLOOKUP($A12,'Last Week Data'!$E:$BF,I$1,0) -> 0 | J12: =VLOOKUP($A12,'Last Week Data'!$E:$BF,J$1,0) -> 0 | K12: =VLOOKUP($A12,'Last Week Data'!$E:$BF,K$1,0) -> 0 | L12: =VLOOKUP($A12,'Last Week Data'!$E:$BF,L$1,0) -> 0 | M12: =VLOOKUP($A12,'Last Week Data'!$E:$BF,M$1,0) -> 0 | N12: =VLOOKUP($A12,'Last Week Data'!$E:$BF,N$1,0) -> 0 | O12: =VLOOKUP($A12,'Last Week Data'!$E:$BF,O$1,0) -> 0 | ... BG12: =VLOOKUP($A12,'Last Week Data'!$E:$BF,BG$1,0) -> 0
A13: =CONCATENATE(D13,G13) -> 677536463pos_quantity_this_year | B13: 2 | C13: AS-PREC-TB-BK | D13: 677536463 | E13: AS TOOTHBRUSH | F13: 573415018POS Qty | G13: pos_quantity_this_year | H13: =VLOOKUP($A13,'Last Week Data'!$E$3:$BF$17924,H$1,0) -> 0 | I13: =VLOOKUP($A13,'Last Week Data'!$E$3:$BF$17924,I$1,0) -> 0 | J13: =VLOOKUP($A13,'Last Week Data'!$E$3:$BF$17924,J$1,0) -> 0 | K13: =VLOOKUP($A13,'Last Week Data'!$E$3:$BF$17924,K$1,0) -> 0 | L13: =VLOOKUP($A13,'Last Week Data'!$E$3:$BF$17924,L$1,0) -> 0 | M13: =VLOOKUP($A13,'Last Week Data'!$E$3:$BF$17924,M$1,0) -> 0 | N13: =VLOOKUP($A13,'Last Week Data'!$E$3:$BF$17924,N$1,0) -> 0 | O13: =VLOOKUP($A13,'Last Week Data'!$E$3:$BF$17924,O$1,0) -> 0 | ... BG13: =VLOOKUP($A13,'Last Week Data'!$E$3:$BF$17924,BG$1,0) -> 0
A14: =CONCATENATE(D14,G14) -> 677536463POS Qty if Instock | B14: 2 | C14: AS-PREC-TB-BK | D14: 677536463 | E14: AS TOOTHBRUSH | F14: 573415018POS Qty if Instock | G14: POS Qty if Instock | H14: =((1-H18)*H13)+H13 -> 0 | I14: =((1-I18)*I13)+I13 -> 0 | J14: =((1-J18)*J13)+J13 -> 0 | K14: =((1-K18)*K13)+K13 -> 0 | L14: =((1-L18)*L13)+L13 -> 0 | M14: =((1-M18)*M13)+M13 -> 0 | N14: =((1-N18)*N13)+N13 -> 0 | O14: =((1-O18)*O13)+O13 -> 0 | ... BG14: =((1-BG18)*BG13)+BG13 -> 0
A15: =CONCATENATE(D15,G15) -> 677536463Units per Store per Week (w/zeros) | B15: 2 | C15: AS-PREC-TB-BK | D15: 677536463 | E15: AS TOOTHBRUSH | F15: 573415018USW | G15: Units per Store per Week (w/zeros) | H15: =IFERROR(H13/H17,0) -> 0 | I15: =IFERROR(I13/I17,0) -> 0 | J15: =IFERROR(J13/J17,0) -> 0 | K15: =IFERROR(K13/K17,0) -> 0 | L15: =IFERROR(L13/L17,0) -> 0 | M15: =IFERROR(M13/M17,0) -> 0 | N15: =IFERROR(N13/N17,0) -> 0 | O15: =IFERROR(O13/O17,0) -> 0 | ... BG15: =IFERROR(BG13/BG17,0) -> 0
A16: =CONCATENATE(D16,G16) -> 677536463Avg Price | B16: 2 | C16: AS-PREC-TB-BK | D16: 677536463 | E16: AS TOOTHBRUSH | F16: 573415018Avg Price | G16: Avg Price | H16: =IFERROR(H12/H13,0) -> 0 | I16: =IFERROR(I12/I13,0) -> 0 | J16: =IFERROR(J12/J13,0) -> 0 | K16: =IFERROR(K12/K13,0) -> 0 | L16: =IFERROR(L12/L13,0) -> 0 | M16: =IFERROR(M12/M13,0) -> 0 | N16: =IFERROR(N12/N13,0) -> 0 | O16: =IFERROR(O12/O13,0) -> 0 | ... BG16: =IFERROR(BG12/BG13,0) -> 0
A17: =CONCATENATE(D17,G17) -> 677536463traited_store_count_this_year | B17: 2 | C17: AS-PREC-TB-BK | D17: 677536463 | E17: AS TOOTHBRUSH | F17: 573415018Avg Traited Store/Item Comb. | G17: traited_store_count_this_year | H17: =VLOOKUP($A17,'Last Week Data'!$E$3:$BF$17924,H$1,0) -> 0 | I17: =VLOOKUP($A17,'Last Week Data'!$E$3:$BF$17924,I$1,0) -> 0 | J17: =VLOOKUP($A17,'Last Week Data'!$E$3:$BF$17924,J$1,0) -> 0 | K17: =VLOOKUP($A17,'Last Week Data'!$E$3:$BF$17924,K$1,0) -> 0 | L17: =VLOOKUP($A17,'Last Week Data'!$E$3:$BF$17924,L$1,0) -> 0 | M17: =VLOOKUP($A17,'Last Week Data'!$E$3:$BF$17924,M$1,0) -> 0 | N17: =VLOOKUP($A17,'Last Week Data'!$E$3:$BF$17924,N$1,0) -> 0 | O17: =VLOOKUP($A17,'Last Week Data'!$E$3:$BF$17924,O$1,0) -> 0 | ... BG17: =VLOOKUP($A17,'Last Week Data'!$E$3:$BF$17924,BG$1,0) -> 0
A18: =CONCATENATE(D18,G18) -> 677536463repl_instock_percentage_this_year_eop | B18: 2 | C18: AS-PREC-TB-BK | D18: 677536463 | E18: AS TOOTHBRUSH | F18: 573415018Avg Instock % | G18: repl_instock_percentage_this_year_eop | H18: =VLOOKUP($A18,'Last Week Data'!$E$3:$BF$17924,H$1,0) -> 0 | I18: =VLOOKUP($A18,'Last Week Data'!$E$3:$BF$17924,I$1,0) -> 0 | J18: =VLOOKUP($A18,'Last Week Data'!$E$3:$BF$17924,J$1,0) -> 0 | K18: =VLOOKUP($A18,'Last Week Data'!$E$3:$BF$17924,K$1,0) -> 0 | L18: =VLOOKUP($A18,'Last Week Data'!$E$3:$BF$17924,L$1,0) -> 0 | M18: =VLOOKUP($A18,'Last Week Data'!$E$3:$BF$17924,M$1,0) -> 0 | N18: =VLOOKUP($A18,'Last Week Data'!$E$3:$BF$17924,N$1,0) -> 0 | O18: =VLOOKUP($A18,'Last Week Data'!$E$3:$BF$17924,O$1,0) -> 0 | ... BG18: =VLOOKUP($A18,'Last Week Data'!$E$3:$BF$17924,BG$1,0) -> 0
A19: =CONCATENATE(D19,G19) -> 677536463Forecast | B19: 2 | C19: AS-PREC-TB-BK | D19: 677536463 | E19: AS TOOTHBRUSH | F19: 573415018Forecast | G19: Forecast | H19: =_xlfn.IFNA(VLOOKUP($D19,'Luminate Forecast'!$U:$BV,'Luminate Forecast'!V$19,0),0) -> 1071.84 | I19: =_xlfn.IFNA(VLOOKUP($D19,'Luminate Forecast'!$U:$BV,'Luminate Forecast'!W$19,0),0) -> 1158.21 | J19: =_xlfn.IFNA(VLOOKUP($D19,'Luminate Forecast'!$U:$BV,'Luminate Forecast'!X$19,0),0) -> 1462.58 | K19: =_xlfn.IFNA(VLOOKUP($D19,'Luminate Forecast'!$U:$BV,'Luminate Forecast'!Y$19,0),0) -> 1863.85 | L19: =_xlfn.IFNA(VLOOKUP($D19,'Luminate Forecast'!$U:$BV,'Luminate Forecast'!Z$19,0),0) -> 1753.79 | M19: =_xlfn.IFNA(VLOOKUP($D19,'Luminate Forecast'!$U:$BV,'Luminate Forecast'!AA$19,0),0) -> 1625.82 | N19: =_xlfn.IFNA(VLOOKUP($D19,'Luminate Forecast'!$U:$BV,'Luminate Forecast'!AB$19,0),0) -> 1635.45 | O19: =_xlfn.IFNA(VLOOKUP($D19,'Luminate Forecast'!$U:$BV,'Luminate Forecast'!AC$19,0),0) -> 1644.69 | ... BG19: =_xlfn.IFNA(VLOOKUP($D19,'Luminate Forecast'!$U:$BV,'Luminate Forecast'!BU$19,0),0) -> 1113.8
A20: =CONCATENATE(D20,G20) -> 677536463Variance | B20: 2 | C20: AS-PREC-TB-BK | D20: 677536463 | E20: AS TOOTHBRUSH | F20: 573415019Variance | G20: Variance | H20: =IF(H19>0,H13/H19,0) -> 0 | I20: =IF(I19>0,I13/I19,0) -> 0 | J20: =IF(J19>0,J13/J19,0) -> 0 | K20: =IF(K19>0,K13/K19,0) -> 0 | L20: =IF(L19>0,L13/L19,0) -> 0 | M20: =IF(M19>0,M13/M19,0) -> 0 | N20: =IF(N19>0,N13/N19,0) -> 0 | O20: =IF(O19>0,O13/O19,0) -> 0 | ... BG20: =IF(BG19>0,BG13/BG19,0) -> 0

Sheet Last Week Data
E1: 1 | F1: 2 | G1: 3 | H1: 4 | I1: 5 | J1: 6 | K1: 7 | L1: 8 | M1: 9 | N1: 10 | O1: 11 | P1: 12 | Q1: 13 | R1: 14 | S1: 15 | T1: 16 | U1: 17 | V1: 18 | W1: 19 | X1: 20 | Y1: 21 | Z1: 22 | AA1: 23 | AB1: 24 | AC1: 25 | AD1: 26 | AE1: 27 | AF1: 28 | AG1: 29 | AH1: 30 | AI1: 31 | AJ1: 32 | AK1: 33 | AL1: 34 | AM1: 35 | AN1: 36 | AO1: 37 | AP1: 38 | AQ1: 39 | AR1: 40 | AS1: 41 | AT1: 42 | AU1: 43 | AV1: 44 | AW1: 45 | AX1: 46 | AY1: 47 | AZ1: 48 | BA1: 49 | BB1: 50 | BC1: 51 | BD1: 52 | BE1: 53 | BF1: 54
A2: Acct Dept Nbr | B2: Vendor Stk Nbr | C2: Prime Item Nbr | D2: Prime Item Desc | E2: Unique | F2: Data Type | G2: 202501 | H2: 202502 | I2: 202503 | J2: 202504 | K2: 202505 | L2: 202506 | M2: 202507 | N2: 202508 | O2: 202509 | P2: 202510 | Q2: 202511 | R2: 202512 | S2: 202513 | T2: 202514 | U2: 202515 | V2: 202516 | W2: 202517 | X2: 202518 | Y2: 202519 | Z2: 202520 | AA2: 202521 | AB2: 202522 | AC2: 202523 | AD2: 202524 | AE2: 202525 | AF2: 202526 | AG2: 202527 | AH2: 202528 | AI2: 202529 | AJ2: 202530 | AK2: 202531 | AL2: 202532 | AM2: 202533 | AN2: 202534 | AO2: 202535 | AP2: 202536 | AQ2: 202537 | AR2: 202538 | AS2: 202539 | AT2: 202540 | AU2: 202541 | AV2: 202542 | AW2: 202543 | AX2: 202544 | AY2: 202545 | AZ2: 202546 | BA2: 202547 | BB2: 202548 | BC2: 202549 | BD2: 202550 | BE2: 202551 | BF2: 202552
A3: 2 | B3: AS-PREC-FLOS-BK | C3: 677410826 | D3: AQUASONIC WFLS PREC | E3: =CONCATENATE(C3,F3) -> 677410826pos_sales_this_year | F3: pos_sales_this_year | G3: 0 | H3: 0 | I3: 0 | J3: 0 | K3: 0 | L3: 0 | M3: 0 | N3: 0 | O3: 0 | P3: 0 | Q3: 0 | R3: 0 | S3: 0 | T3: 0 | U3: 0 | V3: 0 | W3: 0 | X3: 0 | Y3: 0 | Z3: 0 | AA3: 0 | AB3: 0 | AC3: 0 | AD3: 0 | AE3: 0 | AF3: 0 | AG3: 0 | AH3: 0 | AI3: 0 | AJ3: 0 | AK3: 1201.8 | AL3: 4479.44 | AM3: 13158.52 | AN3: 16305.82 | AO3: 21142.82 | AP3: 19385.12 | AQ3: 21669.02 | AR3: 19839.36 | AS3: 19075.03 | AT3: 18340.68 | AU3: 17270.02 | AV3: 18722.27
A4: 2 | B4: AS-PREC-FLOS-BK | C4: 677410826 | D4: AQUASONIC WFLS PREC | E4: =CONCATENATE(C4,F4) -> 677410826pos_quantity_this_year | F4: pos_quantity_this_year | G4: 0 | H4: 0 | I4: 0 | J4: 0 | K4: 0 | L4: 0 | M4: 0 | N4: 0 | O4: 0 | P4: 0 | Q4: 0 | R4: 0 | S4: 0 | T4: 0 | U4: 0 | V4: 0 | W4: 0 | X4: 0 | Y4: 0 | Z4: 0 | AA4: 0 | AB4: 0 | AC4: 0 | AD4: 0 | AE4: 0 | AF4: 0 | AG4: 0 | AH4: 0 | AI4: 0 | AJ4: 0 | AK4: 34 | AL4: 118 | AM4: 341 | AN4: 419 | AO4: 543 | AP4: 499 | AQ4: 557 | AR4: 516 | AS4: 491 | AT4: 473 | AU4: 445 | AV4: 481
A5: 2 | B5: AS-PREC-FLOS-BK | C5: 677410826 | D5: AQUASONIC WFLS PREC | E5: =CONCATENATE(C5,F5) -> 677410826traited_store_count_this_year | F5: traited_store_count_this_year | G5: 0 | H5: 0 | I5: 0 | J5: 0 | K5: 0 | L5: 0 | M5: 0 | N5: 0 | O5: 0 | P5: 0 | Q5: 0 | R5: 0 | S5: 0 | T5: 0 | U5: 0 | V5: 0 | W5: 0 | X5: 0 | Y5: 0 | Z5: 0 | AA5: 0 | AB5: 0 | AC5: 0 | AD5: 0 | AE5: 0 | AF5: 0 | AG5: 0 | AH5: 0 | AI5: 0 | AJ5: 0 | AK5: 1439 | AL5: 1440 | AM5: 1440 | AN5: 1441 | AO5: 1442 | AP5: 1473 | AQ5: 1474 | AR5: 1473 | AS5: 1473 | AT5: 1472 | AU5: 1473 | AV5: 1472
A6: 2 | B6: AS-PREC-FLOS-BK | C6: 677410826 | D6: AQUASONIC WFLS PREC | E6: =CONCATENATE(C6,F6) -> 677410826repl_instock_percentage_this_year_eop | F6: repl_instock_percentage_this_year_eop | G6: 0 | H6: 0 | I6: 0 | J6: 0 | K6: 0 | L6: 0 | M6: 0 | N6: 0 | O6: 0 | P6: 0 | Q6: 0 | R6: 0 | S6: 0 | T6: 0 | U6: 0 | V6: 0 | W6: 0 | X6: 0 | Y6: 0 | Z6: 0 | AA6: 0 | AB6: 0 | AC6: 0 | AD6: 0 | AE6: 0 | AF6: 0 | AG6: 0 | AH6: 0 | AI6: 0 | AJ6: 0 | AK6: 0 | AL6: 0 | AM6: 0.968 | AN6: 0.9749 | AO6: 0.9854 | AP6: 0.9889 | AQ6: 0.9748 | AR6: 0.9816 | AS6: 0.9871 | AT6: 0.9871 | AU6: 0.9884 | AV6: 0.9884
A7: 2 | B7: AS-PREC-TB-BK | C7: 677536463 | D7: AS TOOTHBRUSH | E7: =CONCATENATE(C7,F7) -> 677536463pos_sales_this_year | F7: pos_sales_this_year | G7: 0 | H7: 0 | I7: 0 | J7: 0 | K7: 0 | L7: 0 | M7: 0 | N7: 0 | O7: 0 | P7: 0 | Q7: 0 | R7: 0 | S7: 0 | T7: 0 | U7: 0 | V7: 0 | W7: 0 | X7: 0 | Y7: 0 | Z7: 0 | AA7: 0 | AB7: 0 | AC7: 0 | AD7: 0 | AE7: 0 | AF7: 0 | AG7: 0 | AH7: 0 | AI7: 0 | AJ7: 38.96 | AK7: 515.52 | AL7: 4181.8 | AM7: 8581.23 | AN7: 9183.64 | AO7: 10902.46 | AP7: 10968.39 | AQ7: 10175.64 | AR7: 10822.96 | AS7: 9362.26 | AT7: 10406.82 | AU7: 10521.25 | AV7: 8043.7
A8: 2 | B8: AS-PREC-TB-BK | C8: 677536463 | D8: AS TOOTHBRUSH | E8: =CONCATENATE(C8,F8) -> 677536463pos_quantity_this_year | F8: pos_quantity_this_year | G8: 0 | H8: 0 | I8: 0 | J8: 0 | K8: 0 | L8: 0 | M8: 0 | N8: 0 | O8: 0 | P8: 0 | Q8: 0 | R8: 0 | S8: 0 | T8: 0 | U8: 0 | V8: 0 | W8: 0 | X8: 0 | Y8: 0 | Z8: 0 | AA8: 0 | AB8: 0 | AC8: 0 | AD8: 0 | AE8: 0 | AF8: 0 | AG8: 0 | AH8: 0 | AI8: 0 | AJ8: 1 | AK8: 14 | AL8: 108 | AM8: 223 | AN8: 236 | AO8: 281 | AP8: 283 | AQ8: 263 | AR8: 281 | AS8: 242 | AT8: 268 | AU8: 271 | AV8: 206
A9: 2 | B9: AS-PREC-TB-BK | C9: 677536463 | D9: AS TOOTHBRUSH | E9: =CONCATENATE(C9,F9) -> 677536463traited_store_count_this_year | F9: traited_store_count_this_year | G9: 0 | H9: 0 | I9: 0 | J9: 0 | K9: 0 | L9: 0 | M9: 0 | N9: 0 | O9: 0 | P9: 0 | Q9: 0 | R9: 0 | S9: 0 | T9: 0 | U9: 0 | V9: 0 | W9: 0 | X9: 0 | Y9: 0 | Z9: 0 | AA9: 0 | AB9: 0 | AC9: 0 | AD9: 0 | AE9: 0 | AF9: 0 | AG9: 0 | AH9: 0 | AI9: 0 | AJ9: 0 | AK9: 1440 | AL9: 1441 | AM9: 1441 | AN9: 1442 | AO9: 1443 | AP9: 1474 | AQ9: 1475 | AR9: 1475 | AS9: 1474 | AT9: 1473 | AU9: 1474 | AV9: 1473
A10: 2 | B10: AS-PREC-TB-BK | C10: 677536463 | D10: AS TOOTHBRUSH | E10: =CONCATENATE(C10,F10) -> 677536463repl_instock_percentage_this_year_eop | F10: repl_instock_percentage_this_year_eop | G10: 0 | H10: 0 | I10: 0 | J10: 0 | K10: 0 | L10: 0 | M10: 0 | N10: 0 | O10: 0 | P10: 0 | Q10: 0 | R10: 0 | S10: 0 | T10: 0 | U10: 0 | V10: 0 | W10: 0 | X10: 0 | Y10: 0 | Z10: 0 | AA10: 0 | AB10: 0 | AC10: 0 | AD10: 0 | AE10: 0 | AF10: 0 | AG10: 0 | AH10: 0 | AI10: 0 | AJ10: 0 | AK10: 0 | AL10: 0 | AM10: 0.9618 | AN10: 0.9736 | AO10: 0.9875 | AP10: 0.9896 | AQ10: 0.9748 | AR10: 0.985 | AS10: 0.9898 | AT10: 0.9911 | AU10: 0.9905 | AV10: 0.9851

Sheet Luminate Sales Data
A32: 1 | B32: 2 | C32: 3 | D32: 4 | E32: 5 | F32: 6 | G32: 7 | H32: 8 | I32: 9 | J32: 10 | K32: 11 | L32: 12 | M32: 13 | N32: 14 | O32: 15 | P32: 16 | Q32: 17 | R32: 18 | S32: 19 | T32: 20 | U32: 21 | V32: 22 | W32: 23 | X32: 24 | Y32: 25 | Z32: 26 | AA32: 27 | AB32: 28 | AC32: 29 | AD32: 30 | AE32: 31 | AF32: 32 | AG32: 33 | AH32: 34 | AI32: 35 | AJ32: 36 | AK32: 37 | AL32: 38
A33: prime_item_number | B33: all_links_item_description | C33: LW_pos_quantity_this_year | D33: LW_pos_quantity_last_year | E33: LW_pos_sales_this_year | F33: LW_pos_sales_last_year | G33: LW_units_per_str_with_sales_per_week_or_per_day_ty | H33: LW_units_per_str_with_sales_per_week_or_per_day_ly | I33: LW_dollar_per_str_with_sales_per_week_or_per_day_ty | J33: LW_dollar_per_str_with_sales_per_week_or_per_day_ly | K33: LW_gross_receipt_quantity_this_year | L33: LW_gross_receipt_quantity_last_year | M33: LW_total_store_customer_returns_amount_defective_this_year | N33: LW_total_store_customer_returns_amount_defective_last_year | O33: LW_total_store_customer_returns_quantity_defective_this_year | P33: LW_total_store_customer_returns_quantity_defective_last_year | Q33: LW_total_store_customer_returns_quantity_this_year | R33: LW_total_store_customer_returns_quantity_last_year | S33: LW_total_store_customer_returns_amount_this_year | T33: LW_total_store_customer_returns_amount_last_year | U33: YTD_pos_quantity_this_year | V33: YTD_pos_quantity_last_year | W33: YTD_pos_sales_this_year | X33: YTD_pos_sales_last_year | Y33: YTD_units_per_str_with_sales_per_week_or_per_day_ty | Z33: YTD_units_per_str_with_sales_per_week_or_per_day_ly | AA33: YTD_dollar_per_str_with_sales_per_week_or_per_day_ty | AB33: YTD_dollar_per_str_with_sales_per_week_or_per_day_ly | AC33: YTD_gross_receipt_quantity_this_year | AD33: YTD_gross_receipt_quantity_last_year | AE33: YTD_total_store_customer_returns_amount_defective_this_year | AF33: YTD_total_store_customer_returns_amount_defective_last_year | AG33: YTD_total_store_customer_returns_quantity_defective_this_year | AH33: YTD_total_store_customer_returns_quantity_defective_last_year | AI33: YTD_total_store_customer_returns_quantity_this_year | AJ33: YTD_total_store_customer_returns_quantity_last_year | AK33: YTD_total_store_customer_returns_amount_this_year | AL33: YTD_total_store_customer_returns_amount_last_year
A34: 677410826 | B34: AQUASONIC WFLS PREC | C34: 481 | D34: 0 | E34: 18722.27 | F34: 0 | G34: 1.13 | H34: 0 | I34: 44.05 | J34: 0 | K34: 411 | L34: 0 | M34: -545.44 | N34: 0 | O34: -14 | P34: 0 | Q34: -24 | R34: 0 | S34: -937 | T34: 0 | U34: 4917 | V34: 0 | W34: 190589.9 | X34: 0 | Y34: 0.08 | Z34: 0 | AA34: 3.23 | AB34: 0 | AC34: 12342 | AD34: 0 | AE34: -4120.02 | AF34: 0 | AG34: -106 | AH34: 0 | AI34: -189 | AJ34: 0 | AK34: -7315.27 | AL34: 0
A35: 677536463 | B35: AS TOOTHBRUSH | C35: 206 | D35: 0 | E35: 8043.7 | F35: 0 | G35: 1.02 | H35: 0 | I35: 39.82 | J35: 0 | K35: 9 | L35: 0 | M35: -233.76 | N35: 0 | O35: -6 | P35: 0 | Q35: -15 | R35: 0 | S35: -541.54 | T35: 0 | U35: 2677 | V35: 0 | W35: 103704.63 | X35: 0 | Y35: 0.05 | Z35: 0 | AA35: 2.08 | AB35: 0 | AC35: 10947 | AD35: 0 | AE35: -1636.32 | AF35: 0 | AG35: -42 | AH35: 0 | AI35: -80 | AJ35: 0 | AK35: -3065.97 | AL35: 0

Sheet Luminate Markdown
A21: prime_item_number | B21: consumer_item_description | C21: LW_mumd_amount_this_year | D21: LW_mumd_amount_last_year | E21: YTD_mumd_amount_this_year | F21: YTD_mumd_amount_last_year
A22: 677410826 | B22: AQUASONIC WFLS PREC | C22: -177.84 | D22: 0 | E22: 5195.1 | F22: 0
A23: 677536463 | B23: AS TOOTHBRUSH | C23: -457.08 | D23: 0 | E23: 1938.34 | F23: 0
A24: 679250386 | B24: AQUASONIC PRECISION | C24: 0 | D24: 0 | E24: 38.96 | F24: 0
A25: 679250397 | B25: AQUASONIC PRECISION | C25: 0 | D25: 0 | E25: 38.96 | F25: 0

Sheet Luminate Warehouse Inv
B21: prime_item_number | C21: all_links_item_description | D21: warehouse_pack_quantity | E21: warehouse_pack_quantity_this_year | F21: warehouse_packs_on_order_this_year | G21: Eaches On Order
B22: 677410826 | C22: AQUASONIC WFLS PREC | D22: 3 | E22: 40 | F22: 307 | G22: =F22*D22 -> 921
B23: 677536463 | C23: AS TOOTHBRUSH | D23: 3 | E23: 0 | F23: 82 | G23: =F23*D23 -> 246
B24: 679250386 | C24: AQUASONIC PRECISION | D24: 3 | E24: 0 | F24: 0 | G24: =F24*D24 -> 0
B25: 679250397 | C25: AQUASONIC PRECISION | D25: 3 | E25: 0 | F25: 0 | G25: =F25*D25 -> 0

Sheet Luminate Item Data
A38: prime_item_number | B38: all_links_item_description | C38: vendor_stock_id | D38: walmart_upc_number | E38: item_start_date | F38: item_order_effective_date | G38: unit_cost_amount | H38: base_unit_retail_amount | I38: warehouse_alignment_type_code | J38: item_type_code | K38: item_status_code | L38: item_replenishment_indicator | M38: cancel_when_out_indicator | N38: color_description | O38: size_description | P38: brand_name | Q38: vendor_pack_quantity | R38: vendor_pack_cost_amount | S38: warehouse_pack_quantity | T38: vendor_number | U38: vendor_name | V38: vendor_sequence_number | W38: buyer_name | X38: accounting_department_number | Y38: omni_department_description | Z38: omni_category_group_description | AA38: omni_subcategory_description | AB38: fineline_description | AC38: fineline_number | AD38: consumer_id | AE38: item_cube_quantity | AF38: item_weight_quantity | AG38: item_height_quantity | AH38: item_length_quantity | AI38: item_width_quantity | AJ38: vendor_pack_weight_quantity | AK38: vendor_pack_height_quantity | AL38: vendor_pack_length_quantity | AM38: vendor_pack_width_quantity | AN38: warehouse_pack_weight_quantity | AO38: warehouse_pack_height_quantity | AP38: warehouse_pack_length_quantity | AQ38: warehouse_pack_width_quantity | AR38: 202532_traited_store_count_this_year | AS38: 202532_repl_instock_percentage_this_year_eop | AT38: 202532_store_on_hand_quantity_this_year_eop | AU38: 202532_store_in_transit_quantity_this_year | AV38: 202532_store_in_warehouse_quantity_this_year | AW38: 202532_store_on_order_quantity_this_year | AX38: 202532_traited_store_count_last_year
A39: prime_item_number | B39: all_links_item_description | C39: vendor_stock_id | D39: walmart_upc_number | E39: item_start_date | F39: item_order_effective_date | G39: unit_cost_amount | H39: base_unit_retail_amount | I39: warehouse_alignment_type_code | J39: item_type_code | K39: item_status_code | L39: item_replenishment_indicator | M39: cancel_when_out_indicator | N39: color_description | O39: size_description | P39: brand_name | Q39: vendor_pack_quantity | R39: vendor_pack_cost_amount | S39: warehouse_pack_quantity | T39: vendor_number | U39: vendor_name | V39: vendor_sequence_number | W39: buyer_name | X39: accounting_department_number | Y39: omni_department_description | Z39: omni_category_group_description | AA39: omni_subcategory_description | AB39: fineline_description | AC39: fineline_number | AD39: consumer_id | AE39: item_cube_quantity | AF39: item_weight_quantity | AG39: item_height_quantity | AH39: item_length_quantity | AI39: item_width_quantity | AJ39: vendor_pack_weight_quantity | AK39: vendor_pack_height_quantity | AL39: vendor_pack_length_quantity | AM39: vendor_pack_width_quantity | AN39: warehouse_pack_weight_quantity | AO39: warehouse_pack_height_quantity | AP39: warehouse_pack_length_quantity | AQ39: warehouse_pack_width_quantity | AR39: traited_store_count_this_year | AS39: repl_instock_percentage_this_year_eop | AT39: store_on_hand_quantity_this_year_eop | AU39: store_in_transit_quantity_this_year | AV39: store_in_warehouse_quantity_this_year | AW39: store_on_order_quantity_this_year | AX39: traited_store_count_last_year
A40: 677410826 | B40: AQUASONIC WFLS PREC | C40: AS-PREC-FLOS-BK | D40: 85007565805 | E40: 45796 | F40: 45797 | G40: 23.38 | H40: 38.96 | I40: WH | J40: 20 | K40: A | L40: 1 | M40: 0 | N40: BLACK | O40: NA | P40: AquaSonic | Q40: 24 | R40: 561.12 | S40: 3 | T40: 122289 | U40: AQUASONIC LLC | V40: 0 | W40: Blake Barron | X40: 2 | Y40: PERSONAL CARE | Z40: ORAL CARE | AA40: WATER FLOSSERS | AB40: BASE WATER FLOSSERS | AC40: 607 | AD40: 224488320 | AE40: 0.068 | AF40: 0.96 | AG40: 9.5 | AH40: 3.1 | AI40: 4 | AJ40: 32.1 | AK40: 10.83 | AL40: 20.55 | AM40: 19.49 | AN40: 3.7 | AO40: 9.84 | AP40: 9.84 | AQ40: 4.53 | AR40: 1472 | AS40: 0.9884 | AT40: 7262 | AU40: 74 | AV40: 96 | AW40: 950 | AX40: 0
A41: 677536463 | B41: AS TOOTHBRUSH | C41: AS-PREC-TB-BK | D41: 85007565801 | E41: 45803 | F41: 45804 | G41: 23.38 | H41: 38.96 | I41: WH | J41: 20 | K41: A | L41: 1 | M41: 0 | N41: BLACK | O41: NA | P41: AquaSonic | Q41: 24 | R41: 561.12 | S41: 3 | T41: 122289 | U41: AQUASONIC LLC | V41: 0 | W41: Blake Barron | X41: 2 | Y41: PERSONAL CARE | Z41: ORAL CARE | AA41: WATER FLOSSERS | AB41: PORTABLE WATER FLOSSERS | AC41: 431 | AD41: 224537318 | AE41: 0.054 | AF41: 0.9 | AG41: 8.4 | AH41: 2.8 | AI41: 4 | AJ41: 27.5 | AK41: 10.08 | AL41: 19.09 | AM41: 18.7 | AN41: 3.2 | AO41: 8.9 | AP41: 4.45 | AQ41: 9.17 | AR41: 1473 | AS41: 0.9851 | AT41: 8426 | AU41: 4 | AV41: 6 | AW41: 251 | AX41: 0
