Workbook

Sheet SKU Info
A1: BBY SKU | B1: GLN | C1: UPC | D1: MFG | E1: Title | F1: BBY Cost | G1: MSRP | H1: Online | I1: In Stock | J1: Link | K1: Notes
A2: 6454804 | B2: 810016710004 | C2: 810016712022 | D2: AS-TBSH-SPIN | E2: AQUASONIC PROSPIN ULTRA TOOTHBRUSH | F2: 29.96 | G2: 39.95 | J2: Holding until product update
A3: 6454800 | B3: 810016710004 | C3: 810016711094 | D3: AS-TBSH-DUOP | E3: AQUASONIC DUO PRO ULTRA TOOTHBRUSHES - KEEP OFFLINE | F3: 59.96 | G3: 79.95 | H3: NO | I3: NO | J3: https://www.bestbuy.com/site/aquasonic-duo-series-pro-rechargeable-electric-toothbrush-set-midnight-black-optic-white/6454800.p?skuId=6454800 | K3: Hidden for now - focus on the Holiday exclusive
A4: 6454806 | B4: 810016710004 | C4: 810016710127 | D4: AS-TBSH-BS | E4: AQUASONIC BLACK ULTRA SONIC TOOTHBRUSH. - KEEP OFFLINE | F4: 27.71 | G4: 36.95 | H4: NO | I4: NO | J4: https://www.bestbuy.com/site/aquasonic-black-series-rechargeable-electric-toothbrush-black/6454806.p?skuId=6454806 | K4: Hidden for now - focus on the Holiday exclusive
A5: 6454805 | B5: 810016710004 | C5: 810016710066 | D5: AS-TBSH-CH | E5: AQUASONIC VIBE ULTRA TOOTHBRUSH CHARCL KEEP OFFLINE | F5: 27.71 | G5: 36.95 | H5: NO | I5: NO | J5: https://www.bestbuy.com/site/aquasonic-vibe-series-rechargeable-electric-toothbrush-charcoal-metallic/6454805.p?skuId=6454805
A6: 6454808 | B6: 810016710004 | C6: 810016710059 | D6: AS-TBSH-RG | E6: AQUASONIC VIBE ULTRA TOOTHBRUSH-RSGLD - KEEP OFFLINE | F6: 27.71 | G6: 36.95 | H6: NO | I6: NO | J6: https://www.bestbuy.com/site/aquasonic-vibe-series-rechargeable-electric-toothbrush-satin-rose-gold/6454808.p?skuId=6454808
A7: 6454798 | B7: 810016710004 | C7: 810016710042 | D7: AS-TBSH-WH | E7: AQUASONIC VIBE ULTRA TOOTHBRUSH-WHITE - KEEP OFFLINE | F7: 27.71 | G7: 36.95 | H7: NO | I7: NO | J7: https://www.bestbuy.com/site/aquasonic-vibe-series-rechargeable-electric-toothbrush-optic-white/6454798.p?skuId=6454798
A8: 6454807 | B8: 810016710004 | C8: 810016710196 | D8: AS-FLOS-PRO | E8: AQUASONIC AQUA FLOSSER PRO | F8: 37.49 | G8: 49.95 | H8: NO | I8: NO | J8: https://www.bestbuy.com/site/aquasonic-pro-water-flosser-white/6454807.p?skuId=6454807 | K8: Currently OOS
A9: 6505519 | B9: 810016710004 | C9: 810016715122 | D9: BBY-PDC-HALO-SLV | E9: Halo Face Cleansing Brush with Red & Blue LED Light | F9: 31.96 | G9: 39.95 | H9: NO | I9: NO | J9: https://www.bestbuy.com/site/pure-daily-care-halo-face-cleansing-brush-light-gray/6505519.p?skuId=6505519
A10: 6454799 | B10: 810016710004 | C10: 810016710387 | D10: AS-FLOS-REG | E10: AQUA FLOSSER RCHRGBLE ORAL IRRIGATOR -ADDING INVENTORY | F10: 29.99 | G10: 39.95 | H10: YES | I10: NO | J10: https://www.bestbuy.com/site/aquasonic-aqua-flosser-oral-irrigator-white/6454799.p?skuId=6454799
A11: 6454802 | B11: 810016710004 | C11: 810016710240 | D11: AS-HDCS-SET | E11: COMPLETE FAMILY ORAL CARE | F11: 37.46 | G11: 49.95 | H11: YES | I11: NO | J11: https://www.bestbuy.com/site/aquasonic-rechargeable-electric-toothbrush-and-oral-irrigator-set-white/6454802.p?skuId=6454802
A12: 6500849 | B12: 810016710004 | C12: 810016714842 | D12: BBY-AS-TBSH-RG | E12: AquaSonic - Ultrasonic Rechargeable Electric Toothbrush Ultimate Bundle - Rose Gold | F12: 37.46 | G12: 49.95 | H12: YES | I12: NO | J12: https://www.bestbuy.com/site/aquasonic-vibe-series-rechargeable-electric-toothbrush-rose-gold/6500849.p?skuId=6500849
A13: 6500855 | B13: 810016710004 | C13: 810016714859 | D13: BBY-AS-TBSH-CH | E13: AquaSonic - Ultrasonic Rechargeable Electric Toothbrush Ultimate Bundle - Charcoal Metallic | F13: 37.46 | G13: 49.95 | H13: YES | I13: NO | J13: https://www.bestbuy.com/site/aquasonic-vibe-series-rechargeable-electric-toothbrush-charcoal-metallic/6500855.p?skuId=6500855#anchor=productVariations
A14: 6500856 | B14: 810016710004 | C14: 810016714866 | D14: BBY-AS-TBSH-WH | E14: AquaSonic - Ultrasonic Rechargeable Electric Toothbrush Ultimate Bundle - Optic White | F14: 37.46 | G14: 49.95 | H14: YES | I14: NO | J14: https://www.bestbuy.com/site/aquasonic-vibe-series-rechargeable-electric-toothbrush-optic-white/6500856.p?skuId=6500856#anchor=productVariations
A15: 6500876 | B15: 810016710004 | C15: 810016712961 | D15: AS-HEADC-PLS-WH | E15: AquaSonic - Activated Charcoal Pulse Replacement Brush Heads (2-Pack) - White | F15: 7.46 | G15: 9.95 | H15: YES | I15: NO | J15: https://www.bestbuy.com/site/aquasonic-activated-charcoal-replacement-brush-heads-2-pack-white/6500876.p?skuId=6500876#anchor=productVariations
A16: 6454801 | B16: 810016710004 | C16: 810016710004 | D16: AS-TBSH-PRO | E16: AQUASONIC BLACK SERIES PLUS TOOTHBRUSH | F16: 37.49 | G16: 49.95 | H16: YES | I16: NO | J16: https://www.bestbuy.com/site/aquasonic-black-series-pro-rechargeable-electric-toothbrush-black/6454801.p?skuId=6454801
A17: 6505518 | B17: 810016710004 | C17: 810016715061 | D17: BBY-PDC-NANO-5PC | E17: NanoSteamer - Large 3-in-1 Nano Ionic Facial Steamer with Bonus 5 Piece Stainless Steel Skin Kit | F17: 39.96 | G17: 49.95 | H17: YES | I17: YES | J17: https://www.bestbuy.com/site/pure-daily-care-nanosteamer-facial-steamer-white/6505518.p?skuId=6505518
A18: 6505517 | B18: 810016710004 | C18: 810016715160 | D18: BBY-PDC-LUMA-WAND | E18: Luma Skin Therapy Wand - 4-in-1 Natural Facial Skincare Treatments | F18: 63.99 | G18: 79.99 | H18: YES | I18: YES | J18: https://www.bestbuy.com/site/pure-daily-care-luma-skin-therapy-wand/6505517.p?skuId=6505517
A19: 6505524 | B19: 810016710004 | C19: 810016715153 | D19: BBY-PDC-LUMA-MSK | E19: Luma LED Skin Therapy Mask - Home Skin Rejuvenation & Anti-Aging Light Therapy - 7 Color LED - Facial Skin Care - Skin Tightening - Wrinkles and Fine Lines - Boost Collagen - Inflammation Fighter | F19: 71.96 | G19: 89.95 | H19: YES | I19: YES | J19: https://www.bestbuy.com/site/pure-daily-care-luma-light-therapy-mask/6505524.p?skuId=6505524
A20: 6500874 | B20: 810016710004 | C20: 810016712954 | D20: AS-HEADC-PLS-BK | E20: AquaSonic - Activated Charcoal Pulse Replacement Brush Heads (2-Pack) - Black | F20: 7.46 | G20: 9.95 | H20: YES | I20: YES | J20: https://www.bestbuy.com/site/aquasonic-activated-charcoal-replacement-brush-heads-2-pack-black/6500874.p?skuId=6500874#anchor=productVariations
... A24: 6454803 | B24: 810016710004 | C24: 810016710110 | D24: AS-TBSH-DUO | E24: AQUASONIC DUO ULTRA TOOTHBRUSHES | F24: 37.46 | G24: 49.95 | H24: YES | I24: YES | J24: https://www.bestbuy.com/site/aquasonic-duo-series-rechargeable-electric-toothbrush-set-white-satin-black/6454803.p?skuId=6454803
A25: 6488842 | B25: 810016710004 | C25: 810016713715 | D25: AS-TBSH-BS-HB | E25: AquaSonic Black UltraSonic ToothBrush Ultimate Bundle | F25: 37.46 | G25: 49.99 | H25: YES | I25: YES | J25: https://www.bestbuy.com/site/aquasonic-black-ultrasonic-toothbrush-ultimate-bundle-black/6488842.p?skuId=6488842 | K25: EOL on 6/21/22
A26: 6488843 | B26: 810016710004 | C26: 810016713722 | D26: AS-TBSH-DUOP-HB | E26: AquaSonic - Duo Series Pro Rechargeable Electric Toothbrush Ultimate Bundle | F26: 74.96 | G26: 99.95 | H26: YES | I26: YES | J26: https://www.bestbuy.com/site/aquasonic-ultrasonic-uv-sanitizing-toothbrush-set-limited-edition-bundle-midnight-black-optic-white/6488843.p?skuId=6488843
A27: 6500868 | B27: 810016710004 | C27: 810016712985 | D27: AS-HEADC-PRO-WH | E27: AquaSonic - Activated Charcoal Vibe, Black Series, Pro Series, Duo Pro Replacement Brush Heads (2-Pack) - White | F27: 11.2 | G27: 14.95 | H27: YES | I27: YES | J27: https://www.bestbuy.com/site/aquasonic-activated-charcoal-replacement-brush-heads-2-pack-white/6500868.p?skuId=6500868
A28: 6500870 | B28: 810016710004 | C28: 810016712732 | D28: AS-HEAD-DUOP | E28: AQUASONIC DUO PRO 8-PACK BRUSH HEADS | F28: 18.71 | G28: 24.95 | H28: YES | I28: YES | J28: https://www.bestbuy.com/site/aquasonic-proflex-replacement-brush-heads-8-pack-white-black/6500870.p?skuId=6500870
A29: 6550471 | B29: 810016710004 | C29: 810016717096 | D29: AS-ELITE-BK | E29: Aquasonic Elite Series Electric Toothbrush - Black | F29: 37.46 | G29: 49.95 | H29: YES | I29: YES | J29: https://www.bestbuy.com/site/aquasonic-elite-series-electric-toothbrush-black/6550471.p?skuId=6550471
A30: 6550475 | B30: 810016710004 | C30: 810016717102 | D30: AS-ELITE-RG | E30: Aquasonic Elite Series Electric Toothbrush - Rose Gold | F30: 37.46 | G30: 49.95 | H30: YES | I30: YES | J30: https://www.bestbuy.com/site/aquasonic-elite-series-electric-toothbrush-black/6550471.p?skuId=6550471
A31: 6550472 | B31: 810016710004 | C31: 810016717119 | D31: AS-ELITE-WH | E31: Aquasonic Elite Series Electric Toothbrush - White | F31: 37.46 | G31: 49.95 | H31: YES | I31: YES | J31: https://www.bestbuy.com/site/aquasonic-elite-series-electric-toothbrush-black/6550471.p?skuId=6550471
A32: 6550477 | B32: 810016710004 | C32: 810016717362 | D32: AS-ICON-NV | E32: Aquasonic Icon ADA-Accepted Rechargeable Toothbrush | Magnetic Holder & Slim Travel Case (Navy) | F32: 18.71 | G32: 24.95 | H32: YES | I32: YES | J32: https://www.bestbuy.com/site/aquasonic-icon-rechargeable-power-toothbrush--magnetic-holder-slim-travel-case-navy/6550477.p?skuId=6550477
A33: 6550543 | B33: 810016710004 | C33: 810016717379 | D33: AS-ICON-WH | E33: Aquasonic Icon ADA-Accepted Rechargeable Toothbrush | Magnetic Holder & Slim Travel Case (White) | F33: 18.71 | G33: 24.95 | H33: YES | I33: YES | J33: https://www.bestbuy.com/site/aquasonic-icon-rechargeable-power-toothbrush--magnetic-holder-slim-travel-case-navy/6550477.p?skuId=6550477
A34: 6550478 | B34: 810016710004 | C34: 810016717348 | D34: AS-HEAD-ICON-2NV | E34: AquaSonic Icon Navy Replacement Brush Heads - 2 Pack | F34: 7.46 | G34: 9.95 | H34: YES | I34: YES | J34: https://www.bestbuy.com/site/aquasonic-icon-replacement-brushheads-2pk-navy/6550478.p?skuId=6550478
A35: 6550474 | B35: 810016710004 | C35: 810016717355 | D35: AS-HEAD-ICON-2WH | E35: AquaSonic Icon White Replacement Brush Heads - 2 Pack | F35: 7.46 | G35: 9.95 | H35: YES | I35: YES | J35: https://www.bestbuy.com/site/aquasonic-icon-replacement-brushheads-2pk-navy/6550478.p?skuId=6550478
A36: 6550544 | B36: 810016710004 | C36: 810016718178 | D36: AS-ELITE-DUO | E36: AquaSonic Elite Duo Ultra-Whitening Toothbrush Set - Black & White | F36: 67.46 | G36: 89.95 | H36: YES | I36: YES | J36: https://www.bestbuy.com/site/aquasonic-elite-duo-series-electric-toothbrush-set-white-and-black/6550544.p?skuId=6550544
A37: 6550480 | B37: 810016710004 | C37: 810016716549 | D37: AS-HEAD-P3WH | E37: AquaSonic ProFlex White Brush Heads - 3 Pack | F37: 11.21 | G37: 14.95 | H37: YES | I37: YES | J37: https://www.bestbuy.com/site/aquasonic-proflex-brush-heads-3-pack-white/6550480.p?skuId=6550480
... A43: 6576717 | B43: 810016710004 | C43: 810016718857 | D43: AS-ELITE-FLOS-WH | E43: AquaSonic Elite Flosser - Rechargeable Water Flosser with 4 Tips, 4 Modes & Portable - White | F43: 37.46 | G43: 49.95 | H43: YES | I43: YES | J43: https://www.bestbuy.com/site/aquasonic-elite-water-flosser-white/6576717.p?skuId=6576717
A44: Pure Daily Care
A45: 6505523 | B45: 810016710004 | C45: 810016715092 | D45: BBY-PDC-NDSW-WH | E45: NuDerma Skin Wand - Portable Handheld High Frequency Skin Therapy Machine | F45: 39.96 | G45: 49.95 | H45: YES | I45: YES | J45: https://www.bestbuy.com/site/pure-daily-care-nuderma-skin-therapy-wand/6505523.p?skuId=6505523 | K45: Cost changing to 55.96, retail to 69.95 on 8/1/22
A46: 6505515 | B46: 810016710004 | C46: 810016715108 | D46: BBY-PDC-DERM-PRO | E46: NuDerma Professional Skin Therapy Wand - Portable Handheld High Frequency Skin Therapy Machine with 6 Neon & Argon Wands - Acne Treatment - Skin Tightening - Wrinkle Reducing – Facial Skin Lifter | F46: 63.96 | G46: 79.95 | H46: NO | I46: YES | J46: https://www.bestbuy.com/site/pure-daily-care-nuderma-professional-skin-therapy-wand/6505515.p?skuId=6505515 | K46: Cost change to 71.96, retail to 89.95 on 8/1/22
A47: 6505516 | B47: 810016710004 | C47: 810016715139 | D47: BBY-PDC-RNEW-WH | E47: ReNew Skin Scrubber | F47: 23.96 | G47: 29.95 | H47: YES | I47: YES | J47: https://www.bestbuy.com/site/pure-daily-care-renew-skin-scrubber-white/6505516.p?skuId=6505516
A48: 6505521 | B48: 810016710004 | C48: 810016715146 | D48: BBY-PDC-DERM-CLNC | E48: NuDerma Clinical Skin Therapy Wand - Portable Handheld High Frequency Skin Therapy Machine w 6 FUSION Neon + Argon Wands - Natural Acne Treatment - Skin Tightening - Wrinkle Reducing - Facial Skin | F48: 95.96 | G48: 119.95 | H48: YES | I48: YES | J48: https://www.bestbuy.com/site/pure-daily-care-nuderma-clinical-skin-therapy-wand/6505521.p?skuId=6505521 | K48: Cost change to 119.96, retail to $149.95 on 8/1/22
...

Sheet Core Shipments
A1: BBY | B1: BBY SKU | C1: UPC | D1: MFG | E1: Title | F1: 44834 | G1: 44858 | H1: 44872 | I1: 44879 | J1: 44886 | K1: 44893 | L1: 44900 | M1: 44907 | N1: 44914 | O1: 44921 | P1: 44928 | Q1: 44935 | R1: 44949 | S1: 44963 | T1: 44970 | U1: 44977 | V1: 44991 | W1: 45005 | X1: 45019 | Y1: 45033 | Z1: 45047 | AA1: 45061 | AB1: 45075 | AC1: 45089 | AD1: 45103 | AE1: 45117 | AF1: 45131 | AG1: 45145 | AH1: 45159 | AI1: 45173 | AJ1: 45187 | AK1: 45201 | AL1: 45215 | AM1: 45229 | AN1: 45235 | AO1: 45243 | AP1: 45257 | AQ1: 45271 | AR1: 45285 | AS1: 45299 | AT1: 45313 | AU1: 45327 | AV1: 45341 | AW1: 45355 | AX1: 45369 | AY1: 45383 | AZ1: 45397 | BA1: 45411 | BB1: 45425 | BC1: 45439 | BD1: 45453 | BE1: 45460 | BF1: 45467 | BG1: 45481 | BH1: 45495 | BI1: 45509 | BJ1: 45523 | BK1: 45537 | BL1: 45551 | BM1: 45565 | BN1: 45579 | BO1: 45593 | BP1: 45607 | BQ1: 45621 | BR1: 45635 | BS1: 45649 | BT1: 45663 | BU1: 45677 | BV1: 45691 | BW1: 45705 | BX1: 45719 | BY1: 45733 | BZ1: 45747 | CA1: 45761 | CB1: 45775 | CC1: 45789 | CD1: 45803 | CE1: 45817 | CF1: 45831 | CG1: 45845 | CH1: 45859 | CI1: 45873 | CJ1: 45887 | CL1: BBY COST | CM1: Units | CN1: Total Sales
A2: 6488842 | B2: 6488842 | C2: 810016713715 | D2: AS-TBSH-BS-HB | E2: AquaSonic Black UltraSonic ToothBrush Ultimate Bundle | F2: 1020 | G2: 168 | H2: 396 | I2: 384 | J2: 864 | K2: 24 | L2: 12 | M2: 60 | N2: 12 | O2: 492 | P2: 36 | Q2: 612 | R2: 216 | S2: 576 | T2: 216 | U2: 324 | V2: 588 | W2: 744 | X2: 12 | Y2: 144 | Z2: 312 | AA2: 0 | AB2: 0 | AC2: 444 | AD2: 0 | AE2: 0 | AF2: 0 | AG2: 0 | AH2: 0 | AI2: 0 | AJ2: 0 | AK2: 0 | AL2: 0 | AM2: 0 | AN2: 0 | AO2: 0 | AP2: 0 | AQ2: 0 | AR2: 0 | AS2: 0 | AT2: 0 | AU2: 0 | CL2: 37.46 | CM2: =SUM(F2:CJ2) -> 7656 | CN2: =CL2*CM2 -> 286793.76
A3: 6488843 | B3: 6488843 | C3: 810016713722 | D3: AS-TBSH-DUOP-HB | E3: AquaSonic - Duo Series Pro Rechargeable Electric Toothbrush Ultimate Bundle | F3: 1008 | G3: 240 | H3: 112 | I3: 16 | J3: 248 | K3: 160 | L3: 248 | M3: 112 | N3: 176 | O3: 184 | P3: 72 | Q3: 520 | R3: 256 | S3: 112 | T3: 64 | U3: 384 | V3: 24 | W3: 320 | X3: 48 | Y3: 56 | Z3: 408 | AA3: 254 | AB3: 328 | AC3: 104 | AD3: 168 | AE3: 0 | AF3: 0 | AG3: 0 | AH3: 0 | AI3: 0 | AJ3: 0 | AK3: 0 | AL3: 0 | AM3: 0 | AN3: 0 | AO3: 0 | AP3: 0 | AQ3: 0 | AR3: 0 | AS3: 0 | AT3: 0 | AU3: 0 | CL3: 74.96 | CM3: =SUM(F3:CJ3) -> 5622 | CN3: =CL3*CM3 -> 421425.12
B4: 6488843 | C4: 810016713722 | D4: AS-TBSH-DUOP-HB | E4: AquaSonic - Duo Series Pro Rechargeable Electric Toothbrush Ultimate Bundle _ SPECIAL COST | F4: 0 | G4: 0 | H4: 0 | I4: 0 | J4: 0 | K4: 0 | L4: 0 | M4: 0 | N4: 0 | O4: 0 | P4: 0 | Q4: 0 | R4: 0 | S4: 0 | T4: 0 | U4: 0 | V4: 0 | W4: 0 | X4: 0 | Y4: 0 | Z4: 0 | AA4: 0 | AB4: 0 | AC4: 0 | AD4: 0 | AE4: 0 | AF4: 0 | AG4: 0 | AH4: 0 | AI4: 0 | AJ4: 1000 | AK4: 0 | AL4: 0 | AM4: 0 | AN4: 0 | AO4: 0 | AP4: 0 | AQ4: 0 | AR4: 0 | AS4: 0 | AT4: 0 | AU4: 0 | CL4: 60.16 | CM4: =SUM(F4:CJ4) -> 1000 | CN4: =CL4*CM4 -> 60160
B5: 6550471 | C5: 810016717096 | D5: AS-ELITE-BK | E5: Aquasonic Elite Series Electric Toothbrush - Black | F5: 0 | G5: 0 | H5: 0 | I5: 0 | J5: 0 | K5: 0 | L5: 0 | M5: 0 | N5: 0 | O5: 0 | P5: 0 | Q5: 0 | R5: 0 | S5: 0 | T5: 0 | U5: 0 | V5: 0 | W5: 0 | X5: 0 | Y5: 0 | Z5: 0 | AA5: 0 | AB5: 0 | AC5: 0 | AD5: 0 | AE5: 0 | AF5: 0 | AG5: 0 | AH5: 0 | AI5: 1344 | AJ5: 0 | AK5: 0 | AL5: 0 | AM5: 0 | AO5: 1200 | AP5: 36 | AQ5: 0 | AR5: 0 | AS5: 0 | AT5: 0 | AU5: 1440 | AV5: 468 | AW5: 372 | AX5: 456 | AY5: 468 | AZ5: 216 | BA5: 468 | BB5: 96 | BC5: 0 | BD5: 120 | BF5: 720 | BG5: 492 | BH5: 168 | BI5: 288 | BJ5: 804 | BK5: 764 | BL5: 0 | BM5: 720 | BN5: 1692 | BO5: 0 | BP5: 192 | BQ5: 612 | BR5: 708 | BS5: 384 | BT5: 0 | BU5: 1236 | BV5: 252 | BW5: 228 | BX5: 348 | BY5: 60 | BZ5: 0 | CA5: 108 | CB5: 492 | CC5: 324 | CD5: 0 | CE5: 504 | CF5: 444 | CG5: 252 | CH5: 24 | CL5: 37.46 | CM5: =SUM(F5:CJ5) -> 18500 | CN5: =CL5*CM5 -> 693010
B6: 6550544 | C6: 810016718178 | D6: AS-ELITE-DUO | E6: AquaSonic Elite Duo Series Electric Toothbrush Set | F6: 0 | G6: 0 | H6: 0 | I6: 0 | J6: 0 | K6: 0 | L6: 0 | M6: 0 | N6: 0 | O6: 0 | P6: 0 | Q6: 0 | R6: 0 | S6: 0 | T6: 0 | U6: 0 | V6: 0 | W6: 0 | X6: 0 | Y6: 0 | Z6: 0 | AA6: 0 | AB6: 0 | AC6: 0 | AD6: 0 | AE6: 0 | AF6: 0 | AG6: 0 | AH6: 0 | AI6: 0 | AJ6: 0 | AK6: 0 | AL6: 0 | AM6: 0 | AN6: 2190 | AO6: 312 | AP6: 396 | AQ6: 0 | AR6: 0 | AS6: 150 | AT6: 0 | AU6: 576 | AV6: 222 | AW6: 234 | AX6: 48 | AY6: 270 | AZ6: 150 | BA6: 348 | BB6: 366 | BC6: 48 | BD6: 0 | BF6: 336 | BG6: 570 | BH6: 96 | BI6: 294 | BJ6: 366 | BK6: 120 | BL6: 330 | BM6: 420 | BN6: 498 | BO6: 0 | BP6: 726 | BQ6: 1134 | BR6: 720 | BS6: 192 | BT6: 0 | BU6: 120 | BV6: 162 | BW6: 234 | BX6: 180 | BY6: 414 | BZ6: 0 | CA6: 108 | CB6: 72 | CC6: 294 | CD6: 0 | CE6: 0 | CF6: 0 | CG6: 588 | CH6: 66 | CL6: 67.46 | CM6: =SUM(F6:CJ6) -> 13350 | CN6: =CL6*CM6 -> 900591
B7: 6550477 | C7: 810016717362 | D7: AS-ICON-NV | E7: Aquasonic Icon ADA-Accepted Rechargeable Toothbrush (Navy) | F7: Aquasonic Icon ADA-Accepted Rechargeable Toothbrush | Magnetic Holder & Slim Travel Case (Navy) | BE7: 2100 | BI7: 360 | BJ7: 210 | BK7: 0 | BL7: 90 | BM7: 210 | BN7: 510 | BO7: 90 | BP7: 330 | BQ7: 660 | BR7: 390 | BS7: 90 | BT7: 0 | BU7: 0 | BV7: 0 | BW7: 810 | BX7: 210 | BY7: 120 | BZ7: 0 | CA7: 0 | CB7: 30 | CC7: 30 | CD7: 0 | CE7: 0 | CF7: 270 | CG7: 0 | CH7: 300 | CL7: 14.99 | CM7: =SUM(F7:CJ7) -> 6810 | CN7: =CL7*CM7 -> 102081.9
B8: 6552876 | C8: 810016718123 | D8: AS-ELITE-FLOS-BK | E8: AquaSonic Elite Flosser - Black | BE8: 2040 | BH8: 240 | BI8: 996 | BJ8: 936 | BK8: 420 | BL8: 1308 | BM8: 432 | BN8: 2364 | BO8: 240 | BP8: 1788 | BQ8: 1512 | BR8: 1320 | BS8: 492 | BT8: 0 | BU8: 2100 | BV8: 552 | BW8: 432 | BX8: 540 | BY8: 0 | BZ8: 624 | CA8: 564 | CB8: 588 | CC8: 252 | CD8: 72 | CE8: 132 | CF8: 336 | CG8: 240 | CH8: 276 | CL8: 37.46 | CM8: =SUM(F8:CJ8) -> 20796 | CN8: =CL8*CM8 -> 779018.16
B9: 6576717 | C9: 810016718857 | D9: AS-ELITE-FLOS-WH | E9: AquaSonic Elite Flosser - White | BY9: 1812 | BZ9: 0 | CA9: 0 | CB9: 948 | CC9: 372 | CD9: 0 | CE9: 0 | CF9: 0 | CG9: 0 | CH9: 36 | CL9: 37.46 | CM9: =SUM(F9:CJ9) -> 3168 | CN9: =CL9*CM9 -> 118673.28
F10: =SUM(F2:F8) -> 2028 | G10: =SUM(G2:G8) -> 408 | H10: =SUM(H2:H8) -> 508 | I10: =SUM(I2:I8) -> 400 | J10: =SUM(J2:J8) -> 1112 | K10: =SUM(K2:K8) -> 184 | L10: =SUM(L2:L8) -> 260 | M10: =SUM(M2:M8) -> 172 | ... BV10: =SUM(BV2:BV8) -> 966 | BW10: =SUM(BW2:BW9) -> 1704 | BX10: =SUM(BX2:BX9) -> 1278 | BY10: =SUM(BY2:BY9) -> 2406 | BZ10: =SUM(BZ2:BZ9) -> 624 | CA10: =SUM(CA2:CA9) -> 780 | CB10: =SUM(CB2:CB9) -> 2130 | CC10: =SUM(CC2:CC9) -> 1272 | CD10: =SUM(CD2:CD9) -> 72 | ... CJ10: =SUM(CJ2:CJ9) -> 0 | CM10: =SUM(CM2:CM8) -> 73734 | CN10: =SUM(CN2:CN8) -> 3243079.9
F22: `

Sheet Sales TOTAL
A1: BBY SKU | B1: UPC | C1: SDF Sell Thru (Online) | D1: Title | E1: 44275 | F1: 44282 | G1: 44289 | H1: 44296 | I1: 44303 | J1: 44310 | K1: 44317 | L1: 44324 | M1: 44331 | N1: 44338 | O1: 44345 | P1: 44352 | Q1: 44359 | R1: 44366 | S1: 44373 | T1: 44380 | U1: 44387 | V1: 44394 | W1: 44401 | X1: 44408 | Y1: 44415 | Z1: 44422 | AA1: 44429 | AB1: 44436 | AC1: 44443 | AD1: 44450 | AE1: 44457 | AF1: 44464 | AG1: 44471 | AH1: 44478 | AI1: 44485 | AJ1: 44492 | AK1: 44499 | AL1: 44506 | AM1: 44513 | AN1: 44520 | AO1: 44527 | AP1: 44534 | AQ1: 44541 | AR1: 44548 | AS1: 44555 | AT1: 44562 | AU1: 44569 | AV1: 44576 | AW1: 44583 | AX1: 44590 | AY1: 44597 | AZ1: 44604 | BA1: 44611 | BB1: 44618 | BC1: 44625 | BD1: 44632 | BE1: 44639 | BF1: 44646 | BG1: 44653 | BH1: 44660 | BI1: 44667 | BJ1: 44674 | BK1: 44681 | BL1: 44688 | BM1: 44695 | BN1: 44702 | BO1: 44709 | BP1: 44716 | BQ1: 44723 | BR1: 44730 | BS1: 44737 | BT1: 44744 | BU1: 44751 | BV1: 44758 | BW1: 44765 | BX1: 44772 | BY1: 44779 | BZ1: 44786 | CA1: 44793 | CB1: 44800 | CC1: 44807 | CD1: 44814 | CE1: 44821 | CF1: 44828 | CG1: 44835 | CH1: 44842 | CI1: 44849 | CJ1: 44856 | CK1: 44863 | CL1: 44870 | CM1: 44877 | CN1: 44884 | CO1: 44891 | CP1: 44898 | CQ1: 44905 | CR1: 44912 | CS1: 44919 | CT1: 44926 | CU1: 44933 | CV1: 44940 | CW1: 44947 | CX1: 44954 | CY1: 44961 | CZ1: 44968 | DA1: 44975 | DB1: 44982 | DC1: 44989 | DD1: 44996 | DE1: 45003 | DF1: 45010 | DG1: 45017 | DH1: 45024 | DI1: 45031 | DJ1: 45038 | DK1: 45045 | DL1: 45052 | DM1: 45059 | DN1: 45066 | DO1: 45073 | DP1: 45080 | DQ1: 45087 | DR1: 45094 | DS1: 45101 | DT1: 45108 | DU1: 45115 | DV1: 45122 | DW1: 45129 | DX1: 45136 | DY1: 45143 | DZ1: 45150 | EA1: 45157 | EB1: 45164 | EC1: 45171 | ED1: 45178 | EE1: 45185 | EF1: 45192 | EG1: 45199 | EH1: 45206 | EI1: 45213 | EJ1: 45220 | EK1: 45227 | EL1: 45234 | EM1: 45241 | EN1: 45248 | EO1: 45255 | EP1: 45262 | EQ1: 45269 | ER1: 45276 | ES1: 45283 | ET1: 45290 | EU1: 45297 | EV1: 45304 | EW1: 45311 | EX1: 45318 | EY1: 45325 | EZ1: 45332 | FA1: 45339 | FB1: 45346 | FC1: 45353 | FD1: 45360 | FE1: 45367 | FF1: 45374 | FG1: 45381 | FH1: 45388 | FI1: 45395 | FJ1: 45402 | FK1: 45409 | FL1: 45416 | FM1: 45423 | FN1: 45430 | FO1: 45437 | FP1: 45444 | FQ1: 45451 | FR1: 45458 | FS1: 45465 | FT1: 45472 | FU1: 45479 | FV1: 45486 | FW1: 45493 | FX1: 45500 | FY1: 45507 | FZ1: 45514 | GA1: 45521 | GB1: 45528 | GC1: 45535 | GD1: 45542 | GE1: 45549 | GF1: 45556 | GG1: 45563 | GH1: 45570 | GI1: 45577 | GJ1: 45584 | GK1: 45591 | GL1: 45598 | GM1: 45605 | GN1: 45612 | GO1: 45619 | GP1: 45626 | GQ1: 45633 | GR1: 45640 | GS1: 45647 | GT1: 45654 | GU1: 45661 | GV1: 45668 | GW1: 45675 | GX1: 45682 | GY1: 45689 | GZ1: 45696 | HA1: 45703 | HB1: 45710 | HC1: 45717 | HD1: 45724 | HE1: 45731 | HF1: 45738 | HG1: 45745 | HH1: 45752 | HI1: 45759 | HJ1: 45766 | HK1: 45773 | HL1: 45780 | HM1: 45787 | HN1: 45794 | HO1: 45801 | HP1: 45808 | HQ1: 45815 | HR1: 45822 | HS1: 45829 | HT1: 45836 | HU1: 45843 | HV1: 45850 | HW1: 45857 | HX1: 45864 | IW1: Units | IX1: BBY Cost | IY1: Sales at Cost | IZ1: MSRP | JA1: Sales at MSRP
A2: 6454800 | B2: 810016711094 | C2: AS-TBSH-DUOP | D2: AQUASONIC DUO PRO ULTRA TOOTHBRUSHES | E2: 1 | F2: 5 | G2: 13 | H2: 8 | I2: 8 | J2: 9 | K2: 2 | L2: 6 | M2: 231 | N2: 56 | O2: 5 | P2: 6 | Q2: 4 | R2: 3 | S2: 4 | T2: 6 | U2: 7 | V2: 2 | W2: 3 | X2: 6 | Y2: 10 | Z2: 10 | AA2: 6 | AH2: 5 | AI2: 3 | AJ2: 10 | AK2: 4 | AL2: 12 | AM2: 12 | IW2: =SUM(E2:HX2) -> 457 | IX2: 59.96 | IY2: =IW2*IX2 -> 27401.72 | IZ2: 79.95 | JA2: =IW2*IZ2 -> 36537.15
A3: 6454799 | B3: 810016710387 | C3: AS-FLOS-REG | D3: AQUA FLOSSER RCHRGBLE ORAL IRRIGATOR | E3: 2 | F3: 2 | G3: 3 | H3: 8 | I3: 6 | K3: 3 | L3: 9 | M3: 14 | N3: 8 | O3: 7 | P3: 10 | Q3: 2 | R3: 4 | S3: 2 | T3: 3 | U3: 6 | V3: 1 | W3: 3 | X3: 2 | Y3: 4 | Z3: 3 | AA3: 5 | AB3: 3 | AC3: 3 | AD3: 5 | AE3: 5 | AF3: 3 | AG3: 1 | AH3: 8 | AI3: 4 | AJ3: 1 | AK3: 6 | AL3: 6 | AM3: 2 | AN3: 2 | AO3: 7 | AP3: 10 | AQ3: 16 | AR3: 8 | AS3: 8 | AT3: 4 | AU3: 3 | BI3: 7 | BJ3: 2 | BK3: 4 | BL3: 6 | BM3: 2 | BN3: 4 | BO3: 6 | BP3: 3 | BQ3: 6 | BR3: 2 | BS3: 1 | BT3: 1 | BU3: 6 | BV3: 4 | BW3: 5 | BX3: 4 | BY3: 3 | BZ3: 4 | CA3: 3 | CB3: 6 | CC3: 8 | CD3: 4 | CE3: 5 | CF3: 4 | CG3: 9 | CH3: 2 | CI3: 14 | CJ3: 7 | CK3: 7 | CL3: 1 | CM3: 5 | CN3: 5 | CO3: 1 | CQ3: 10 | CR3: 33 | CS3: 28 | CT3: 9 | CU3: 17 | CV3: 20 | CW3: 15 | IW3: =SUM(E3:HX3) -> 495 | IX3: 29.99 | IY3: =IW3*IX3 -> 14845.05 | IZ3: 39.95 | JA3: =IW3*IZ3 -> 19775.25
A4: 6454802 | B4: 810016710240 | C4: AS-HDSC-SET | D4: COMPLETE FAMILY ORAL CARE | E4: 2 | F4: 1 | G4: 10 | H4: 16 | I4: 19 | J4: 11 | K4: 6 | L4: 16 | M4: 13 | N4: 26 | O4: 32 | P4: 18 | Q4: 13 | R4: 5 | S4: 13 | T4: 17 | U4: 5 | V4: 8 | W4: 6 | X4: 8 | Y4: 7 | Z4: 7 | AA4: 8 | AB4: 8 | AC4: 9 | AD4: 11 | AE4: 7 | AF4: 7 | AG4: 12 | AH4: 8 | AI4: 4 | AJ4: 7 | AK4: 5 | AL4: 7 | AN4: 2 | AO4: 18 | AP4: 22 | AY4: 1 | AZ4: 4 | BE4: 1 | BF4: 5 | BG4: 4 | BH4: 7 | BI4: 5 | BJ4: 4 | BK4: 1 | CH4: 4 | CI4: 3 | CJ4: 3 | CK4: 10 | CL4: 9 | CM4: 13 | CN4: 24 | CO4: 17 | CP4: 39 | CQ4: 47 | CR4: 10 | DB4: 3 | DC4: 10 | DD4: 2 | DE4: 4 | DF4: 5 | DG4: 7 | DH4: 4 | DI4: 7 | DJ4: 9 | DK4: 3 | DL4: 11 | DM4: 11 | DN4: 10 | DO4: 10 | DP4: 1 | DQ4: 3 | DR4: 12 | DS4: 9 | DT4: 8 | DU4: 9 | DV4: 8 | IW4: =SUM(E4:HX4) -> 751 | IX4: 37.46 | IY4: =IW4*IX4 -> 28132.46 | IZ4: 49.95 | JA4: =IW4*IZ4 -> 37512.45
A5: 6454807 | B5: 810016710196 | C5: AS-FLOS-PRO | D5: AQUASONIC AQUA FLOSSER PRO | S5: 2 | T5: 1 | U5: 3 | V5: 1 | Z5: 2 | AA5: 1 | AD5: 1 | AE5: 2 | AF5: 2 | AI5: 1 | AJ5: 16 | AN5: 2 | AP5: 1 | AR5: 7 | AS5: 1 | AV5: 4 | AW5: 3 | AX5: 5 | AZ5: 2 | BA5: 3 | BB5: 1 | BC5: 1 | BI5: 1 | BK5: 2 | BM5: 1 | IW5: =SUM(E5:HX5) -> 66 | IX5: 37.49 | IY5: =IW5*IX5 -> 2474.34 | IZ5: 49.95 | JA5: =IW5*IZ5 -> 3296.7
A6: 6454806 | B6: 810016710127 | C6: AS-TBSH-BS | D6: AQUASONIC BLACK ULTRA SONIC TOOTHBRUSH | E6: 5 | F6: 7 | G6: 14 | H6: 30 | I6: 257 | J6: 21 | K6: 8 | L6: 9 | M6: 18 | N6: 23 | O6: 19 | P6: 8 | Q6: 3 | S6: 14 | T6: 34 | U6: 13 | V6: 12 | W6: 12 | X6: 1 | Y6: 10 | Z6: 207 | AA6: 235 | AB6: 17 | AC6: 24 | AD6: 10 | AG6: 5 | AH6: 18 | AI6: 14 | AK6: 23 | AL6: 26 | AM6: 14 | IW6: =SUM(E6:HX6) -> 1111 | IX6: 27.71 | IY6: =IW6*IX6 -> 30785.81 | IZ6: 36.95 | JA6: =IW6*IZ6 -> 41051.45
A7: 6454803 | B7: 810016710110 | C7: AS-TBSH-DUO | D7: AQUASONIC DUO ULTRA TOOTHBRUSHES | E7: 1 | F7: 2 | G7: 1 | H7: 3 | I7: 12 | J7: 4 | K7: 4 | L7: 3 | M7: 8 | N7: 3 | O7: 4 | P7: 2 | Q7: 1 | R7: 1 | S7: 8 | T7: 10 | U7: 4 | V7: 2 | W7: 2 | X7: 3 | Y7: 19 | Z7: 12 | AA7: 8 | AG7: 2 | AH7: 6 | AI7: 8 | AJ7: 8 | AK7: 3 | AL7: 11 | AM7: 12 | AN7: 26 | AO7: 47 | AP7: 52 | AQ7: 49 | AR7: 60 | AS7: 20 | AT7: 26 | AU7: 22 | AV7: 30 | AW7: 12 | AY7: 1 | AZ7: 9 | BA7: 3 | BB7: 11 | BC7: 3 | BD7: 4 | BE7: 19 | BF7: 14 | BG7: 7 | BH7: 8 | BI7: 13 | BJ7: 6 | BK7: 9 | BL7: 12 | BM7: 11 | BN7: 20 | BO7: 10 | BP7: 23 | BQ7: 14 | BR7: 9 | BS7: 11 | BT7: 15 | BU7: 6 | BV7: 5 | BX7: 11 | BY7: 2 | BZ7: 7 | CA7: 13 | CB7: 20 | CC7: 8 | CD7: 16 | CE7: 14 | CF7: 19 | CG7: 17 | CH7: 29 | CI7: 40 | CJ7: 7 | CK7: 26 | CL7: 16 | CM7: 24 | CN7: 21 | CO7: 15 | CP7: 25 | CQ7: 29 | CR7: 65 | CS7: 74 | CT7: 27 | CU7: 17 | CV7: 15 | CW7: 21 | CX7: 39 | CY7: 27 | DC7: 8 | DD7: 17 | DE7: 9 | DF7: 21 | DG7: 11 | DH7: 15 | DI7: 8 | DJ7: 14 | DK7: 13 | DL7: 12 | DM7: 10 | DN7: 16 | DO7: 16 | DP7: 13 | DQ7: 2 | DR7: 4 | DS7: 17 | DT7: 3 | DU7: 7 | DV7: 17 | DW7: 17 | DX7: 12 | DY7: 9 | DZ7: 12 | EA7: 17 | EB7: 4 | EC7: 12 | ED7: 12 | EE7: 5 | EF7: 11 | EG7: 13 | EH7: 12 | EI7: 8 | EJ7: 7 | EK7: 14 | EL7: 10 | EM7: 5 | IW7: =SUM(E7:HX7) -> 1811 | IX7: 37.46 | IY7: =IW7*IX7 -> 67840.06 | IZ7: 49.95 | JA7: =IW7*IZ7 -> 90459.45
A8: 6454805 | B8: 810016710066 | C8: AS-TBSH-CH | D8: AQUASONIC VIBE ULTRA TOOTHBRUSH CHARCL | F8: 1 | G8: 2 | H8: 14 | I8: 258 | J8: 79 | K8: 7 | L8: 7 | M8: 11 | N8: 13 | O8: 6 | P8: 8 | Q8: 4 | R8: 2 | S8: 10 | T8: 7 | U8: 9 | V8: 6 | W8: 3 | X8: 7 | Y8: 1 | AA8: 1 | AZ8: 8 | BA8: 2 | BB8: 5 | IW8: =SUM(E8:HX8) -> 471 | IX8: 27.71 | IY8: =IW8*IX8 -> 13051.41 | IZ8: 36.95 | JA8: =IW8*IZ8 -> 17403.45
A9: 6454808 | B9: 810016710059 | C9: AS-TBSH-RG | D9: AQUASONIC VIBE ULTRA TOOTHBRUSH-RSGLD | G9: 2 | H9: 94 | I9: 156 | J9: 26 | K9: 4 | L9: 5 | M9: 6 | N9: 9 | O9: 11 | P9: 16 | Q9: 10 | R9: 3 | S9: 10 | T9: 8 | U9: 5 | V9: 10 | W9: 8 | X9: 12 | Y9: 12 | Z9: 13 | AA9: 19 | AB9: 16 | AN9: 11 | AO9: 28 | AP9: 40 | AQ9: 42 | AR9: 50 | AS9: 39 | AT9: 17 | AY9: 4 | AZ9: 14 | BA9: 22 | BB9: 6 | BG9: 2 | BP9: 5 | DC9: 5 | IW9: =SUM(E9:HX9) -> 740 | IX9: 27.71 | IY9: =IW9*IX9 -> 20505.4 | IZ9: 36.95 | JA9: =IW9*IZ9 -> 27343
A10: 6454798 | B10: 810016710042 | C10: AS-TBSH-WH | D10: AQUASONIC VIBE ULTRA TOOTHBRUSH-WHITE | E10: 2 | H10: 7 | I10: 40 | J10: 212 | K10: 6 | L10: 4 | N10: 1 | O10: 1 | V10: 5 | W10: 2 | X10: 5 | Y10: 4 | Z10: 2 | AA10: 4 | AB10: 10 | AC10: 10 | AD10: 13 | AE10: 16 | AF10: 3 | AZ10: 1 | BB10: 4 | BO10: 2 | BP10: 1 | IW10: =SUM(E10:HX10) -> 355 | IX10: 27.71 | IY10: =IW10*IX10 -> 9837.05 | IZ10: 36.95 | JA10: =IW10*IZ10 -> 13117.25
A11: 6454801 | B11: 810016710004 | C11: AS-TBSH-PLUS | D11: AQUASONIC BLACK SERIES PLUS TOOTHBRUSH | F11: 2 | G11: 2 | H11: 6 | I11: 256 | J11: 11 | K11: 6 | L11: 9 | M11: 16 | N11: 5 | O11: 17 | P11: 12 | Q11: 12 | R11: 9 | S11: 81 | T11: 45 | U11: 13 | V11: 13 | W11: 12 | X11: 12 | Y11: 15 | Z11: 15 | AA11: 14 | AB11: 17 | AC11: 15 | AD11: 10 | AZ11: 8 | BA11: 1 | BN11: 4 | BO11: 3 | BP11: 3 | BQ11: 1 | BR11: 6 | BS11: 6 | BT11: 3 | BU11: 3 | BV11: 8 | BW11: 13 | CA11: 4 | CB11: 5 | CC11: 5 | CD11: 3 | CE11: 6 | CF11: 3 | CG11: 7 | CH11: 9 | CI11: 5 | CJ11: 6 | CK11: 12 | CL11: 7 | CM11: 6 | CN11: 9 | CO11: 6 | CP11: 16 | CQ11: 4 | CR11: 23 | CS11: 4 | CT11: 5 | CU11: 5 | CV11: 5 | CW11: 5 | CX11: 12 | CY11: 11 | CZ11: 7 | DA11: 8 | DB11: 15 | DC11: 13 | DD11: 6 | DE11: 3 | DF11: 7 | DG11: 3 | DH11: 7 | DI11: 1 | DJ11: 4 | DK11: 6 | DL11: 2 | DM11: 169 | DN11: 6 | DO11: 3 | IW11: =SUM(E11:HX11) -> 1127 | IX11: 37.49 | IY11: =IW11*IX11 -> 42251.23 | IZ11: 49.95 | JA11: =IW11*IZ11 -> 56293.65
C12: AS-TBSH-BS-HB | D12: AquaSonic Black UltraSonic ToothBrush Ultimate Bundle | AN12: 18 | AO12: 28 | AP12: 38 | AQ12: 39 | AR12: 61 | AS12: 46 | AT12: 52 | AU12: 37 | AV12: 24 | AW12: 10 | AX12: 19 | AY12: 11 | AZ12: 29 | BA12: 312 | BB12: 14 | BC12: 24 | BD12: 24 | BE12: 331 | BG12: 8 | BH12: 27 | BI12: 29 | BJ12: 10 | BK12: 7 | BL12: 267 | BM12: 116 | BN12: 26 | BO12: 1 | BP12: 334 | BQ12: 36 | BR12: 19 | BS12: 10 | BT12: 12 | BU12: 29 | BV12: 26 | BW12: 20 | BX12: 15 | BY12: 45 | BZ12: 23 | CA12: 9 | CB12: 232 | CC12: 82 | CD12: 31 | CE12: 11 | CF12: 10 | CG12: 10 | CH12: Moved to Core | IW12: =SUM(E12:HX12) -> 2562 | IX12: 37.46 | IY12: =IW12*IX12 -> 95972.52 | IZ12: 49.95 | JA12: =IW12*IZ12 -> 127971.9
C13: AS-TBSH-DUOP-HB | D13: AquaSonic - Duo Series Pro Rechargeable Electric Toothbrush Ultimate Bundle | AN13: 5 | AO13: 23 | AP13: 19 | AQ13: 28 | AR13: 42 | AS13: 43 | AT13: 486 | AU13: 15 | AV13: 14 | AW13: 48 | AX13: 459 | AY13: 30 | AZ13: 14 | BA13: 10 | BB13: 38 | BC13: 14 | BD13: 10 | BE13: 15 | BF13: 33 | BG13: 16 | BH13: 12 | BI13: 306 | BJ13: 23 | BK13: 23 | BL13: 20 | BM13: 10 | BN13: 307 | BO13: 34 | BP13: 31 | BQ13: 10 | BR13: 8 | BS13: 10 | BT13: 112 | BU13: 10 | BV13: 111 | BW13: 18 | BX13: 31 | BY13: 19 | BZ13: 16 | CA13: 240 | CB13: 25 | CC13: 14 | CD13: 285 | CE13: 11 | CF13: 8 | CG13: 12 | CH13: Moved to Core | ED13: 4 | IW13: =SUM(E13:HX13) -> 3072 | IX13: 74.96 | IY13: =IW13*IX13 -> 230277.12 | IZ13: 99.95 | JA13: =IW13*IZ13 -> 307046.4
C14: BBY-AS-TBSH-RG | D14: AquaSonic - Ultrasonic Rechargeable Electric Toothbrush Ultimate Bundle - Rose Gold | E14: V+VLOOKUP(B82,'[AQUASONIC_SV-CORE_CPFR_EXTRACT_SV_1234_20250929115416.xlsx]Sheet3'!$A:$K,11,False) | BE14: 2 | BF14: 8 | BG14: 5 | BI14: 83 | BJ14: 4 | BK14: 10 | BL14: 2 | BM14: 15 | BN14: 2 | BO14: 5 | BQ14: 5 | BR14: 3 | BS14: 3 | BT14: 2 | BU14: 4 | BV14: 2 | BX14: 4 | BY14: 7 | BZ14: 6 | CA14: 4 | CB14: 10 | CC14: 4 | CD14: 6 | CE14: 2 | CF14: 2 | CG14: 2 | CH14: 2 | CI14: 6 | CJ14: 7 | CL14: 15 | CM14: 6 | CN14: 8 | CO14: 5 | CP14: 29 | CQ14: 20 | CR14: 39 | CS14: 58 | CT14: 11 | CU14: 10 | CV14: 7 | CW14: 9 | CX14: 15 | CY14: 6 | CZ14: 16 | DA14: 16 | DB14: 23 | DD14: 5 | DE14: 9 | DF14: 5 | DG14: 3 | DH14: 2 | DI14: 7 | DJ14: 5 | DK14: 2 | DL14: 2 | DM14: 3 | DN14: 5 | DO14: 3 | DP14: 4 | DQ14: 4 | DR14: 4 | DS14: 7 | DT14: 2 | DU14: 2 | DV14: 4 | DW14: 7 | DX14: 10 | DY14: 6 | DZ14: 3 | EC14: 7 | IW14: =SUM(E14:HX14) -> 621 | IX14: 37.46 | IY14: =IW14*IX14 -> 23262.66 | IZ14: 49.95 | JA14: =IW14*IZ14 -> 31018.95
C15: BBY-AS-TBSH-CH | D15: AquaSonic - Ultrasonic Rechargeable Electric Toothbrush Ultimate Bundle - Charcoal Metallic | BE15: 4 | BF15: 6 | BG15: 5 | BH15: 12 | BI15: 98 | BJ15: 4 | BK15: 1 | BL15: 3 | BM15: 6 | BN15: 4 | BP15: 3 | BQ15: 12 | BR15: 2 | BT15: 2 | BU15: 2 | BV15: 2 | BW15: 3 | BX15: 3 | BY15: 1 | BZ15: 4 | CA15: 2 | CB15: 7 | CD15: 4 | CE15: 5 | CF15: 7 | CG15: 1 | CH15: 4 | CI15: 5 | CJ15: 7 | CK15: 4 | CN15: 2 | CO15: 3 | CP15: 13 | CQ15: 13 | CR15: 17 | CU15: 1 | CV15: 25 | CW15: 6 | CX15: 11 | CY15: 3 | CZ15: 2 | DA15: 6 | DB15: 14 | DC15: 2 | DD15: 8 | DE15: 5 | DF15: 2 | DG15: 4 | DH15: 3 | DI15: 6 | DJ15: 3 | DL15: 3 | DM15: 2 | DN15: 3 | DO15: 3 | DP15: 2 | DQ15: 2 | DR15: 7 | DS15: 8 | DT15: 5 | DU15: 1 | DV15: 2 | DW15: 2 | DX15: 7 | DY15: 6 | DZ15: 3 | IW15: =SUM(E15:HX15) -> 428 | IX15: 37.46 | IY15: =IW15*IX15 -> 16032.88 | IZ15: 49.95 | JA15: =IW15*IZ15 -> 21378.6
C16: BBY-AS-TBSH-WH | D16: AquaSonic - Ultrasonic Rechargeable Electric Toothbrush Ultimate Bundle - Optic White | BF16: 1 | BI16: 16 | BK16: 1 | BM16: 2 | BN16: 1 | BQ16: 5 | BS16: 1 | BW16: 3 | BX16: 1 | BY16: 1 | BZ16: 1 | CA16: 1 | CB16: 1 | CC16: 1 | CG16: 1 | CH16: 2 | CI16: 1 | CJ16: 2 | CL16: 8 | CM16: 2 | CN16: 3 | CO16: 6 | CP16: 7 | CQ16: 6 | CR16: 17 | CS16: 14 | CT16: 4 | CU16: 8 | CV16: 15 | CX16: 1 | DE16: 1 | DH16: 4 | DI16: 2 | DK16: 2 | DL16: 1 | DM16: 2 | DO16: 1 | DQ16: 1 | DR16: 1 | DT16: 2 | DU16: 3 | DV16: 2 | DW16: 1 | DX16: 1 | DY16: 3 | IW16: =SUM(E16:HX16) -> 160 | IX16: 37.46 | IY16: =IW16*IX16 -> 5993.6 | IZ16: 49.95 | JA16: =IW16*IZ16 -> 7992
C17: BBY-AS-PLSE-BK | D17: Aquasonic - Sonic Rechargeable Electric Toothbrush with Activated Charcoal Whitening Bristles - Midnight Black | BE17: 2 | BF17: 2 | BG17: 3 | BH17: 1 | BI17: 4 | BJ17: 48 | BK17: 3 | BS17: 6 | BT17: 2 | BU17: 4 | BV17: 14 | BW17: 203 | CB17: 169 | CD17: 1 | CE17: 5 | CF17: 2 | CG17: 3 | CH17: 5 | CI17: 4 | CJ17: 1 | CK17: 2 | CL17: 1 | CM17: 2 | CN17: 2 | CO17: 1 | CP17: 4 | CQ17: 4 | CR17: 11 | CS17: 8 | CT17: 4 | CU17: 2 | CV17: 4 | CW17: 7 | CX17: 1 | CY17: 3 | CZ17: 4 | DA17: 5 | DB17: 2 | DC17: 5 | DD17: 3 | DG17: 3 | DI17: 2 | DJ17: 2 | DK17: 1 | DL17: 2 | DO17: 3 | DP17: 2 | DQ17: 3 | DR17: 2 | DS17: 5 | DT17: 1 | DU17: 1 | DV17: 1 | DW17: 2 | DZ17: 2 | EB17: 87 | EC17: 1 | ED17: 2 | EF17: 109 | EG17: 1 | EJ17: 1 | EK17: 3 | EL17: 1 | EM17: 2 | EO17: 3 | EP17: 4 | EQ17: 6 | ER17: 18 | ES17: 4 | ET17: 3 | EV17: 1 | EW17: 1 | EX17: 4 | EY17: 6 | EZ17: 1 | FA17: 1 | IW17: =SUM(E17:HX17) -> 848 | IX17: 22.46 | IY17: =IW17*IX17 -> 19046.08 | IZ17: 29.95 | JA17: =IW17*IZ17 -> 25397.6
C18: BBY-AS-PLSE-WH | D18: Aquasonic - Sonic Rechargeable Electric Toothbrush with Activated Charcoal Whitening Bristles - Optic White | BF18: 1 | BG18: 1 | BH18: 1 | BJ18: 39 | BK18: 4 | BL18: 3 | BN18: 2 | BO18: 1 | BQ18: 1 | BR18: 1 | BS18: 1 | BT18: 4 | BU18: 2 | BV18: 8 | BW18: 64 | BX18: 2 | BY18: 2 | BZ18: 1 | CA18: 3 | CB18: 61 | CC18: 3 | CD18: 6 | CE18: 2 | CF18: 1 | CG18: 1 | CH18: 3 | CK18: 1 | CP18: 5 | CQ18: 1 | CR18: 4 | CS18: 2 | CU18: 1 | CV18: 3 | CW18: 2 | CX18: 1 | DC18: 2 | DD18: 2 | DG18: 1 | DH18: 1 | DI18: 1 | DM18: 1 | DO18: 7 | DT18: 1 | DU18: 1 | DX18: 1 | DY18: 1 | DZ18: 2 | EA18: 1 | EB18: 51 | EF18: 54 | EI18: 1 | EK18: 2 | EL18: 1 | EM18: 1 | EN18: 2 | EO18: 2 | EP18: 1 | EQ18: 2 | ER18: 4 | ES18: 2 | EW18: 2 | EX18: 2 | EZ18: 1 | FA18: 2 | IW18: =SUM(E18:HX18) -> 390 | IX18: 22.46 | IY18: =IW18*IX18 -> 8759.4 | IZ18: 29.95 | JA18: =IW18*IZ18 -> 11680.5
C19: BBY-AS-PLSE-RG | D19: Aquasonic - Sonic Rechargeable Electric Toothbrush with Activated Charcoal Whitening Bristles - Rose Gold | BE19: 3 | BH19: 6 | BI19: 2 | BJ19: 34 | BK19: 4 | BL19: 2 | BM19: 2 | BO19: 3 | BR19: 2 | BS19: 2 | BT19: 2 | BU19: 5 | BV19: 15 | BW19: 87 | BX19: 5 | BY19: 2 | BZ19: 4 | CA19: 1 | CB19: 84 | CC19: 1 | CD19: 4 | CE19: 6 | CF19: 3 | CG19: 2 | CH19: 6 | CI19: 2 | CJ19: 2 | CK19: 4 | CL19: 1 | CN19: 2 | CP19: 8 | CQ19: 4 | CR19: 9 | CS19: 4 | CT19: 2 | CU19: 4 | CV19: 1 | CW19: 7 | CY19: 2 | CZ19: 1 | DA19: 1 | DB19: 1 | DC19: 5 | DD19: 4 | DE19: 1 | DG19: 5 | DH19: 1 | DI19: 1 | DJ19: 3 | DK19: 1 | DM19: 3 | DN19: 1 | DO19: 2 | DP19: 2 | DS19: 1 | DT19: 2 | DU19: 3 | DV19: 1 | DX19: 1 | DY19: 3 | DZ19: 1 | EB19: 78 | EC19: 1 | ED19: 2 | EE19: 1 | EF19: 99 | EI19: 1 | EK19: 1 | EM19: 2 | EN19: 2 | EO19: 3 | EP19: 7 | EQ19: 7 | ER19: 7 | ES19: 2 | ET19: 4 | EU19: 2 | EV19: 5 | EW19: 1 | EX19: 7 | EY19: 3 | EZ19: 1 | FA19: 1 | IW19: =SUM(E19:HX19) -> 620 | IX19: 22.46 | IY19: =IW19*IX19 -> 13925.2 | IZ19: 29.95 | JA19: =IW19*IZ19 -> 18569
C20: AS-HEADC-PRO-WH | D20: AquaSonic - Activated Charcoal Vibe, Black Series, Pro Series, Duo Pro Replacement Brush Heads (2-Pack) - White | BJ20: 1 | BQ20: 1 | BU20: 1 | CB20: 1 | CC20: 1 | IW20: =SUM(E20:HX20) -> 5 | IX20: 11.2 | IY20: =IW20*IX20 -> 56 | IZ20: 14.95 | JA20: =IW20*IZ20 -> 74.75
C21: AS-HEAD-DUOP | D21: AQUASONIC DUO PRO 8-PACK BRUSH HEADS | BE21: 3 | BF21: 4 | BG21: 1 | BH21: 2 | BI21: 5 | BJ21: 3 | BK21: 2 | BL21: 3 | BM21: 1 | BN21: 4 | BO21: 2 | BP21: 3 | BQ21: 1 | BR21: 2 | BT21: 6 | BU21: 2 | BV21: 2 | BW21: 3 | BX21: 3 | BY21: 4 | BZ21: 4 | CA21: 3 | CB21: 7 | CC21: 2 | CD21: 2 | CE21: 3 | CF21: 3 | CH21: 2 | CJ21: 2 | CK21: 9 | CL21: 4 | CM21: 1 | CN21: 2 | CQ21: 6 | CR21: 2 | CS21: 6 | CT21: 7 | CU21: 6 | CV21: 6 | CW21: 8 | CX21: 9 | CY21: 2 | CZ21: 5 | DA21: 3 | DB21: 1 | DC21: 3 | DD21: 4 | DE21: 5 | DF21: 2 | DG21: 3 | DH21: 3 | DI21: 1 | DJ21: 1 | DK21: 4 | DL21: 5 | DM21: 8 | DN21: 5 | DO21: 11 | DP21: 1 | DQ21: 6 | DR21: 4 | DS21: 2 | DT21: 7 | DU21: 1 | DV21: 6 | DW21: 3 | DX21: 4 | DY21: 3 | DZ21: 2 | IW21: =SUM(E21:HX21) -> 255 | IX21: 18.71 | IY21: =IW21*IX21 -> 4771.05 | IZ21: 24.95 | JA21: =IW21*IZ21 -> 6362.25
C22: AS-HEADC-PLS-BK | D22: AquaSonic - Activated Charcoal Pulse Replacement Brush Heads (2-Pack) - Black | BE22: 1 | BG22: 1 | BH22: 1 | BI22: 2 | BJ22: 1 | BV22: 1 | BW22: 4 | CA22: 2 | CB22: 4 | CE22: 1 | CF22: 1 | CG22: 1 | CH22: 3 | CJ22: 2 | CL22: 1 | CN22: 3 | CP22: 3 | CR22: 6 | CS22: 5 | CT22: 3 | CW22: 1 | CX22: 1 | CZ22: 1 | DA22: 2 | DI22: 4 | DJ22: 1 | DO22: 1 | DW22: 2 | DX22: 4 | DZ22: 4 | EA22: 1 | EC22: 2 | EF22: 1 | EG22: 2 | EH22: 1 | EL22: 1 | EO22: 1 | EW22: 1 | EY22: 6 | EZ22: 1 | FA22: 2 | IW22: =SUM(E22:HX22) -> 86 | IX22: 7.46 | IY22: =IW22*IX22 -> 641.56 | IZ22: 9.95 | JA22: =IW22*IZ22 -> 855.7
C23: AS-HEADC-PLS-WH | D23: AquaSonic - Activated Charcoal Pulse Replacement Brush Heads (2-Pack) - White | BH23: 1 | BU23: 2 | BV23: 1 | BW23: 1 | BZ23: 2 | CB23: 1 | CC23: 1 | CE23: 1 | DB23: 2 | IW23: =SUM(E23:HX23) -> 12 | IX23: 7.46 | IY23: =IW23*IX23 -> 89.52 | IZ23: 9.95 | JA23: =IW23*IZ23 -> 119.4
C24: BBY-PDC-NANO-5PC | D24: NanoSteamer - Large 3-in-1 Nano Ionic Facial Steamer with Bonus 5 Piece Stainless Steel Skin Kit | BJ24: 2 | BK24: 1 | BL24: 214 | BM24: 4 | BN24: 6 | BO24: 6 | BP24: 3 | BQ24: 4 | BR24: 6 | BS24: 4 | BT24: 71 | BU24: 10 | BV24: 6 | BW24: 14 | BX24: 11 | BY24: 6 | BZ24: 6 | CA24: 7 | CB24: 4 | CC24: 8 | CD24: 6 | CE24: 8 | CF24: 5 | CG24: 8 | CH24: 6 | CI24: 7 | CJ24: 10 | CK24: 6 | CL24: 7 | CM24: 6 | CN24: 20 | CO24: 11 | CP24: 32 | CQ24: 54 | CR24: 131 | CS24: 221 | CT24: 18 | CU24: 15 | CV24: 14 | CW24: 14 | CX24: 5 | CY24: 9 | CZ24: 9 | DA24: 11 | DB24: 6 | DC24: 4 | DD24: 4 | DE24: 7 | DF24: 9 | DG24: 5 | DH24: 5 | DI24: 1 | DJ24: 1 | DM24: 5 | DN24: 5 | DP24: 1 | DQ24: 2 | DR24: 9 | DS24: 4 | DT24: 1 | DV24: 2 | DX24: 2 | DY24: 4 | DZ24: 2 | EA24: 1 | EB24: 6 | EC24: 3 | ED24: 4 | EE24: 2 | EG24: 1 | ER24: 10 | ES24: 6 | EU24: 2 | EV24: 5 | EW24: 6 | EY24: 4 | EZ24: 3 | FA24: 3 | IW24: =SUM(E24:HX24) -> 1161 | IX24: 39.96 | IY24: =IW24*IX24 -> 46393.56 | IZ24: 49.95 | JA24: =IW24*IZ24 -> 57991.95
C25: BBY-PDC-DERM-CLNC | D25: NuDerma Clinical Skin Therapy Wand - Portable Handheld High Frequency Skin Therapy Machine w 6 FUSION Neon + Argon Wands - Natural Acne Treatment - Skin Tightening - Wrinkle Reducing - Facial Skin | BK25: 10 | BL25: 15 | BM25: 3 | BN25: 1 | BO25: 4 | BP25: 8 | BQ25: 4 | BR25: 6 | BS25: 5 | BT25: 3 | BU25: 3 | BV25: 5 | BW25: 3 | BX25: 4 | BY25: 2 | BZ25: 3 | CA25: 3 | CB25: 5 | CD25: 5 | CE25: 2 | CF25: 1 | CG25: 2 | CH25: 4 | CI25: 3 | CJ25: 5 | CK25: 5 | CL25: 2 | CM25: 7 | CN25: 3 | CO25: 3 | CP25: 7 | CQ25: 2 | CR25: 14 | CS25: 25 | CT25: 14 | CU25: 8 | CV25: 8 | CW25: 3 | CX25: 3 | CY25: 5 | CZ25: 4 | DA25: 1 | DB25: 6 | DC25: 10 | DD25: 6 | DE25: 3 | DF25: 6 | DG25: 2 | DH25: 1 | DI25: 9 | DJ25: 3 | DK25: 3 | DL25: 4 | DM25: 2 | DN25: 4 | DO25: 2 | DP25: 1 | DS25: 2 | DT25: 5 | DU25: 1 | DV25: 1 | DX25: 1 | DY25: 5 | DZ25: 2 | EA25: 4 | EB25: 5 | EC25: 1 | ED25: 2 | EE25: 1 | EF25: 2 | EG25: 2 | EI25: 3 | EJ25: 4 | EK25: 1 | EL25: 3 | EM25: 3 | EN25: 3 | EP25: 3 | ER25: 1 | ES25: 14 | IW25: =SUM(E25:HX25) -> 354 | IX25: 95.96 | IY25: =IW25*IX25 -> 33969.84 | IZ25: 119.95 | JA25: =IW25*IZ25 -> 42462.3
C26: BBY-PDC-DERM-PRO | D26: NuDerma Professional Skin Therapy Wand - Portable Handheld High Frequency Skin Therapy Machine with 6 Neon & Argon Wands - Acne Treatment - Skin Tightening - Wrinkle Reducing – Facial Skin Lifter | BK26: 1 | BL26: 7 | BM26: 2 | BN26: 3 | BO26: 10 | BP26: 4 | BQ26: 8 | BR26: 4 | BS26: 5 | BT26: 3 | CH26: 2 | CI26: 1 | CJ26: 3 | CK26: 1 | CL26: 3 | CM26: 4 | CN26: 7 | CO26: 5 | CP26: 14 | CQ26: 26 | CR26: 23 | CS26: 30 | CT26: 10 | CU26: 7 | CV26: 6 | CW26: 7 | CX26: 5 | DY26: 1 | DZ26: 5 | EA26: 7 | EB26: 3 | EC26: 2 | EF26: 1 | EG26: 3 | EH26: 4 | EK26: 1 | EL26: 3 | EM26: 1 | EN26: 1 | IW26: =SUM(E26:HX26) -> 233 | IX26: 63.96 | IY26: =IW26*IX26 -> 14902.68 | IZ26: 79.95 | JA26: =IW26*IZ26 -> 18628.35
C27: BBY-PDC-HALO-SLV | D27: Halo Face Cleansing Brush with Red & Blue LED Light | BK27: 6 | BL27: 7 | BM27: 4 | BN27: 4 | BO27: 5 | BP27: 2 | BQ27: 5 | BR27: 3 | BS27: 1 | BT27: 3 | BU27: 6 | BV27: 2 | BW27: 10 | BX27: 7 | BY27: 3 | BZ27: 3 | CA27: 7 | CB27: 6 | CC27: 7 | CD27: 8 | CE27: 3 | CF27: 3 | CG27: 3 | CH27: 5 | CI27: 4 | CJ27: 3 | CK27: 2 | CL27: 9 | CM27: 2 | CN27: 5 | CO27: 10 | CP27: 11 | IW27: =SUM(E27:HX27) -> 159 | IX27: 31.96 | IY27: =IW27*IX27 -> 5081.64 | IZ27: 39.95 | JA27: =IW27*IZ27 -> 6352.05
C28: BBY-PDC-LUMA-MSK | D28: Luma LED Skin Therapy Mask - Home Skin Rejuvenation & Anti-Aging Light Therapy - 7 Color LED - Facial Skin Care - Skin Tightening - Wrinkles and Fine Lines - Boost Collagen - Inflammation Fighter | BK28: 2 | BL28: 5 | BM28: 8 | BN28: 5 | BO28: 5 | CI28: 3 | CJ28: 10 | CK28: 12 | CL28: 10 | CM28: 8 | CN28: 16 | CO28: 14 | CP28: 37 | CQ28: 45 | CR28: 70 | CS28: 68 | CV28: 3 | CW28: 9 | CX28: 5 | CY28: 1 | DM28: 12 | DN28: 2 | DO28: 3 | DP28: 5 | DQ28: 7 | DR28: 6 | DS28: 6 | DT28: 7 | DU28: 7 | DV28: 4 | DW28: 7 | DX28: 6 | DY28: 7 | DZ28: 10 | EA28: 5 | EB28: 11 | EC28: 4 | ED28: 12 | EE28: 8 | EF28: 12 | EG28: 8 | EP28: 5 | EQ28: 38 | ER28: 34 | ES28: 27 | ET28: 13 | EU28: 16 | EV28: 14 | EW28: 5 | EX28: 6 | EY28: 6 | EZ28: 3 | FA28: 6 | FB28: 3 | IW28: =SUM(E28:HX28) -> 661 | IX28: 71.96 | IY28: =IW28*IX28 -> 47565.56 | IZ28: 89.95 | JA28: =IW28*IZ28 -> 59456.95
C29: BBY-PDC-LUMA-WAND | D29: Luma Skin Therapy Wand - 4-in-1 Natural Facial Skincare Treatments | BK29: 3 | BL29: 3 | BN29: 3 | BO29: 2 | BP29: 3 | BQ29: 2 | BR29: 3 | BS29: 5 | BT29: 11 | BU29: 6 | BV29: 4 | BW29: 4 | BX29: 1 | BY29: 2 | BZ29: 4 | CA29: 3 | CB29: 5 | CC29: 4 | CD29: 3 | CF29: 9 | CG29: 5 | CH29: 3 | CI29: 9 | CJ29: 3 | DM29: 4 | DN29: 2 | DO29: 3 | DP29: 1 | DQ29: 1 | DR29: 2 | DS29: 6 | DT29: 3 | DU29: 3 | DV29: 3 | DW29: 2 | DX29: 3 | DY29: 4 | DZ29: 2 | EA29: 5 | EB29: 4 | EC29: 5 | ED29: 4 | EE29: 2 | EF29: 5 | EG29: 4 | ES29: 1 | ET29: 8 | EU29: 17 | EV29: 14 | EW29: 13 | EX29: 9 | EY29: 6 | EZ29: 5 | FA29: 9 | FB29: 1 | IW29: =SUM(E29:HX29) -> 251 | IX29: 63.99 | IY29: =IW29*IX29 -> 16061.49 | IZ29: 79.99 | JA29: =IW29*IZ29 -> 20077.49
C30: BBY-PDC-NDSW-WH | D30: NuDerma Skin Wand - Portable Handheld High Frequency Skin Therapy Machine | BK30: 8 | BL30: 9 | BM30: 1 | BN30: 2 | BO30: 6 | BQ30: 5 | BR30: 1 | BS30: 2 | BZ30: 3 | CA30: 1 | CD30: 1 | CE30: 2 | CF30: 1 | CG30: 2 | CH30: 1 | CI30: 3 | CJ30: 2 | CK30: 4 | CM30: 3 | CN30: 6 | CO30: 4 | CP30: 10 | CR30: 23 | CT30: 6 | CU30: 12 | CV30: 10 | CW30: 1 | CX30: 3 | CY30: 2 | CZ30: 5 | DA30: 4 | DB30: 8 | DC30: 7 | DD30: 5 | DE30: 6 | DF30: 3 | DG30: 3 | DH30: 3 | DI30: 1 | DJ30: 2 | DK30: 4 | DM30: 2 | DN30: 2 | DR30: 1 | DS30: 2 | DT30: 2 | DV30: 3 | DW30: 1 | DX30: 5 | DY30: 7 | DZ30: 10 | EA30: 9 | EB30: 2 | EC30: 1 | ED30: 2 | EE30: 1 | EF30: 3 | EG30: 1 | EI30: 1 | EJ30: 2 | EK30: 3 | EM30: 5 | EN30: 2 | EO30: 2 | IW30: =SUM(E30:HX30) -> 254 | IX30: 39.96 | IY30: =IW30*IX30 -> 10149.84 | IZ30: 49.95 | JA30: =IW30*IZ30 -> 12687.3
C31: BBY-PDC-RNEW-WH | D31: ReNew Skin Scrubber | BK31: 2 | BL31: 1 | BP31: 4 | BQ31: 1 | BS31: 2 | BT31: 48 | BU31: 4 | CB31: 5 | CC31: 1 | CD31: 2 | CE31: 3 | CI31: 2 | CJ31: 1 | CL31: 6 | CN31: 2 | CO31: 1 | CQ31: 17 | CR31: 1 | CS31: 37 | CT31: 1 | CU31: 1 | CW31: 2 | CY31: 3 | CZ31: 3 | DA31: 2 | DB31: 3 | DC31: 2 | DF31: 4 | IW31: =SUM(E31:HX31) -> 161 | IX31: 23.96 | IY31: =IW31*IX31 -> 3857.56 | IZ31: 29.95 | JA31: =IW31*IZ31 -> 4821.95
C32: BBY-PDC-RDIO-SNG | D32: DermaWave Clinical Radio Frequency Machine | BL32: 5 | BN32: 4 | BO32: 53 | BP32: 8 | BQ32: 1 | BR32: 2 | BS32: 2 | BV32: 4 | BW32: 3 | BX32: 3 | CA32: 1 | CB32: 3 | CC32: 4 | CD32: 2 | CF32: 1 | CG32: 2 | CK32: 7 | DM32: 2 | DN32: 2 | DP32: 2 | DQ32: 3 | DR32: 1 | DS32: 1 | DT32: 2 | DU32: 1 | DV32: 1 | DX32: 2 | DY32: 1 | EH32: 2 | EJ32: 2 | EL32: 1 | EM32: 4 | EN32: 2 | EO32: 3 | EP32: 8 | EQ32: 8 | ER32: 4 | ES32: 5 | ET32: 7 | EU32: 5 | EV32: 4 | EW32: 3 | EX32: 4 | EY32: 1 | EZ32: 3 | FA32: 1 | FB32: 2 | FC32: 3 | FD32: 5 | FE32: 2 | FF32: 2 | FG32: 1 | FI32: 1 | FJ32: 1 | FK32: 3 | FL32: 3 | FM32: 2 | FN32: 1 | FP32: 1 | FV32: 1 | FY32: 1 | FZ32: 1 | GA32: 10 | GB32: 1 | GC32: 1 | GD32: 1 | GE32: 1 | GG32: 2 | GM32: 1 | GO32: 2 | GP32: 1 | GQ32: 4 | GR32: 1 | GS32: 2 | GT32: 1 | GV32: 2 | GX32: 1 | GZ32: 1 | HA32: 1 | HB32: 1 | HC32: 2 | HM32: 1 | HN32: 1 | HQ32: 2 | IW32: =SUM(E32:HX32) -> 260 | IX32: 191.96 | IY32: =IW32*IX32 -> 49909.6 | IZ32: 239.95 | JA32: =IW32*IZ32 -> 62387
C33: BBY-PDC-NANO-CLNC | D33: NanoSteamer Clinical - 10-in-1 Smart Steam Dermatologist Grade Ionic Facial Steamer with 2 Multi-Position Steam Nozzles - Digital LCD Screen - Extraction Set - 6 Pre-Programmed Professional Modes | BN33: 1 | BO33: 3 | BS33: 5 | BT33: 1 | BU33: 2 | BV33: 1 | BX33: 1 | BY33: 1 | CB33: 1 | CD33: 1 | CE33: 1 | CF33: 1 | CG33: 1 | CI33: 2 | CJ33: 1 | CK33: 1 | CN33: 1 | CQ33: 1 | CR33: 2 | CS33: 3 | CT33: 4 | CV33: 1 | CZ33: 1 | DA33: 1 | DB33: 1 | DE33: 2 | DG33: 2 | DH33: 1 | DM33: 1 | DR33: 1 | DU33: 1 | DV33: 1 | DY33: 2 | ED33: 2 | EE33: 1 | EG33: 1 | EH33: 6 | EL33: 1 | EQ33: 3 | ER33: 3 | ES33: 6 | ET33: 1 | EU33: 1 | EX33: 1 | EZ33: 2 | FC33: 1 | FH33: 1 | FI33: 1 | FQ33: 1 | FT33: 1 | FW33: 4 | FY33: 1 | FZ33: 1 | GA33: 3 | GD33: 3 | GF33: 3 | GI33: 1 | GK33: 1 | GL33: 1 | GN33: 3 | GO33: 1 | GP33: 2 | GQ33: 8 | GR33: 7 | GS33: 7 | GW33: 1 | IW33: =SUM(E33:HX33) -> 130 | IX33: 71.96 | IY33: =IW33*IX33 -> 9354.8 | IZ33: 89.95 | JA33: =IW33*IZ33 -> 11693.5
C34: BBY-PDC-NANO-PRO | D34: NanoStemer PRO - Professional Ionic 4 in 1 Facial Steamer W/ 5 Staineless Steel Blemish Kit and a Headband | BN34: 1 | BO34: 2 | BP34: 1 | BS34: 2 | BV34: 2 | BW34: 2 | BX34: 2 | BY34: 1 | CA34: 1 | CB34: 1 | CC34: 1 | CD34: 1 | CF34: 2 | CG34: 1 | CK34: 1 | CL34: 2 | CM34: 1 | CN34: 1 | CO34: 2 | CP34: 3 | CQ34: 7 | CR34: 5 | CS34: 8 | CW34: 1 | CX34: 4 | CY34: 1 | CZ34: 1 | DB34: 3 | DE34: 1 | DF34: 1 | DG34: 3 | DJ34: 3 | DK34: 2 | DL34: 1 | DN34: 3 | DQ34: 1 | DR34: 2 | DS34: 1 | DT34: 2 | DU34: 4 | DV34: 1 | DW34: 1 | DX34: 2 | DY34: 1 | EA34: 1 | EB34: 1 | EC34: 1 | ED34: 2 | IW34: =SUM(E34:HX34) -> 94 | IX34: 55.99 | IY34: =IW34*IX34 -> 5263.06 | IZ34: 69.99 | JA34: =IW34*IZ34 -> 6579.06
C35: AS-ELITE-BK | D35: Aquasonic Elite Series Electric Toothbrush - Black | DY35: 1 | DZ35: 7 | EA35: 7 | EB35: 9 | EC35: 7 | ED35: 18 | EE35: 13 | EF35: 1 | EI35: Moved to core | EK35: 9 | IW35: =SUM(E35:HX35) -> 72 | IX35: 37.46 | IY35: =IW35*IX35 -> 2697.12 | IZ35: 49.95 | JA35: =IW35*IZ35 -> 3596.4
C36: AS-ELITE-RG | D36: Aquasonic Elite Series Electric Toothbrush - Rose Gold | DY36: 1 | DZ36: 2 | EA36: 6 | EB36: 3 | EC36: 6 | ED36: 39 | EE36: 3 | EF36: 3 | EG36: 4 | EH36: 6 | EI36: 43 | EJ36: 8 | EK36: 4 | EL36: 90 | EM36: 22 | EN36: 6 | EO36: 17 | EP36: 135 | EQ36: 22 | ER36: 34 | FL36: 2 | FM36: 9 | FN36: 16 | FO36: 63 | FP36: 24 | FQ36: 7 | FR36: 37 | FS36: 47 | FT36: 11 | FU36: 14 | FV36: 28 | FW36: 33 | FX36: 143 | FY36: 24 | FZ36: 11 | GA36: 24 | GB36: 24 | GC36: 28 | GD36: 75 | GE36: 17 | GF36: 28 | GG36: 30 | GH36: 24 | GI36: 6 | GJ36: 21 | GK36: 18 | GL36: 19 | GM36: 15 | GN36: 13 | GO36: 26 | GP36: 74 | GQ36: 141 | GR36: 73 | GS36: 66 | GT36: 10 | GU36: 5 | GV36: 16 | GW36: 22 | GX36: 27 | GY36: 19 | GZ36: 5 | HA36: 9 | HB36: 10 | HC36: 46 | HD36: 22 | HE36: 5 | HF36: 13 | HG36: 20 | HH36: 20 | HI36: 34 | HJ36: 17 | HK36: 14 | HL36: 2 | HM36: 9 | HN36: 1 | HO36: 13 | HP36: 41 | HQ36: 12 | HR36: 6 | HS36: 8 | HT36: 5 | HU36: 13 | IW36: =SUM(E36:HX36) -> 2069 | IX36: 37.46 | IY36: =IW36*IX36 -> 77504.74 | IZ36: 49.95 | JA36: =IW36*IZ36 -> 103346.55
C37: AS-ELITE-WH | D37: Aquasonic Elite Series Electric Toothbrush - White | DX37: 1 | DY37: 1 | DZ37: 3 | EA37: 3 | EB37: 1 | EC37: 12 | ED37: 25 | EE37: 6 | EI37: 40 | EJ37: 2 | EL37: 46 | EM37: 6 | EN37: 2 | EO37: 4 | EP37: 100 | EQ37: 42 | ER37: 60 | ES37: 9 | FD37: 1 | FE37: 18 | FF37: 7 | FG37: 50 | FH37: 10 | FI37: 13 | FJ37: 4 | FK37: 5 | FL37: 19 | FM37: 5 | FN37: 12 | FO37: 74 | FP37: 19 | FQ37: 4 | FR37: 14 | FS37: 18 | FT37: 5 | FU37: 7 | FV37: 12 | FW37: 17 | FX37: 62 | FY37: 11 | FZ37: 3 | GA37: 10 | GB37: 23 | GC37: 33 | GD37: 48 | GE37: 9 | GF37: 12 | GG37: 13 | GH37: 13 | GI37: 7 | GJ37: 14 | GK37: 7 | GL37: 10 | GM37: 10 | GN37: 8 | GO37: 13 | GP37: 31 | GQ37: 90 | GR37: 42 | GS37: 29 | GT37: 9 | GU37: 3 | GV37: 7 | GW37: 6 | GX37: 25 | GY37: 13 | GZ37: 9 | HB37: 6 | HC37: 23 | HD37: 13 | HE37: 7 | HF37: 4 | HG37: 9 | HH37: 12 | HI37: 6 | HJ37: 17 | HK37: 6 | HL37: 1 | HM37: 5 | HN37: 5 | HO37: 6 | HP37: 32 | HQ37: 5 | HR37: 1 | HS37: 9 | HT37: 9 | HU37: 5 | IW37: =SUM(E37:HX37) -> 1428 | IX37: 37.46 | IY37: =IW37*IX37 -> 53492.88 | IZ37: 49.95 | JA37: =IW37*IZ37 -> 71328.6
C38: AS-ICON-NV | D38: AquaSonic Icon Rechargeable Power Toothbrush | Magnetic Holder & Slim Travel Case - Navy | DW38: 3 | DX38: 1 | DY38: 1 | EA38: 1 | EB38: 2 | EC38: 9 | ED38: 3 | EE38: 140 | EF38: 10 | EG38: 6 | EH38: 6 | EI38: 7 | EJ38: 172 | EK38: 164 | EL38: 4 | EM38: 5 | EN38: 330 | EO38: 3 | EP38: 86 | EQ38: 30 | ER38: 28 | ES38: 14 | ET38: 277 | EU38: 4 | EV38: 6 | EW38: 10 | EX38: 30 | EY38: 412 | EZ38: 13 | FA38: 3 | FB38: 23 | FC38: 128 | FD38: 5 | FE38: 6 | FF38: 18 | FG38: 332 | FH38: 6 | FI38: 3 | FJ38: 7 | FK38: 349 | FL38: 5 | FM38: 7 | FN38: 5 | FO38: 7 | FP38: 218 | FQ38: 12 | FR38: 11 | FS38: Moved to core | IW38: =SUM(E38:HX38) -> 2922 | IX38: 14.99 | IY38: =IW38*IX38 -> 43800.78 | IZ38: 19.99 | JA38: =IW38*IZ38 -> 58410.78
C39: AS-ICON-WH | D39: AquaSonic Icon Rechargeable Power Toothbrush | Magnetic Holder & Slim Travel Case - Optic White | DX39: 1 | DZ39: 2 | EA39: 1 | EC39: 4 | ED39: 1 | EE39: 161 | EF39: 6 | EG39: 4 | EH39: 5 | EI39: 7 | EJ39: 45 | EK39: 60 | EL39: 1 | EM39: 3 | EN39: 139 | EO39: 1 | EP39: 38 | EQ39: 9 | ER39: 4 | ES39: 7 | ET39: 73 | EU39: 2 | EV39: 2 | EW39: 2 | EX39: 3 | EY39: 118 | EZ39: 17 | FA39: 4 | FB39: 7 | FC39: 84 | FD39: 2 | FE39: 2 | FF39: 9 | FG39: 131 | FH39: 3 | FI39: 2 | FJ39: 14 | FK39: 16 | FL39: 4 | FM39: 4 | FN39: 5 | FO39: 10 | FP39: 76 | FQ39: 7 | FR39: 3 | FS39: 9 | FT39: 4 | FU39: 1 | FV39: 13 | FW39: 9 | FX39: 5 | FY39: 10 | FZ39: 17 | GA39: 3 | GB39: 6 | GC39: 4 | GD39: 2 | GE39: 12 | GF39: 11 | GG39: 18 | GH39: 8 | GI39: 9 | GK39: 8 | GL39: 3 | GM39: 2 | GN39: 6 | GO39: 10 | GP39: 19 | GQ39: 45 | GR39: 30 | GS39: 32 | GT39: 10 | GU39: 1 | GV39: 17 | GW39: 12 | GX39: 48 | GY39: 7 | GZ39: 1 | HA39: 5 | HB39: 4 | HC39: 2 | HD39: 1 | HE39: 9 | HF39: 6 | HG39: 4 | HH39: 7 | HI39: 3 | HJ39: 7 | HK39: 2 | HL39: 6 | HM39: 4 | HN39: 7 | HO39: 6 | HP39: 4 | HQ39: 4 | HR39: 8 | HS39: 4 | HT39: 5 | HU39: 23 | IW39: =SUM(E39:HX39) -> 1612 | IX39: 14.99 | IY39: =IW39*IX39 -> 24163.88 | IZ39: 19.99 | JA39: =IW39*IZ39 -> 32223.88
C40: AS-HEAD-ICON-2NV | D40: AquaSonic Icon Navy Replacement Brush Heads - 2 Pack | EC40: 5 | EE40: 17 | EF40: 3 | EG40: 1 | EH40: 2 | EI40: 1 | EJ40: 21 | EK40: 30 | EL40: 4 | EM40: 2 | EN40: 30 | EP40: 14 | EQ40: 4 | ER40: 4 | ES40: 7 | ET40: 33 | EU40: 6 | EV40: 5 | EW40: 2 | EX40: 1 | EY40: 5 | FF40: 9 | FG40: 51 | FH40: 6 | FI40: 4 | FJ40: 3 | FK40: 55 | FL40: 5 | FM40: 2 | FN40: 4 | FO40: 8 | FP40: 32 | FQ40: 4 | FR40: 7 | FS40: 3 | FT40: 4 | FU40: 2 | FV40: 1 | FX40: 2 | FY40: 19 | FZ40: 10 | GA40: 6 | GB40: 8 | GC40: 1 | GD40: 4 | GE40: 6 | GF40: 9 | GG40: 13 | GH40: 8 | GI40: 3 | GJ40: 4 | GK40: 11 | GL40: 1 | GM40: 4 | GN40: 7 | GO40: 8 | GP40: 8 | GQ40: 14 | GR40: 11 | GS40: 4 | GT40: 4 | GU40: 1 | GV40: 16 | GW40: 18 | GX40: 25 | GY40: 5 | GZ40: 4 | HA40: 13 | HB40: 6 | HC40: 8 | HD40: 7 | HE40: 6 | HF40: 6 | HG40: 3 | HH40: 11 | HI40: 5 | HJ40: 4 | HK40: 6 | HL40: 6 | HM40: 5 | HN40: 6 | HO40: 3 | HP40: 6 | HQ40: 10 | HR40: 6 | HS40: 7 | HT40: 5 | HU40: 12 | IW40: =SUM(E40:HX40) -> 772 | IX40: 7.46 | IY40: =IW40*IX40 -> 5759.12 | IZ40: 9.95 | JA40: =IW40*IZ40 -> 7681.4
...

Sheet Sales (YEARLY)
D1: 2021 SDF | J1: 2022 SDF | P1: 2023 SDF | V1: 2024 SDF | AB1: 2025 SDF | AH1: SDF TOTALS
A2: MFG | B2: Title | D2: Units | E2: BBY Cost | F2: Sales at Cost | G2: MSRP | H2: Sales at MSRP | J2: Units | K2: BBY Cost | L2: Sales at Cost | M2: MSRP | N2: Sales at MSRP | P2: Units | Q2: BBY Cost | R2: Sales at Cost | S2: MSRP | T2: Sales at MSRP | V2: Units | W2: BBY Cost | X2: Sales at Cost | Y2: MSRP | Z2: Sales at MSRP | AB2: Units | AC2: BBY Cost | AD2: Sales at Cost | AE2: MSRP | AF2: Sales at MSRP | AH2: Units | AI2: BBY Cost | AJ2: Sales at Cost | AK2: MSRP | AL2: Sales at MSRP
A3: AS-TBSH-DUOP | B3: AQUASONIC DUO PRO ULTRA TOOTHBRUSHES | D3: =SUM('Sales TOTAL'!E2:AS2) -> 457 | E3: 59.96 | F3: =D3*E3 -> 27401.72 | G3: 79.95 | H3: =D3*G3 -> 36537.15 | J3: =SUM('Sales TOTAL'!AT2:CT2) -> 0 | K3: 59.96 | L3: =J3*K3 -> 0 | M3: 79.95 | N3: =J3*M3 -> 0 | P3: =SUM('Sales TOTAL'!CU2:ET2) -> 0 | Q3: 59.96 | R3: =P3*Q3 -> 0 | S3: 79.95 | T3: =P3*S3 -> 0 | V3: =SUM('Sales TOTAL'!EU2:GT2) -> 0 | W3: 59.96 | X3: =V3*W3 -> 0 | Y3: 79.95 | Z3: =V3*Y3 -> 0 | AB3: =SUM('Sales TOTAL'!GU2:HX2) -> 0 | AC3: 59.96 | AD3: =AB3*AC3 -> 0 | AE3: 79.95 | AF3: =AB3*AE3 -> 0 | AH3: =D3+J3+P3+V3+AB3 -> 457 | AI3: 59.96 | AJ3: =F3+L3+R3+X3+AD3 -> 27401.72 | AK3: 79.95 | AL3: =H3+N3+T3+Z3+AF3 -> 36537.15
A4: AS-FLOS-REG | B4: AQUA FLOSSER RCHRGBLE ORAL IRRIGATOR | D4: =SUM('Sales TOTAL'!E3:AS3) -> 205 | E4: 29.99 | F4: =D4*E4 -> 6147.95 | G4: 39.95 | H4: =D4*G4 -> 8189.75 | J4: =SUM('Sales TOTAL'!AT3:CT3) -> 238 | K4: 29.99 | L4: =J4*K4 -> 7137.62 | M4: 39.95 | N4: =J4*M4 -> 9508.1 | P4: =SUM('Sales TOTAL'!CU3:ET3) -> 52 | Q4: 29.99 | R4: =P4*Q4 -> 1559.48 | S4: 39.95 | T4: =P4*S4 -> 2077.4 | V4: =SUM('Sales TOTAL'!EU3:GT3) -> 0 | W4: 29.99 | X4: =V4*W4 -> 0 | Y4: 39.95 | Z4: =V4*Y4 -> 0 | AB4: =SUM('Sales TOTAL'!GU3:HX3) -> 0 | AC4: 29.99 | AD4: =AB4*AC4 -> 0 | AE4: 39.95 | AF4: =AB4*AE4 -> 0 | AH4: =D4+J4+P4+V4+AB4 -> 495 | AI4: 29.99 | AJ4: =F4+L4+R4+X4+AD4 -> 14845.05 | AK4: 39.95 | AL4: =H4+N4+T4+Z4+AF4 -> 19775.25
A5: AS-HDSC-SET | B5: COMPLETE FAMILY ORAL CARE | D5: =SUM('Sales TOTAL'!E4:AS4) -> 394 | E5: 37.46 | F5: =D5*E5 -> 14759.24 | G5: 49.95 | H5: =D5*G5 -> 19680.3 | J5: =SUM('Sales TOTAL'!AT4:CT4) -> 211 | K5: 37.46 | L5: =J5*K5 -> 7904.06 | M5: 49.95 | N5: =J5*M5 -> 10539.45 | P5: =SUM('Sales TOTAL'!CU4:ET4) -> 146 | Q5: 37.46 | R5: =P5*Q5 -> 5469.16 | S5: 49.95 | T5: =P5*S5 -> 7292.7 | V5: =SUM('Sales TOTAL'!EU4:GT4) -> 0 | W5: 37.46 | X5: =V5*W5 -> 0 | Y5: 49.95 | Z5: =V5*Y5 -> 0 | AB5: =SUM('Sales TOTAL'!GU4:HX4) -> 0 | AC5: 37.46 | AD5: =AB5*AC5 -> 0 | AE5: 49.95 | AF5: =AB5*AE5 -> 0 | AH5: =D5+J5+P5+V5+AB5 -> 751 | AI5: 37.46 | AJ5: =F5+L5+R5+X5+AD5 -> 28132.46 | AK5: 49.95 | AL5: =H5+N5+T5+Z5+AF5 -> 37512.45
A6: AS-FLOS-PRO | B6: AQUASONIC AQUA FLOSSER PRO | D6: =SUM('Sales TOTAL'!E5:AS5) -> 43 | E6: 37.49 | F6: =D6*E6 -> 1612.07 | G6: 49.95 | H6: =D6*G6 -> 2147.85 | J6: =SUM('Sales TOTAL'!AT5:CT5) -> 23 | K6: 37.49 | L6: =J6*K6 -> 862.27 | M6: 49.95 | N6: =J6*M6 -> 1148.85 | P6: =SUM('Sales TOTAL'!CU5:ET5) -> 0 | Q6: 37.49 | R6: =P6*Q6 -> 0 | S6: 49.95 | T6: =P6*S6 -> 0 | V6: =SUM('Sales TOTAL'!EU5:GT5) -> 0 | W6: 37.49 | X6: =V6*W6 -> 0 | Y6: 49.95 | Z6: =V6*Y6 -> 0 | AB6: =SUM('Sales TOTAL'!GU5:HX5) -> 0 | AC6: 37.49 | AD6: =AB6*AC6 -> 0 | AE6: 49.95 | AF6: =AB6*AE6 -> 0 | AH6: =D6+J6+P6+V6+AB6 -> 66 | AI6: 37.49 | AJ6: =F6+L6+R6+X6+AD6 -> 2474.34 | AK6: 49.95 | AL6: =H6+N6+T6+Z6+AF6 -> 3296.7
A7: AS-TBSH-BS | B7: AQUASONIC BLACK ULTRA SONIC TOOTHBRUSH | D7: =SUM('Sales TOTAL'!E6:AS6) -> 1111 | E7: 27.71 | F7: =D7*E7 -> 30785.81 | G7: 36.95 | H7: =D7*G7 -> 41051.45 | J7: =SUM('Sales TOTAL'!AT6:CT6) -> 0 | K7: 27.71 | L7: =J7*K7 -> 0 | M7: 36.95 | N7: =J7*M7 -> 0 | P7: =SUM('Sales TOTAL'!CU6:ET6) -> 0 | Q7: 27.71 | R7: =P7*Q7 -> 0 | S7: 36.95 | T7: =P7*S7 -> 0 | V7: =SUM('Sales TOTAL'!EU6:GT6) -> 0 | W7: 27.71 | X7: =V7*W7 -> 0 | Y7: 36.95 | Z7: =V7*Y7 -> 0 | AB7: =SUM('Sales TOTAL'!GU6:HX6) -> 0 | AC7: 27.71 | AD7: =AB7*AC7 -> 0 | AE7: 36.95 | AF7: =AB7*AE7 -> 0 | AH7: =D7+J7+P7+V7+AB7 -> 1111 | AI7: 27.71 | AJ7: =F7+L7+R7+X7+AD7 -> 30785.81 | AK7: 36.95 | AL7: =H7+N7+T7+Z7+AF7 -> 41051.45
A8: AS-TBSH-DUO | B8: AQUASONIC DUO ULTRA TOOTHBRUSHES | D8: =SUM('Sales TOTAL'!E7:AS7) -> 421 | E8: 37.46 | F8: =D8*E8 -> 15770.66 | G8: 49.95 | H8: =D8*G8 -> 21028.95 | J8: =SUM('Sales TOTAL'!AT7:CT7) -> 858 | K8: 37.46 | L8: =J8*K8 -> 32140.68 | M8: 49.95 | N8: =J8*M8 -> 42857.1 | P8: =SUM('Sales TOTAL'!CU7:ET7) -> 532 | Q8: 37.46 | R8: =P8*Q8 -> 19928.72 | S8: 49.95 | T8: =P8*S8 -> 26573.4 | V8: =SUM('Sales TOTAL'!EU7:GT7) -> 0 | W8: 37.46 | X8: =V8*W8 -> 0 | Y8: 49.95 | Z8: =V8*Y8 -> 0 | AB8: =SUM('Sales TOTAL'!GU7:HX7) -> 0 | AC8: 37.46 | AD8: =AB8*AC8 -> 0 | AE8: 49.95 | AF8: =AB8*AE8 -> 0 | AH8: =D8+J8+P8+V8+AB8 -> 1811 | AI8: 37.46 | AJ8: =F8+L8+R8+X8+AD8 -> 67840.06 | AK8: 49.95 | AL8: =H8+N8+T8+Z8+AF8 -> 90459.45
A9: AS-TBSH-CH | B9: AQUASONIC VIBE ULTRA TOOTHBRUSH CHARCL | D9: =SUM('Sales TOTAL'!E8:AS8) -> 456 | E9: 27.71 | F9: =D9*E9 -> 12635.76 | G9: 36.95 | H9: =D9*G9 -> 16849.2 | J9: =SUM('Sales TOTAL'!AT8:CT8) -> 15 | K9: 27.71 | L9: =J9*K9 -> 415.65 | M9: 36.95 | N9: =J9*M9 -> 554.25 | P9: =SUM('Sales TOTAL'!CU8:ET8) -> 0 | Q9: 27.71 | R9: =P9*Q9 -> 0 | S9: 36.95 | T9: =P9*S9 -> 0 | V9: =SUM('Sales TOTAL'!EU8:GT8) -> 0 | W9: 27.71 | X9: =V9*W9 -> 0 | Y9: 36.95 | Z9: =V9*Y9 -> 0 | AB9: =SUM('Sales TOTAL'!GU8:HX8) -> 0 | AC9: 27.71 | AD9: =AB9*AC9 -> 0 | AE9: 36.95 | AF9: =AB9*AE9 -> 0 | AH9: =D9+J9+P9+V9+AB9 -> 471 | AI9: 27.71 | AJ9: =F9+L9+R9+X9+AD9 -> 13051.41 | AK9: 36.95 | AL9: =H9+N9+T9+Z9+AF9 -> 17403.45
A10: AS-TBSH-RG | B10: AQUASONIC VIBE ULTRA TOOTHBRUSH-RSGLD | D10: =SUM('Sales TOTAL'!E9:AS9) -> 665 | E10: 27.71 | F10: =D10*E10 -> 18427.15 | G10: 36.95 | H10: =D10*G10 -> 24571.75 | J10: =SUM('Sales TOTAL'!AT9:CT9) -> 70 | K10: 27.71 | L10: =J10*K10 -> 1939.7 | M10: 36.95 | N10: =J10*M10 -> 2586.5 | P10: =SUM('Sales TOTAL'!CU9:ET9) -> 5 | Q10: 27.71 | R10: =P10*Q10 -> 138.55 | S10: 36.95 | T10: =P10*S10 -> 184.75 | V10: =SUM('Sales TOTAL'!EU9:GT9) -> 0 | W10: 27.71 | X10: =V10*W10 -> 0 | Y10: 36.95 | Z10: =V10*Y10 -> 0 | AB10: =SUM('Sales TOTAL'!GU9:HX9) -> 0 | AC10: 27.71 | AD10: =AB10*AC10 -> 0 | AE10: 36.95 | AF10: =AB10*AE10 -> 0 | AH10: =D10+J10+P10+V10+AB10 -> 740 | AI10: 27.71 | AJ10: =F10+L10+R10+X10+AD10 -> 20505.4 | AK10: 36.95 | AL10: =H10+N10+T10+Z10+AF10 -> 27343
